Workbook

Sheet 사용안내
A1: 위례 근태 관리 — Teams · OneDrive 공동 편집용
A3: 이 파일은 Teams 또는 OneDrive 공유 폴더에 두고 모든 구성원이 동시에 편집합니다. 각자 자기 행만 고치면 되고, 30% 판정·월 총량·OT 잔여는 전부 자동으로 계산됩니다.
A5: ■ 반드시 지켜주세요 — 동시 편집이 되려면
A6: · Excel Online(브라우저)으로 열거나, Excel 데스크톱에서 자동 저장(AutoSave)을 켜고 여세요.
A7: · 파일을 자기 PC로 복사해서 열면 별개 파일이 되어 다른 사람 입력이 반영되지 않습니다.
A9: ■ 근태 시트 — 자기 이름 행에서 날짜 칸을 고릅니다
A10: · 빈칸이 8시간 근무입니다. 8시간을 채우는 날은 아무것도 넣지 마세요.
A11: · 유형 11가지 · 출근 6가지 · 퇴근 18가지를 각각 고르면 됩니다. 연차·출장·교육·기타·휴직은 유형만 고르고 시각은 비워 둡니다.
A12: · 규칙에 없는 조합(예: 오전반 + 08:30 출근)은 빨갛게 표시됩니다 — 유형·출근·퇴근을 다시 고르세요.
A13: · 맨 아래 판정 행이 빨갛게 되면 그날 30%가 미달입니다. 노랗게 강조된 칸이 조율 후보 — 그 사람이 8시간으로 바꾸면 충족됩니다.
A14: · 노란 칸(B1·B2)에 연·월을 넣으면 날짜와 요일이 자동으로 바뀝니다.
A16: ■ OT 시트 — 날짜별 초과근로 시간
... A34: 근무 조합 106가지는 index.html 의 규칙 엔진에서 직접 뽑았습니다 (규칙 엔진에서 새로 생성). 규칙이 바뀌면 python worktime/build_xlsx.py 로 다시 만드세요.

Sheet 근태
A1: 연 | B1: 2026 | D1: 근태 — 빈칸이 8시간 근무입니다. 못 채우는 날만 채우세요
A2: 월 | B2: 9 | D2: 유형 · 출근 · 퇴근을 각각 고릅니다 (연차 · 출장 · 교육 · 휴직은 유형만) · 노란 칸에 연·월을 넣으면 날짜와 요일이 바뀝니다
A3: 주 | D3: =IF(D4="","",INT((D4-1+MOD(WEEKDAY(DATE($B$1,$B$2,1))+5,7))/7)+1) | G3: =IF(G4="","",INT((G4-1+MOD(WEEKDAY(DATE($B$1,$B$2,1))+5,7))/7)+1) | J3: =IF(J4="","",INT((J4-1+MOD(WEEKDAY(DATE($B$1,$B$2,1))+5,7))/7)+1) | M3: =IF(M4="","",INT((M4-1+MOD(WEEKDAY(DATE($B$1,$B$2,1))+5,7))/7)+1) | P3: =IF(P4="","",INT((P4-1+MOD(WEEKDAY(DATE($B$1,$B$2,1))+5,7))/7)+1) | S3: =IF(S4="","",INT((S4-1+MOD(WEEKDAY(DATE($B$1,$B$2,1))+5,7))/7)+1) | V3: =IF(V4="","",INT((V4-1+MOD(WEEKDAY(DATE($B$1,$B$2,1))+5,7))/7)+1) | Y3: =IF(Y4="","",INT((Y4-1+MOD(WEEKDAY(DATE($B$1,$B$2,1))+5,7))/7)+1) | AB3: =IF(AB4="","",INT((AB4-1+MOD(WEEKDAY(DATE($B$1,$B$2,1))+5,7))/7)+1) | AE3: =IF(AE4="","",INT((AE4-1+MOD(WEEKDAY(DATE($B$1,$B$2,1))+5,7))/7)+1) | AH3: =IF(AH4="","",INT((AH4-1+MOD(WEEKDAY(DATE($B$1,$B$2,1))+5,7))/7)+1) | AK3: =IF(AK4="","",INT((AK4-1+MOD(WEEKDAY(DATE($B$1,$B$2,1))+5,7))/7)+1) | AN3: =IF(AN4="","",INT((AN4-1+MOD(WEEKDAY(DATE($B$1,$B$2,1))+5,7))/7)+1) | AQ3: =IF(AQ4="","",INT((AQ4-1+MOD(WEEKDAY(DATE($B$1,$B$2,1))+5,7))/7)+1) | AT3: =IF(AT4="","",INT((AT4-1+MOD(WEEKDAY(DATE($B$1,$B$2,1))+5,7))/7)+1) | AW3: =IF(AW4="","",INT((AW4-1+MOD(WEEKDAY(DATE($B$1,$B$2,1))+5,7))/7)+1) | AZ3: =IF(AZ4="","",INT((AZ4-1+MOD(WEEKDAY(DATE($B$1,$B$2,1))+5,7))/7)+1) | BC3: =IF(BC4="","",INT((BC4-1+MOD(WEEKDAY(DATE($B$1,$B$2,1))+5,7))/7)+1) | BF3: =IF(BF4="","",INT((BF4-1+MOD(WEEKDAY(DATE($B$1,$B$2,1))+5,7))/7)+1) | BI3: =IF(BI4="","",INT((BI4-1+MOD(WEEKDAY(DATE($B$1,$B$2,1))+5,7))/7)+1) | BL3: =IF(BL4="","",INT((BL4-1+MOD(WEEKDAY(DATE($B$1,$B$2,1))+5,7))/7)+1) | BO3: =IF(BO4="","",INT((BO4-1+MOD(WEEKDAY(DATE($B$1,$B$2,1))+5,7))/7)+1) | BR3: =IF(BR4="","",INT((BR4-1+MOD(WEEKDAY(DATE($B$1,$B$2,1))+5,7))/7)+1) | BU3: =IF(BU4="","",INT((BU4-1+MOD(WEEKDAY(DATE($B$1,$B$2,1))+5,7))/7)+1) | BX3: =IF(BX4="","",INT((BX4-1+MOD(WEEKDAY(DATE($B$1,$B$2,1))+5,7))/7)+1) | CA3: =IF(CA4="","",INT((CA4-1+MOD(WEEKDAY(DATE($B$1,$B$2,1))+5,7))/7)+1) | CD3: =IF(CD4="","",INT((CD4-1+MOD(WEEKDAY(DATE($B$1,$B$2,1))+5,7))/7)+1) | CG3: =IF(CG4="","",INT((CG4-1+MOD(WEEKDAY(DATE($B$1,$B$2,1))+5,7))/7)+1) | CJ3: =IF(CJ4="","",INT((CJ4-1+MOD(WEEKDAY(DATE($B$1,$B$2,1))+5,7))/7)+1) | CM3: =IF(CM4="","",INT((CM4-1+MOD(WEEKDAY(DATE($B$1,$B$2,1))+5,7))/7)+1) | CP3: =IF(CP4="","",INT((CP4-1+MOD(WEEKDAY(DATE($B$1,$B$2,1))+5,7))/7)+1)
D4: =IF(MONTH(DATE($B$1,$B$2,1))<>$B$2,"",1) | G4: =IF(MONTH(DATE($B$1,$B$2,2))<>$B$2,"",2) | J4: =IF(MONTH(DATE($B$1,$B$2,3))<>$B$2,"",3) | M4: =IF(MONTH(DATE($B$1,$B$2,4))<>$B$2,"",4) | P4: =IF(MONTH(DATE($B$1,$B$2,5))<>$B$2,"",5) | S4: =IF(MONTH(DATE($B$1,$B$2,6))<>$B$2,"",6) | V4: =IF(MONTH(DATE($B$1,$B$2,7))<>$B$2,"",7) | Y4: =IF(MONTH(DATE($B$1,$B$2,8))<>$B$2,"",8) | AB4: =IF(MONTH(DATE($B$1,$B$2,9))<>$B$2,"",9) | AE4: =IF(MONTH(DATE($B$1,$B$2,10))<>$B$2,"",10) | AH4: =IF(MONTH(DATE($B$1,$B$2,11))<>$B$2,"",11) | AK4: =IF(MONTH(DATE($B$1,$B$2,12))<>$B$2,"",12) | AN4: =IF(MONTH(DATE($B$1,$B$2,13))<>$B$2,"",13) | AQ4: =IF(MONTH(DATE($B$1,$B$2,14))<>$B$2,"",14) | AT4: =IF(MONTH(DATE($B$1,$B$2,15))<>$B$2,"",15) | AW4: =IF(MONTH(DATE($B$1,$B$2,16))<>$B$2,"",16) | AZ4: =IF(MONTH(DATE($B$1,$B$2,17))<>$B$2,"",17) | BC4: =IF(MONTH(DATE($B$1,$B$2,18))<>$B$2,"",18) | BF4: =IF(MONTH(DATE($B$1,$B$2,19))<>$B$2,"",19) | BI4: =IF(MONTH(DATE($B$1,$B$2,20))<>$B$2,"",20) | BL4: =IF(MONTH(DATE($B$1,$B$2,21))<>$B$2,"",21) | BO4: =IF(MONTH(DATE($B$1,$B$2,22))<>$B$2,"",22) | BR4: =IF(MONTH(DATE($B$1,$B$2,23))<>$B$2,"",23) | BU4: =IF(MONTH(DATE($B$1,$B$2,24))<>$B$2,"",24) | BX4: =IF(MONTH(DATE($B$1,$B$2,25))<>$B$2,"",25) | CA4: =IF(MONTH(DATE($B$1,$B$2,26))<>$B$2,"",26) | CD4: =IF(MONTH(DATE($B$1,$B$2,27))<>$B$2,"",27) | CG4: =IF(MONTH(DATE($B$1,$B$2,28))<>$B$2,"",28) | CJ4: =IF(MONTH(DATE($B$1,$B$2,29))<>$B$2,"",29) | CM4: =IF(MONTH(DATE($B$1,$B$2,30))<>$B$2,"",30) | CP4: =IF(MONTH(DATE($B$1,$B$2,31))<>$B$2,"",31)
D5: =IF(D$4="","",INDEX(코드!$M$2:$M$8,WEEKDAY(DATE($B$1,$B$2,D$4)))) | G5: =IF(G$4="","",INDEX(코드!$M$2:$M$8,WEEKDAY(DATE($B$1,$B$2,G$4)))) | J5: =IF(J$4="","",INDEX(코드!$M$2:$M$8,WEEKDAY(DATE($B$1,$B$2,J$4)))) | M5: =IF(M$4="","",INDEX(코드!$M$2:$M$8,WEEKDAY(DATE($B$1,$B$2,M$4)))) | P5: =IF(P$4="","",INDEX(코드!$M$2:$M$8,WEEKDAY(DATE($B$1,$B$2,P$4)))) | S5: =IF(S$4="","",INDEX(코드!$M$2:$M$8,WEEKDAY(DATE($B$1,$B$2,S$4)))) | V5: =IF(V$4="","",INDEX(코드!$M$2:$M$8,WEEKDAY(DATE($B$1,$B$2,V$4)))) | Y5: =IF(Y$4="","",INDEX(코드!$M$2:$M$8,WEEKDAY(DATE($B$1,$B$2,Y$4)))) | AB5: =IF(AB$4="","",INDEX(코드!$M$2:$M$8,WEEKDAY(DATE($B$1,$B$2,AB$4)))) | AE5: =IF(AE$4="","",INDEX(코드!$M$2:$M$8,WEEKDAY(DATE($B$1,$B$2,AE$4)))) | AH5: =IF(AH$4="","",INDEX(코드!$M$2:$M$8,WEEKDAY(DATE($B$1,$B$2,AH$4)))) | AK5: =IF(AK$4="","",INDEX(코드!$M$2:$M$8,WEEKDAY(DATE($B$1,$B$2,AK$4)))) | AN5: =IF(AN$4="","",INDEX(코드!$M$2:$M$8,WEEKDAY(DATE($B$1,$B$2,AN$4)))) | AQ5: =IF(AQ$4="","",INDEX(코드!$M$2:$M$8,WEEKDAY(DATE($B$1,$B$2,AQ$4)))) | AT5: =IF(AT$4="","",INDEX(코드!$M$2:$M$8,WEEKDAY(DATE($B$1,$B$2,AT$4)))) | AW5: =IF(AW$4="","",INDEX(코드!$M$2:$M$8,WEEKDAY(DATE($B$1,$B$2,AW$4)))) | AZ5: =IF(AZ$4="","",INDEX(코드!$M$2:$M$8,WEEKDAY(DATE($B$1,$B$2,AZ$4)))) | BC5: =IF(BC$4="","",INDEX(코드!$M$2:$M$8,WEEKDAY(DATE($B$1,$B$2,BC$4)))) | BF5: =IF(BF$4="","",INDEX(코드!$M$2:$M$8,WEEKDAY(DATE($B$1,$B$2,BF$4)))) | BI5: =IF(BI$4="","",INDEX(코드!$M$2:$M$8,WEEKDAY(DATE($B$1,$B$2,BI$4)))) | BL5: =IF(BL$4="","",INDEX(코드!$M$2:$M$8,WEEKDAY(DATE($B$1,$B$2,BL$4)))) | BO5: =IF(BO$4="","",INDEX(코드!$M$2:$M$8,WEEKDAY(DATE($B$1,$B$2,BO$4)))) | BR5: =IF(BR$4="","",INDEX(코드!$M$2:$M$8,WEEKDAY(DATE($B$1,$B$2,BR$4)))) | BU5: =IF(BU$4="","",INDEX(코드!$M$2:$M$8,WEEKDAY(DATE($B$1,$B$2,BU$4)))) | BX5: =IF(BX$4="","",INDEX(코드!$M$2:$M$8,WEEKDAY(DATE($B$1,$B$2,BX$4)))) | CA5: =IF(CA$4="","",INDEX(코드!$M$2:$M$8,WEEKDAY(DATE($B$1,$B$2,CA$4)))) | CD5: =IF(CD$4="","",INDEX(코드!$M$2:$M$8,WEEKDAY(DATE($B$1,$B$2,CD$4)))) | CG5: =IF(CG$4="","",INDEX(코드!$M$2:$M$8,WEEKDAY(DATE($B$1,$B$2,CG$4)))) | CJ5: =IF(CJ$4="","",INDEX(코드!$M$2:$M$8,WEEKDAY(DATE($B$1,$B$2,CJ$4)))) | CM5: =IF(CM$4="","",INDEX(코드!$M$2:$M$8,WEEKDAY(DATE($B$1,$B$2,CM$4)))) | CP5: =IF(CP$4="","",INDEX(코드!$M$2:$M$8,WEEKDAY(DATE($B$1,$B$2,CP$4))))
D6: =IF(D$4="","",IF(OR(WEEKDAY(DATE($B$1,$B$2,D$4),2)>5,COUNTIF(공휴일!$A$2:$A$400,DATE($B$1,$B$2,D$4))>0),"휴일","")) | G6: =IF(G$4="","",IF(OR(WEEKDAY(DATE($B$1,$B$2,G$4),2)>5,COUNTIF(공휴일!$A$2:$A$400,DATE($B$1,$B$2,G$4))>0),"휴일","")) | J6: =IF(J$4="","",IF(OR(WEEKDAY(DATE($B$1,$B$2,J$4),2)>5,COUNTIF(공휴일!$A$2:$A$400,DATE($B$1,$B$2,J$4))>0),"휴일","")) | M6: =IF(M$4="","",IF(OR(WEEKDAY(DATE($B$1,$B$2,M$4),2)>5,COUNTIF(공휴일!$A$2:$A$400,DATE($B$1,$B$2,M$4))>0),"휴일","")) | P6: =IF(P$4="","",IF(OR(WEEKDAY(DATE($B$1,$B$2,P$4),2)>5,COUNTIF(공휴일!$A$2:$A$400,DATE($B$1,$B$2,P$4))>0),"휴일","")) | S6: =IF(S$4="","",IF(OR(WEEKDAY(DATE($B$1,$B$2,S$4),2)>5,COUNTIF(공휴일!$A$2:$A$400,DATE($B$1,$B$2,S$4))>0),"휴일","")) | V6: =IF(V$4="","",IF(OR(WEEKDAY(DATE($B$1,$B$2,V$4),2)>5,COUNTIF(공휴일!$A$2:$A$400,DATE($B$1,$B$2,V$4))>0),"휴일","")) | Y6: =IF(Y$4="","",IF(OR(WEEKDAY(DATE($B$1,$B$2,Y$4),2)>5,COUNTIF(공휴일!$A$2:$A$400,DATE($B$1,$B$2,Y$4))>0),"휴일","")) | AB6: =IF(AB$4="","",IF(OR(WEEKDAY(DATE($B$1,$B$2,AB$4),2)>5,COUNTIF(공휴일!$A$2:$A$400,DATE($B$1,$B$2,AB$4))>0),"휴일","")) | AE6: =IF(AE$4="","",IF(OR(WEEKDAY(DATE($B$1,$B$2,AE$4),2)>5,COUNTIF(공휴일!$A$2:$A$400,DATE($B$1,$B$2,AE$4))>0),"휴일","")) | AH6: =IF(AH$4="","",IF(OR(WEEKDAY(DATE($B$1,$B$2,AH$4),2)>5,COUNTIF(공휴일!$A$2:$A$400,DATE($B$1,$B$2,AH$4))>0),"휴일","")) | AK6: =IF(AK$4="","",IF(OR(WEEKDAY(DATE($B$1,$B$2,AK$4),2)>5,COUNTIF(공휴일!$A$2:$A$400,DATE($B$1,$B$2,AK$4))>0),"휴일","")) | AN6: =IF(AN$4="","",IF(OR(WEEKDAY(DATE($B$1,$B$2,AN$4),2)>5,COUNTIF(공휴일!$A$2:$A$400,DATE($B$1,$B$2,AN$4))>0),"휴일","")) | AQ6: =IF(AQ$4="","",IF(OR(WEEKDAY(DATE($B$1,$B$2,AQ$4),2)>5,COUNTIF(공휴일!$A$2:$A$400,DATE($B$1,$B$2,AQ$4))>0),"휴일","")) | AT6: =IF(AT$4="","",IF(OR(WEEKDAY(DATE($B$1,$B$2,AT$4),2)>5,COUNTIF(공휴일!$A$2:$A$400,DATE($B$1,$B$2,AT$4))>0),"휴일","")) | AW6: =IF(AW$4="","",IF(OR(WEEKDAY(DATE($B$1,$B$2,AW$4),2)>5,COUNTIF(공휴일!$A$2:$A$400,DATE($B$1,$B$2,AW$4))>0),"휴일","")) | AZ6: =IF(AZ$4="","",IF(OR(WEEKDAY(DATE($B$1,$B$2,AZ$4),2)>5,COUNTIF(공휴일!$A$2:$A$400,DATE($B$1,$B$2,AZ$4))>0),"휴일","")) | BC6: =IF(BC$4="","",IF(OR(WEEKDAY(DATE($B$1,$B$2,BC$4),2)>5,COUNTIF(공휴일!$A$2:$A$400,DATE($B$1,$B$2,BC$4))>0),"휴일","")) | BF6: =IF(BF$4="","",IF(OR(WEEKDAY(DATE($B$1,$B$2,BF$4),2)>5,COUNTIF(공휴일!$A$2:$A$400,DATE($B$1,$B$2,BF$4))>0),"휴일","")) | BI6: =IF(BI$4="","",IF(OR(WEEKDAY(DATE($B$1,$B$2,BI$4),2)>5,COUNTIF(공휴일!$A$2:$A$400,DATE($B$1,$B$2,BI$4))>0),"휴일","")) | BL6: =IF(BL$4="","",IF(OR(WEEKDAY(DATE($B$1,$B$2,BL$4),2)>5,COUNTIF(공휴일!$A$2:$A$400,DATE($B$1,$B$2,BL$4))>0),"휴일","")) | BO6: =IF(BO$4="","",IF(OR(WEEKDAY(DATE($B$1,$B$2,BO$4),2)>5,COUNTIF(공휴일!$A$2:$A$400,DATE($B$1,$B$2,BO$4))>0),"휴일","")) | BR6: =IF(BR$4="","",IF(OR(WEEKDAY(DATE($B$1,$B$2,BR$4),2)>5,COUNTIF(공휴일!$A$2:$A$400,DATE($B$1,$B$2,BR$4))>0),"휴일","")) | BU6: =IF(BU$4="","",IF(OR(WEEKDAY(DATE($B$1,$B$2,BU$4),2)>5,COUNTIF(공휴일!$A$2:$A$400,DATE($B$1,$B$2,BU$4))>0),"휴일","")) | BX6: =IF(BX$4="","",IF(OR(WEEKDAY(DATE($B$1,$B$2,BX$4),2)>5,COUNTIF(공휴일!$A$2:$A$400,DATE($B$1,$B$2,BX$4))>0),"휴일","")) | CA6: =IF(CA$4="","",IF(OR(WEEKDAY(DATE($B$1,$B$2,CA$4),2)>5,COUNTIF(공휴일!$A$2:$A$400,DATE($B$1,$B$2,CA$4))>0),"휴일","")) | CD6: =IF(CD$4="","",IF(OR(WEEKDAY(DATE($B$1,$B$2,CD$4),2)>5,COUNTIF(공휴일!$A$2:$A$400,DATE($B$1,$B$2,CD$4))>0),"휴일","")) | CG6: =IF(CG$4="","",IF(OR(WEEKDAY(DATE($B$1,$B$2,CG$4),2)>5,COUNTIF(공휴일!$A$2:$A$400,DATE($B$1,$B$2,CG$4))>0),"휴일","")) | CJ6: =IF(CJ$4="","",IF(OR(WEEKDAY(DATE($B$1,$B$2,CJ$4),2)>5,COUNTIF(공휴일!$A$2:$A$400,DATE($B$1,$B$2,CJ$4))>0),"휴일","")) | CM6: =IF(CM$4="","",IF(OR(WEEKDAY(DATE($B$1,$B$2,CM$4),2)>5,COUNTIF(공휴일!$A$2:$A$400,DATE($B$1,$B$2,CM$4))>0),"휴일","")) | CP6: =IF(CP$4="","",IF(OR(WEEKDAY(DATE($B$1,$B$2,CP$4),2)>5,COUNTIF(공휴일!$A$2:$A$400,DATE($B$1,$B$2,CP$4))>0),"휴일",""))
A7: 이름 | B7: 파트 | C7: 그룹 | D7: 유형 | E7: 출근 | F7: 퇴근 | G7: 유형 | H7: 출근 | I7: 퇴근 | J7: 유형 | K7: 출근 | L7: 퇴근 | M7: 유형 | N7: 출근 | O7: 퇴근 | P7: 유형 | Q7: 출근 | R7: 퇴근 | S7: 유형 | T7: 출근 | U7: 퇴근 | V7: 유형 | W7: 출근 | X7: 퇴근 | Y7: 유형 | Z7: 출근 | AA7: 퇴근 | AB7: 유형 | AC7: 출근 | AD7: 퇴근 | AE7: 유형 | AF7: 출근 | AG7: 퇴근 | AH7: 유형 | AI7: 출근 | AJ7: 퇴근 | AK7: 유형 | AL7: 출근 | AM7: 퇴근 | AN7: 유형 | AO7: 출근 | AP7: 퇴근 | AQ7: 유형 | AR7: 출근 | AS7: 퇴근 | AT7: 유형 | AU7: 출근 | AV7: 퇴근 | AW7: 유형 | AX7: 출근 | AY7: 퇴근 | AZ7: 유형 | BA7: 출근 | BB7: 퇴근 | BC7: 유형 | BD7: 출근 | BE7: 퇴근 | BF7: 유형 | BG7: 출근 | BH7: 퇴근 | BI7: 유형 | BJ7: 출근 | BK7: 퇴근 | BL7: 유형 | BM7: 출근 | BN7: 퇴근 | BO7: 유형 | BP7: 출근 | BQ7: 퇴근 | BR7: 유형 | BS7: 출근 | BT7: 퇴근 | BU7: 유형 | BV7: 출근 | BW7: 퇴근 | BX7: 유형 | BY7: 출근 | BZ7: 퇴근 | CA7: 유형 | CB7: 출근 | CC7: 퇴근 | CD7: 유형 | CE7: 출근 | CF7: 퇴근 | CG7: 유형 | CH7: 출근 | CI7: 퇴근 | CJ7: 유형 | CK7: 출근 | CL7: 퇴근 | CM7: 유형 | CN7: 출근 | CO7: 퇴근 | CP7: 유형 | CQ7: 출근 | CR7: 퇴근
A8: =IF(명부!A2="","",명부!A2) | B8: =IF(명부!C2="","",명부!C2) | C8: =IF(명부!E2="","",명부!E2)
A9: =IF(명부!A3="","",명부!A3) | B9: =IF(명부!C3="","",명부!C3) | C9: =IF(명부!E3="","",명부!E3)
A10: =IF(명부!A4="","",명부!A4) | B10: =IF(명부!C4="","",명부!C4) | C10: =IF(명부!E4="","",명부!E4)
A11: =IF(명부!A5="","",명부!A5) | B11: =IF(명부!C5="","",명부!C5) | C11: =IF(명부!E5="","",명부!E5)
A12: =IF(명부!A6="","",명부!A6) | B12: =IF(명부!C6="","",명부!C6) | C12: =IF(명부!E6="","",명부!E6)
A13: =IF(명부!A7="","",명부!A7) | B13: =IF(명부!C7="","",명부!C7) | C13: =IF(명부!E7="","",명부!E7)
A14: =IF(명부!A8="","",명부!A8) | B14: =IF(명부!C8="","",명부!C8) | C14: =IF(명부!E8="","",명부!E8)
A15: =IF(명부!A9="","",명부!A9) | B15: =IF(명부!C9="","",명부!C9) | C15: =IF(명부!E9="","",명부!E9)
A16: =IF(명부!A10="","",명부!A10) | B16: =IF(명부!C10="","",명부!C10) | C16: =IF(명부!E10="","",명부!E10)
A17: =IF(명부!A11="","",명부!A11) | B17: =IF(명부!C11="","",명부!C11) | C17: =IF(명부!E11="","",명부!E11)
A18: =IF(명부!A12="","",명부!A12) | B18: =IF(명부!C12="","",명부!C12) | C18: =IF(명부!E12="","",명부!E12)
A19: =IF(명부!A13="","",명부!A13) | B19: =IF(명부!C13="","",명부!C13) | C19: =IF(명부!E13="","",명부!E13)
... A31: =IF(명부!A25="","",명부!A25) | B31: =IF(명부!C25="","",명부!C25) | C31: =IF(명부!E25="","",명부!E25)
A33: 8시간 인원 | D33: =IF(D$6="휴일","",SUMPRODUCT((명부!$F$2:$F$25<>"Y")*(시간!$D$92:$D$115))) | G33: =IF(G$6="휴일","",SUMPRODUCT((명부!$F$2:$F$25<>"Y")*(시간!$E$92:$E$115))) | J33: =IF(J$6="휴일","",SUMPRODUCT((명부!$F$2:$F$25<>"Y")*(시간!$F$92:$F$115))) | M33: =IF(M$6="휴일","",SUMPRODUCT((명부!$F$2:$F$25<>"Y")*(시간!$G$92:$G$115))) | P33: =IF(P$6="휴일","",SUMPRODUCT((명부!$F$2:$F$25<>"Y")*(시간!$H$92:$H$115))) | S33: =IF(S$6="휴일","",SUMPRODUCT((명부!$F$2:$F$25<>"Y")*(시간!$I$92:$I$115))) | V33: =IF(V$6="휴일","",SUMPRODUCT((명부!$F$2:$F$25<>"Y")*(시간!$J$92:$J$115))) | Y33: =IF(Y$6="휴일","",SUMPRODUCT((명부!$F$2:$F$25<>"Y")*(시간!$K$92:$K$115))) | AB33: =IF(AB$6="휴일","",SUMPRODUCT((명부!$F$2:$F$25<>"Y")*(시간!$L$92:$L$115))) | AE33: =IF(AE$6="휴일","",SUMPRODUCT((명부!$F$2:$F$25<>"Y")*(시간!$M$92:$M$115))) | AH33: =IF(AH$6="휴일","",SUMPRODUCT((명부!$F$2:$F$25<>"Y")*(시간!$N$92:$N$115))) | AK33: =IF(AK$6="휴일","",SUMPRODUCT((명부!$F$2:$F$25<>"Y")*(시간!$O$92:$O$115))) | AN33: =IF(AN$6="휴일","",SUMPRODUCT((명부!$F$2:$F$25<>"Y")*(시간!$P$92:$P$115))) | AQ33: =IF(AQ$6="휴일","",SUMPRODUCT((명부!$F$2:$F$25<>"Y")*(시간!$Q$92:$Q$115))) | AT33: =IF(AT$6="휴일","",SUMPRODUCT((명부!$F$2:$F$25<>"Y")*(시간!$R$92:$R$115))) | AW33: =IF(AW$6="휴일","",SUMPRODUCT((명부!$F$2:$F$25<>"Y")*(시간!$S$92:$S$115))) | AZ33: =IF(AZ$6="휴일","",SUMPRODUCT((명부!$F$2:$F$25<>"Y")*(시간!$T$92:$T$115))) | BC33: =IF(BC$6="휴일","",SUMPRODUCT((명부!$F$2:$F$25<>"Y")*(시간!$U$92:$U$115))) | BF33: =IF(BF$6="휴일","",SUMPRODUCT((명부!$F$2:$F$25<>"Y")*(시간!$V$92:$V$115))) | BI33: =IF(BI$6="휴일","",SUMPRODUCT((명부!$F$2:$F$25<>"Y")*(시간!$W$92:$W$115))) | BL33: =IF(BL$6="휴일","",SUMPRODUCT((명부!$F$2:$F$25<>"Y")*(시간!$X$92:$X$115))) | BO33: =IF(BO$6="휴일","",SUMPRODUCT((명부!$F$2:$F$25<>"Y")*(시간!$Y$92:$Y$115))) | BR33: =IF(BR$6="휴일","",SUMPRODUCT((명부!$F$2:$F$25<>"Y")*(시간!$Z$92:$Z$115))) | BU33: =IF(BU$6="휴일","",SUMPRODUCT((명부!$F$2:$F$25<>"Y")*(시간!$AA$92:$AA$115))) | BX33: =IF(BX$6="휴일","",SUMPRODUCT((명부!$F$2:$F$25<>"Y")*(시간!$AB$92:$AB$115))) | CA33: =IF(CA$6="휴일","",SUMPRODUCT((명부!$F$2:$F$25<>"Y")*(시간!$AC$92:$AC$115))) | CD33: =IF(CD$6="휴일","",SUMPRODUCT((명부!$F$2:$F$25<>"Y")*(시간!$AD$92:$AD$115))) | CG33: =IF(CG$6="휴일","",SUMPRODUCT((명부!$F$2:$F$25<>"Y")*(시간!$AE$92:$AE$115))) | CJ33: =IF(CJ$6="휴일","",SUMPRODUCT((명부!$F$2:$F$25<>"Y")*(시간!$AF$92:$AF$115))) | CM33: =IF(CM$6="휴일","",SUMPRODUCT((명부!$F$2:$F$25<>"Y")*(시간!$AG$92:$AG$115))) | CP33: =IF(CP$6="휴일","",SUMPRODUCT((명부!$F$2:$F$25<>"Y")*(시간!$AH$92:$AH$115)))
A34: 필요 인원 (30%) | D34: =IF(D$6="휴일","",ROUNDUP(명부!$B$27*0.3,0)) | G34: =IF(G$6="휴일","",ROUNDUP(명부!$B$27*0.3,0)) | J34: =IF(J$6="휴일","",ROUNDUP(명부!$B$27*0.3,0)) | M34: =IF(M$6="휴일","",ROUNDUP(명부!$B$27*0.3,0)) | P34: =IF(P$6="휴일","",ROUNDUP(명부!$B$27*0.3,0)) | S34: =IF(S$6="휴일","",ROUNDUP(명부!$B$27*0.3,0)) | V34: =IF(V$6="휴일","",ROUNDUP(명부!$B$27*0.3,0)) | Y34: =IF(Y$6="휴일","",ROUNDUP(명부!$B$27*0.3,0)) | AB34: =IF(AB$6="휴일","",ROUNDUP(명부!$B$27*0.3,0)) | AE34: =IF(AE$6="휴일","",ROUNDUP(명부!$B$27*0.3,0)) | AH34: =IF(AH$6="휴일","",ROUNDUP(명부!$B$27*0.3,0)) | AK34: =IF(AK$6="휴일","",ROUNDUP(명부!$B$27*0.3,0)) | AN34: =IF(AN$6="휴일","",ROUNDUP(명부!$B$27*0.3,0)) | AQ34: =IF(AQ$6="휴일","",ROUNDUP(명부!$B$27*0.3,0)) | AT34: =IF(AT$6="휴일","",ROUNDUP(명부!$B$27*0.3,0)) | AW34: =IF(AW$6="휴일","",ROUNDUP(명부!$B$27*0.3,0)) | AZ34: =IF(AZ$6="휴일","",ROUNDUP(명부!$B$27*0.3,0)) | BC34: =IF(BC$6="휴일","",ROUNDUP(명부!$B$27*0.3,0)) | BF34: =IF(BF$6="휴일","",ROUNDUP(명부!$B$27*0.3,0)) | BI34: =IF(BI$6="휴일","",ROUNDUP(명부!$B$27*0.3,0)) | BL34: =IF(BL$6="휴일","",ROUNDUP(명부!$B$27*0.3,0)) | BO34: =IF(BO$6="휴일","",ROUNDUP(명부!$B$27*0.3,0)) | BR34: =IF(BR$6="휴일","",ROUNDUP(명부!$B$27*0.3,0)) | BU34: =IF(BU$6="휴일","",ROUNDUP(명부!$B$27*0.3,0)) | BX34: =IF(BX$6="휴일","",ROUNDUP(명부!$B$27*0.3,0)) | CA34: =IF(CA$6="휴일","",ROUNDUP(명부!$B$27*0.3,0)) | CD34: =IF(CD$6="휴일","",ROUNDUP(명부!$B$27*0.3,0)) | CG34: =IF(CG$6="휴일","",ROUNDUP(명부!$B$27*0.3,0)) | CJ34: =IF(CJ$6="휴일","",ROUNDUP(명부!$B$27*0.3,0)) | CM34: =IF(CM$6="휴일","",ROUNDUP(명부!$B$27*0.3,0)) | CP34: =IF(CP$6="휴일","",ROUNDUP(명부!$B$27*0.3,0))
A35: 판정 | D35: =IF(D$6="휴일","",IF(D33>=D34,"충족","미달")) | G35: =IF(G$6="휴일","",IF(G33>=G34,"충족","미달")) | J35: =IF(J$6="휴일","",IF(J33>=J34,"충족","미달")) | M35: =IF(M$6="휴일","",IF(M33>=M34,"충족","미달")) | P35: =IF(P$6="휴일","",IF(P33>=P34,"충족","미달")) | S35: =IF(S$6="휴일","",IF(S33>=S34,"충족","미달")) | V35: =IF(V$6="휴일","",IF(V33>=V34,"충족","미달")) | Y35: =IF(Y$6="휴일","",IF(Y33>=Y34,"충족","미달")) | AB35: =IF(AB$6="휴일","",IF(AB33>=AB34,"충족","미달")) | AE35: =IF(AE$6="휴일","",IF(AE33>=AE34,"충족","미달")) | AH35: =IF(AH$6="휴일","",IF(AH33>=AH34,"충족","미달")) | AK35: =IF(AK$6="휴일","",IF(AK33>=AK34,"충족","미달")) | AN35: =IF(AN$6="휴일","",IF(AN33>=AN34,"충족","미달")) | AQ35: =IF(AQ$6="휴일","",IF(AQ33>=AQ34,"충족","미달")) | AT35: =IF(AT$6="휴일","",IF(AT33>=AT34,"충족","미달")) | AW35: =IF(AW$6="휴일","",IF(AW33>=AW34,"충족","미달")) | AZ35: =IF(AZ$6="휴일","",IF(AZ33>=AZ34,"충족","미달")) | BC35: =IF(BC$6="휴일","",IF(BC33>=BC34,"충족","미달")) | BF35: =IF(BF$6="휴일","",IF(BF33>=BF34,"충족","미달")) | BI35: =IF(BI$6="휴일","",IF(BI33>=BI34,"충족","미달")) | BL35: =IF(BL$6="휴일","",IF(BL33>=BL34,"충족","미달")) | BO35: =IF(BO$6="휴일","",IF(BO33>=BO34,"충족","미달")) | BR35: =IF(BR$6="휴일","",IF(BR33>=BR34,"충족","미달")) | BU35: =IF(BU$6="휴일","",IF(BU33>=BU34,"충족","미달")) | BX35: =IF(BX$6="휴일","",IF(BX33>=BX34,"충족","미달")) | CA35: =IF(CA$6="휴일","",IF(CA33>=CA34,"충족","미달")) | CD35: =IF(CD$6="휴일","",IF(CD33>=CD34,"충족","미달")) | CG35: =IF(CG$6="휴일","",IF(CG33>=CG34,"충족","미달")) | CJ35: =IF(CJ$6="휴일","",IF(CJ33>=CJ34,"충족","미달")) | CM35: =IF(CM$6="휴일","",IF(CM33>=CM34,"충족","미달")) | CP35: =IF(CP$6="휴일","",IF(CP33>=CP34,"충족","미달"))
A36: 직책자 8시간 | D36: =IF(D$6="휴일","",SUMPRODUCT((명부!$F$2:$F$7<>"Y")*(시간!$D$92:$D$97))) | G36: =IF(G$6="휴일","",SUMPRODUCT((명부!$F$2:$F$7<>"Y")*(시간!$E$92:$E$97))) | J36: =IF(J$6="휴일","",SUMPRODUCT((명부!$F$2:$F$7<>"Y")*(시간!$F$92:$F$97))) | M36: =IF(M$6="휴일","",SUMPRODUCT((명부!$F$2:$F$7<>"Y")*(시간!$G$92:$G$97))) | P36: =IF(P$6="휴일","",SUMPRODUCT((명부!$F$2:$F$7<>"Y")*(시간!$H$92:$H$97))) | S36: =IF(S$6="휴일","",SUMPRODUCT((명부!$F$2:$F$7<>"Y")*(시간!$I$92:$I$97))) | V36: =IF(V$6="휴일","",SUMPRODUCT((명부!$F$2:$F$7<>"Y")*(시간!$J$92:$J$97))) | Y36: =IF(Y$6="휴일","",SUMPRODUCT((명부!$F$2:$F$7<>"Y")*(시간!$K$92:$K$97))) | AB36: =IF(AB$6="휴일","",SUMPRODUCT((명부!$F$2:$F$7<>"Y")*(시간!$L$92:$L$97))) | AE36: =IF(AE$6="휴일","",SUMPRODUCT((명부!$F$2:$F$7<>"Y")*(시간!$M$92:$M$97))) | AH36: =IF(AH$6="휴일","",SUMPRODUCT((명부!$F$2:$F$7<>"Y")*(시간!$N$92:$N$97))) | AK36: =IF(AK$6="휴일","",SUMPRODUCT((명부!$F$2:$F$7<>"Y")*(시간!$O$92:$O$97))) | AN36: =IF(AN$6="휴일","",SUMPRODUCT((명부!$F$2:$F$7<>"Y")*(시간!$P$92:$P$97))) | AQ36: =IF(AQ$6="휴일","",SUMPRODUCT((명부!$F$2:$F$7<>"Y")*(시간!$Q$92:$Q$97))) | AT36: =IF(AT$6="휴일","",SUMPRODUCT((명부!$F$2:$F$7<>"Y")*(시간!$R$92:$R$97))) | AW36: =IF(AW$6="휴일","",SUMPRODUCT((명부!$F$2:$F$7<>"Y")*(시간!$S$92:$S$97))) | AZ36: =IF(AZ$6="휴일","",SUMPRODUCT((명부!$F$2:$F$7<>"Y")*(시간!$T$92:$T$97))) | BC36: =IF(BC$6="휴일","",SUMPRODUCT((명부!$F$2:$F$7<>"Y")*(시간!$U$92:$U$97))) | BF36: =IF(BF$6="휴일","",SUMPRODUCT((명부!$F$2:$F$7<>"Y")*(시간!$V$92:$V$97))) | BI36: =IF(BI$6="휴일","",SUMPRODUCT((명부!$F$2:$F$7<>"Y")*(시간!$W$92:$W$97))) | BL36: =IF(BL$6="휴일","",SUMPRODUCT((명부!$F$2:$F$7<>"Y")*(시간!$X$92:$X$97))) | BO36: =IF(BO$6="휴일","",SUMPRODUCT((명부!$F$2:$F$7<>"Y")*(시간!$Y$92:$Y$97))) | BR36: =IF(BR$6="휴일","",SUMPRODUCT((명부!$F$2:$F$7<>"Y")*(시간!$Z$92:$Z$97))) | BU36: =IF(BU$6="휴일","",SUMPRODUCT((명부!$F$2:$F$7<>"Y")*(시간!$AA$92:$AA$97))) | BX36: =IF(BX$6="휴일","",SUMPRODUCT((명부!$F$2:$F$7<>"Y")*(시간!$AB$92:$AB$97))) | CA36: =IF(CA$6="휴일","",SUMPRODUCT((명부!$F$2:$F$7<>"Y")*(시간!$AC$92:$AC$97))) | CD36: =IF(CD$6="휴일","",SUMPRODUCT((명부!$F$2:$F$7<>"Y")*(시간!$AD$92:$AD$97))) | CG36: =IF(CG$6="휴일","",SUMPRODUCT((명부!$F$2:$F$7<>"Y")*(시간!$AE$92:$AE$97))) | CJ36: =IF(CJ$6="휴일","",SUMPRODUCT((명부!$F$2:$F$7<>"Y")*(시간!$AF$92:$AF$97))) | CM36: =IF(CM$6="휴일","",SUMPRODUCT((명부!$F$2:$F$7<>"Y")*(시간!$AG$92:$AG$97))) | CP36: =IF(CP$6="휴일","",SUMPRODUCT((명부!$F$2:$F$7<>"Y")*(시간!$AH$92:$AH$97)))
A38: 판정이 「미달」인 날은 노랗게 강조된 칸이 조율 후보입니다 — 그 사람이 8시간 근무로 바꾸면 충족됩니다 (출장·교육·연차는 후보에서 제외). 빨간 칸은 규칙에 없는 조합이니 유형·출근·퇴근을 다시 고르세요.

Sheet OT
D1: OT — 날짜별 초과근로 시간
D2: 1시간 45분은 1.75 로 넣습니다 (분 단위 신청) · 월 합계와 잔여는 「개인요약」 시트에서 봅니다
A3: 주 | D3: =IF(D4="","",INT((D4-1+MOD(WEEKDAY(DATE(근태!$B$1,근태!$B$2,1))+5,7))/7)+1) | E3: =IF(E4="","",INT((E4-1+MOD(WEEKDAY(DATE(근태!$B$1,근태!$B$2,1))+5,7))/7)+1) | F3: =IF(F4="","",INT((F4-1+MOD(WEEKDAY(DATE(근태!$B$1,근태!$B$2,1))+5,7))/7)+1) | G3: =IF(G4="","",INT((G4-1+MOD(WEEKDAY(DATE(근태!$B$1,근태!$B$2,1))+5,7))/7)+1) | H3: =IF(H4="","",INT((H4-1+MOD(WEEKDAY(DATE(근태!$B$1,근태!$B$2,1))+5,7))/7)+1) | I3: =IF(I4="","",INT((I4-1+MOD(WEEKDAY(DATE(근태!$B$1,근태!$B$2,1))+5,7))/7)+1) | J3: =IF(J4="","",INT((J4-1+MOD(WEEKDAY(DATE(근태!$B$1,근태!$B$2,1))+5,7))/7)+1) | K3: =IF(K4="","",INT((K4-1+MOD(WEEKDAY(DATE(근태!$B$1,근태!$B$2,1))+5,7))/7)+1) | ... AH3: =IF(AH4="","",INT((AH4-1+MOD(WEEKDAY(DATE(근태!$B$1,근태!$B$2,1))+5,7))/7)+1)
D4: =IF(MONTH(DATE(근태!$B$1,근태!$B$2,1))<>근태!$B$2,"",1) | E4: =IF(MONTH(DATE(근태!$B$1,근태!$B$2,2))<>근태!$B$2,"",2) | F4: =IF(MONTH(DATE(근태!$B$1,근태!$B$2,3))<>근태!$B$2,"",3) | G4: =IF(MONTH(DATE(근태!$B$1,근태!$B$2,4))<>근태!$B$2,"",4) | H4: =IF(MONTH(DATE(근태!$B$1,근태!$B$2,5))<>근태!$B$2,"",5) | I4: =IF(MONTH(DATE(근태!$B$1,근태!$B$2,6))<>근태!$B$2,"",6) | J4: =IF(MONTH(DATE(근태!$B$1,근태!$B$2,7))<>근태!$B$2,"",7) | K4: =IF(MONTH(DATE(근태!$B$1,근태!$B$2,8))<>근태!$B$2,"",8) | L4: =IF(MONTH(DATE(근태!$B$1,근태!$B$2,9))<>근태!$B$2,"",9) | M4: =IF(MONTH(DATE(근태!$B$1,근태!$B$2,10))<>근태!$B$2,"",10) | N4: =IF(MONTH(DATE(근태!$B$1,근태!$B$2,11))<>근태!$B$2,"",11) | O4: =IF(MONTH(DATE(근태!$B$1,근태!$B$2,12))<>근태!$B$2,"",12) | P4: =IF(MONTH(DATE(근태!$B$1,근태!$B$2,13))<>근태!$B$2,"",13) | Q4: =IF(MONTH(DATE(근태!$B$1,근태!$B$2,14))<>근태!$B$2,"",14) | R4: =IF(MONTH(DATE(근태!$B$1,근태!$B$2,15))<>근태!$B$2,"",15) | S4: =IF(MONTH(DATE(근태!$B$1,근태!$B$2,16))<>근태!$B$2,"",16) | T4: =IF(MONTH(DATE(근태!$B$1,근태!$B$2,17))<>근태!$B$2,"",17) | U4: =IF(MONTH(DATE(근태!$B$1,근태!$B$2,18))<>근태!$B$2,"",18) | V4: =IF(MONTH(DATE(근태!$B$1,근태!$B$2,19))<>근태!$B$2,"",19) | W4: =IF(MONTH(DATE(근태!$B$1,근태!$B$2,20))<>근태!$B$2,"",20) | X4: =IF(MONTH(DATE(근태!$B$1,근태!$B$2,21))<>근태!$B$2,"",21) | Y4: =IF(MONTH(DATE(근태!$B$1,근태!$B$2,22))<>근태!$B$2,"",22) | Z4: =IF(MONTH(DATE(근태!$B$1,근태!$B$2,23))<>근태!$B$2,"",23) | AA4: =IF(MONTH(DATE(근태!$B$1,근태!$B$2,24))<>근태!$B$2,"",24) | AB4: =IF(MONTH(DATE(근태!$B$1,근태!$B$2,25))<>근태!$B$2,"",25) | AC4: =IF(MONTH(DATE(근태!$B$1,근태!$B$2,26))<>근태!$B$2,"",26) | AD4: =IF(MONTH(DATE(근태!$B$1,근태!$B$2,27))<>근태!$B$2,"",27) | AE4: =IF(MONTH(DATE(근태!$B$1,근태!$B$2,28))<>근태!$B$2,"",28) | AF4: =IF(MONTH(DATE(근태!$B$1,근태!$B$2,29))<>근태!$B$2,"",29) | AG4: =IF(MONTH(DATE(근태!$B$1,근태!$B$2,30))<>근태!$B$2,"",30) | AH4: =IF(MONTH(DATE(근태!$B$1,근태!$B$2,31))<>근태!$B$2,"",31)
D5: =IF(D$4="","",INDEX(코드!$M$2:$M$8,WEEKDAY(DATE(근태!$B$1,근태!$B$2,D$4)))) | E5: =IF(E$4="","",INDEX(코드!$M$2:$M$8,WEEKDAY(DATE(근태!$B$1,근태!$B$2,E$4)))) | F5: =IF(F$4="","",INDEX(코드!$M$2:$M$8,WEEKDAY(DATE(근태!$B$1,근태!$B$2,F$4)))) | G5: =IF(G$4="","",INDEX(코드!$M$2:$M$8,WEEKDAY(DATE(근태!$B$1,근태!$B$2,G$4)))) | H5: =IF(H$4="","",INDEX(코드!$M$2:$M$8,WEEKDAY(DATE(근태!$B$1,근태!$B$2,H$4)))) | I5: =IF(I$4="","",INDEX(코드!$M$2:$M$8,WEEKDAY(DATE(근태!$B$1,근태!$B$2,I$4)))) | J5: =IF(J$4="","",INDEX(코드!$M$2:$M$8,WEEKDAY(DATE(근태!$B$1,근태!$B$2,J$4)))) | K5: =IF(K$4="","",INDEX(코드!$M$2:$M$8,WEEKDAY(DATE(근태!$B$1,근태!$B$2,K$4)))) | ... AH5: =IF(AH$4="","",INDEX(코드!$M$2:$M$8,WEEKDAY(DATE(근태!$B$1,근태!$B$2,AH$4))))
D6: =IF(D$4="","",IF(OR(WEEKDAY(DATE(근태!$B$1,근태!$B$2,D$4),2)>5,COUNTIF(공휴일!$A$2:$A$400,DATE(근태!$B$1,근태!$B$2,D$4))>0),"휴일","")) | E6: =IF(E$4="","",IF(OR(WEEKDAY(DATE(근태!$B$1,근태!$B$2,E$4),2)>5,COUNTIF(공휴일!$A$2:$A$400,DATE(근태!$B$1,근태!$B$2,E$4))>0),"휴일","")) | F6: =IF(F$4="","",IF(OR(WEEKDAY(DATE(근태!$B$1,근태!$B$2,F$4),2)>5,COUNTIF(공휴일!$A$2:$A$400,DATE(근태!$B$1,근태!$B$2,F$4))>0),"휴일","")) | G6: =IF(G$4="","",IF(OR(WEEKDAY(DATE(근태!$B$1,근태!$B$2,G$4),2)>5,COUNTIF(공휴일!$A$2:$A$400,DATE(근태!$B$1,근태!$B$2,G$4))>0),"휴일","")) | H6: =IF(H$4="","",IF(OR(WEEKDAY(DATE(근태!$B$1,근태!$B$2,H$4),2)>5,COUNTIF(공휴일!$A$2:$A$400,DATE(근태!$B$1,근태!$B$2,H$4))>0),"휴일","")) | I6: =IF(I$4="","",IF(OR(WEEKDAY(DATE(근태!$B$1,근태!$B$2,I$4),2)>5,COUNTIF(공휴일!$A$2:$A$400,DATE(근태!$B$1,근태!$B$2,I$4))>0),"휴일","")) | J6: =IF(J$4="","",IF(OR(WEEKDAY(DATE(근태!$B$1,근태!$B$2,J$4),2)>5,COUNTIF(공휴일!$A$2:$A$400,DATE(근태!$B$1,근태!$B$2,J$4))>0),"휴일","")) | K6: =IF(K$4="","",IF(OR(WEEKDAY(DATE(근태!$B$1,근태!$B$2,K$4),2)>5,COUNTIF(공휴일!$A$2:$A$400,DATE(근태!$B$1,근태!$B$2,K$4))>0),"휴일","")) | ... AH6: =IF(AH$4="","",IF(OR(WEEKDAY(DATE(근태!$B$1,근태!$B$2,AH$4),2)>5,COUNTIF(공휴일!$A$2:$A$400,DATE(근태!$B$1,근태!$B$2,AH$4))>0),"휴일",""))
A7: 이름 | B7: 파트 | C7: 그룹
A8: =IF(명부!A2="","",명부!A2) | B8: =IF(명부!C2="","",명부!C2) | C8: =IF(명부!E2="","",명부!E2)
A9: =IF(명부!A3="","",명부!A3) | B9: =IF(명부!C3="","",명부!C3) | C9: =IF(명부!E3="","",명부!E3)
A10: =IF(명부!A4="","",명부!A4) | B10: =IF(명부!C4="","",명부!C4) | C10: =IF(명부!E4="","",명부!E4)
A11: =IF(명부!A5="","",명부!A5) | B11: =IF(명부!C5="","",명부!C5) | C11: =IF(명부!E5="","",명부!E5)
A12: =IF(명부!A6="","",명부!A6) | B12: =IF(명부!C6="","",명부!C6) | C12: =IF(명부!E6="","",명부!E6)
A13: =IF(명부!A7="","",명부!A7) | B13: =IF(명부!C7="","",명부!C7) | C13: =IF(명부!E7="","",명부!E7)
A14: =IF(명부!A8="","",명부!A8) | B14: =IF(명부!C8="","",명부!C8) | C14: =IF(명부!E8="","",명부!E8)
A15: =IF(명부!A9="","",명부!A9) | B15: =IF(명부!C9="","",명부!C9) | C15: =IF(명부!E9="","",명부!E9)
A16: =IF(명부!A10="","",명부!A10) | B16: =IF(명부!C10="","",명부!C10) | C16: =IF(명부!E10="","",명부!E10)
A17: =IF(명부!A11="","",명부!A11) | B17: =IF(명부!C11="","",명부!C11) | C17: =IF(명부!E11="","",명부!E11)
A18: =IF(명부!A12="","",명부!A12) | B18: =IF(명부!C12="","",명부!C12) | C18: =IF(명부!E12="","",명부!E12)
A19: =IF(명부!A13="","",명부!A13) | B19: =IF(명부!C13="","",명부!C13) | C19: =IF(명부!E13="","",명부!E13)
... A31: =IF(명부!A25="","",명부!A25) | B31: =IF(명부!C25="","",명부!C25) | C31: =IF(명부!E25="","",명부!E25)
A34: 선택근로 시간과 OT 시간은 나눠서 관리합니다. 자정을 넘긴 OT 도 시간만 합쳐서 넣으면 됩니다.

Sheet 개인요약
A1: 개인요약 — 월 총량 · OT 잔여 · 주별 근로시간
A2: 「근태」 시트의 연·월을 따릅니다. 노란 칸(OT 기본 가능시간)만 직접 넣으세요 — 휴가를 쓰면 그 시간만큼 OT 한도가 자동으로 늘어납니다.
A7: 이름 | B7: 파트 | C7: 그룹 | D7: 소정근로일 | E7: 기본 총량 | F7: 휴가 | G7: 조정 총량 | H7: 실근로 | I7: 총량 대비 | J7: OT 합계 | K7: OT 기본 | L7: OT 한도 | M7: OT 잔여 | N7: 8시간 일수 | O7: 1주 | P7: 2주 | Q7: 3주 | R7: 4주 | S7: 5주 | T7: 6주 | U7: 최대 주 | V7: 주 64h
A8: =IF(명부!A2="","",명부!A2) | B8: =IF(명부!C2="","",명부!C2) | C8: =IF(명부!E2="","",명부!E2) | D8: =SUMPRODUCT((시간!$D$4:$AH$4<>"")*(시간!$D$6:$AH$6="")) | E8: =D8*8 | F8: =SUM(시간!$D$64:$AH$64) | G8: =E8-F8 | H8: =SUM(시간!$D$36:$AH$36) | I8: =H8-G8 | J8: =SUM(OT!$D$8:$AH$8) | L8: =K8+F8 | M8: =L8-J8 | N8: =SUM(시간!$D$92:$AH$92) | O8: =SUMPRODUCT((시간!$D$3:$AH$3=1)*(시간!$D$36:$AH$36))+SUMPRODUCT((시간!$D$3:$AH$3=1)*(OT!$D$8:$AH$8)) | P8: =SUMPRODUCT((시간!$D$3:$AH$3=2)*(시간!$D$36:$AH$36))+SUMPRODUCT((시간!$D$3:$AH$3=2)*(OT!$D$8:$AH$8)) | Q8: =SUMPRODUCT((시간!$D$3:$AH$3=3)*(시간!$D$36:$AH$36))+SUMPRODUCT((시간!$D$3:$AH$3=3)*(OT!$D$8:$AH$8)) | R8: =SUMPRODUCT((시간!$D$3:$AH$3=4)*(시간!$D$36:$AH$36))+SUMPRODUCT((시간!$D$3:$AH$3=4)*(OT!$D$8:$AH$8)) | S8: =SUMPRODUCT((시간!$D$3:$AH$3=5)*(시간!$D$36:$AH$36))+SUMPRODUCT((시간!$D$3:$AH$3=5)*(OT!$D$8:$AH$8)) | T8: =SUMPRODUCT((시간!$D$3:$AH$3=6)*(시간!$D$36:$AH$36))+SUMPRODUCT((시간!$D$3:$AH$3=6)*(OT!$D$8:$AH$8)) | U8: =MAX(O8:T8) | V8: =IF(U8>64,"초과","적합")
A9: =IF(명부!A3="","",명부!A3) | B9: =IF(명부!C3="","",명부!C3) | C9: =IF(명부!E3="","",명부!E3) | D9: =SUMPRODUCT((시간!$D$4:$AH$4<>"")*(시간!$D$6:$AH$6="")) | E9: =D9*8 | F9: =SUM(시간!$D$65:$AH$65) | G9: =E9-F9 | H9: =SUM(시간!$D$37:$AH$37) | I9: =H9-G9 | J9: =SUM(OT!$D$9:$AH$9) | L9: =K9+F9 | M9: =L9-J9 | N9: =SUM(시간!$D$93:$AH$93) | O9: =SUMPRODUCT((시간!$D$3:$AH$3=1)*(시간!$D$37:$AH$37))+SUMPRODUCT((시간!$D$3:$AH$3=1)*(OT!$D$9:$AH$9)) | P9: =SUMPRODUCT((시간!$D$3:$AH$3=2)*(시간!$D$37:$AH$37))+SUMPRODUCT((시간!$D$3:$AH$3=2)*(OT!$D$9:$AH$9)) | Q9: =SUMPRODUCT((시간!$D$3:$AH$3=3)*(시간!$D$37:$AH$37))+SUMPRODUCT((시간!$D$3:$AH$3=3)*(OT!$D$9:$AH$9)) | R9: =SUMPRODUCT((시간!$D$3:$AH$3=4)*(시간!$D$37:$AH$37))+SUMPRODUCT((시간!$D$3:$AH$3=4)*(OT!$D$9:$AH$9)) | S9: =SUMPRODUCT((시간!$D$3:$AH$3=5)*(시간!$D$37:$AH$37))+SUMPRODUCT((시간!$D$3:$AH$3=5)*(OT!$D$9:$AH$9)) | T9: =SUMPRODUCT((시간!$D$3:$AH$3=6)*(시간!$D$37:$AH$37))+SUMPRODUCT((시간!$D$3:$AH$3=6)*(OT!$D$9:$AH$9)) | U9: =MAX(O9:T9) | V9: =IF(U9>64,"초과","적합")
A10: =IF(명부!A4="","",명부!A4) | B10: =IF(명부!C4="","",명부!C4) | C10: =IF(명부!E4="","",명부!E4) | D10: =SUMPRODUCT((시간!$D$4:$AH$4<>"")*(시간!$D$6:$AH$6="")) | E10: =D10*8 | F10: =SUM(시간!$D$66:$AH$66) | G10: =E10-F10 | H10: =SUM(시간!$D$38:$AH$38) | I10: =H10-G10 | J10: =SUM(OT!$D$10:$AH$10) | L10: =K10+F10 | M10: =L10-J10 | N10: =SUM(시간!$D$94:$AH$94) | O10: =SUMPRODUCT((시간!$D$3:$AH$3=1)*(시간!$D$38:$AH$38))+SUMPRODUCT((시간!$D$3:$AH$3=1)*(OT!$D$10:$AH$10)) | P10: =SUMPRODUCT((시간!$D$3:$AH$3=2)*(시간!$D$38:$AH$38))+SUMPRODUCT((시간!$D$3:$AH$3=2)*(OT!$D$10:$AH$10)) | Q10: =SUMPRODUCT((시간!$D$3:$AH$3=3)*(시간!$D$38:$AH$38))+SUMPRODUCT((시간!$D$3:$AH$3=3)*(OT!$D$10:$AH$10)) | R10: =SUMPRODUCT((시간!$D$3:$AH$3=4)*(시간!$D$38:$AH$38))+SUMPRODUCT((시간!$D$3:$AH$3=4)*(OT!$D$10:$AH$10)) | S10: =SUMPRODUCT((시간!$D$3:$AH$3=5)*(시간!$D$38:$AH$38))+SUMPRODUCT((시간!$D$3:$AH$3=5)*(OT!$D$10:$AH$10)) | T10: =SUMPRODUCT((시간!$D$3:$AH$3=6)*(시간!$D$38:$AH$38))+SUMPRODUCT((시간!$D$3:$AH$3=6)*(OT!$D$10:$AH$10)) | U10: =MAX(O10:T10) | V10: =IF(U10>64,"초과","적합")
A11: =IF(명부!A5="","",명부!A5) | B11: =IF(명부!C5="","",명부!C5) | C11: =IF(명부!E5="","",명부!E5) | D11: =SUMPRODUCT((시간!$D$4:$AH$4<>"")*(시간!$D$6:$AH$6="")) | E11: =D11*8 | F11: =SUM(시간!$D$67:$AH$67) | G11: =E11-F11 | H11: =SUM(시간!$D$39:$AH$39) | I11: =H11-G11 | J11: =SUM(OT!$D$11:$AH$11) | L11: =K11+F11 | M11: =L11-J11 | N11: =SUM(시간!$D$95:$AH$95) | O11: =SUMPRODUCT((시간!$D$3:$AH$3=1)*(시간!$D$39:$AH$39))+SUMPRODUCT((시간!$D$3:$AH$3=1)*(OT!$D$11:$AH$11)) | P11: =SUMPRODUCT((시간!$D$3:$AH$3=2)*(시간!$D$39:$AH$39))+SUMPRODUCT((시간!$D$3:$AH$3=2)*(OT!$D$11:$AH$11)) | Q11: =SUMPRODUCT((시간!$D$3:$AH$3=3)*(시간!$D$39:$AH$39))+SUMPRODUCT((시간!$D$3:$AH$3=3)*(OT!$D$11:$AH$11)) | R11: =SUMPRODUCT((시간!$D$3:$AH$3=4)*(시간!$D$39:$AH$39))+SUMPRODUCT((시간!$D$3:$AH$3=4)*(OT!$D$11:$AH$11)) | S11: =SUMPRODUCT((시간!$D$3:$AH$3=5)*(시간!$D$39:$AH$39))+SUMPRODUCT((시간!$D$3:$AH$3=5)*(OT!$D$11:$AH$11)) | T11: =SUMPRODUCT((시간!$D$3:$AH$3=6)*(시간!$D$39:$AH$39))+SUMPRODUCT((시간!$D$3:$AH$3=6)*(OT!$D$11:$AH$11)) | U11: =MAX(O11:T11) | V11: =IF(U11>64,"초과","적합")
A12: =IF(명부!A6="","",명부!A6) | B12: =IF(명부!C6="","",명부!C6) | C12: =IF(명부!E6="","",명부!E6) | D12: =SUMPRODUCT((시간!$D$4:$AH$4<>"")*(시간!$D$6:$AH$6="")) | E12: =D12*8 | F12: =SUM(시간!$D$68:$AH$68) | G12: =E12-F12 | H12: =SUM(시간!$D$40:$AH$40) | I12: =H12-G12 | J12: =SUM(OT!$D$12:$AH$12) | L12: =K12+F12 | M12: =L12-J12 | N12: =SUM(시간!$D$96:$AH$96) | O12: =SUMPRODUCT((시간!$D$3:$AH$3=1)*(시간!$D$40:$AH$40))+SUMPRODUCT((시간!$D$3:$AH$3=1)*(OT!$D$12:$AH$12)) | P12: =SUMPRODUCT((시간!$D$3:$AH$3=2)*(시간!$D$40:$AH$40))+SUMPRODUCT((시간!$D$3:$AH$3=2)*(OT!$D$12:$AH$12)) | Q12: =SUMPRODUCT((시간!$D$3:$AH$3=3)*(시간!$D$40:$AH$40))+SUMPRODUCT((시간!$D$3:$AH$3=3)*(OT!$D$12:$AH$12)) | R12: =SUMPRODUCT((시간!$D$3:$AH$3=4)*(시간!$D$40:$AH$40))+SUMPRODUCT((시간!$D$3:$AH$3=4)*(OT!$D$12:$AH$12)) | S12: =SUMPRODUCT((시간!$D$3:$AH$3=5)*(시간!$D$40:$AH$40))+SUMPRODUCT((시간!$D$3:$AH$3=5)*(OT!$D$12:$AH$12)) | T12: =SUMPRODUCT((시간!$D$3:$AH$3=6)*(시간!$D$40:$AH$40))+SUMPRODUCT((시간!$D$3:$AH$3=6)*(OT!$D$12:$AH$12)) | U12: =MAX(O12:T12) | V12: =IF(U12>64,"초과","적합")
A13: =IF(명부!A7="","",명부!A7) | B13: =IF(명부!C7="","",명부!C7) | C13: =IF(명부!E7="","",명부!E7) | D13: =SUMPRODUCT((시간!$D$4:$AH$4<>"")*(시간!$D$6:$AH$6="")) | E13: =D13*8 | F13: =SUM(시간!$D$69:$AH$69) | G13: =E13-F13 | H13: =SUM(시간!$D$41:$AH$41) | I13: =H13-G13 | J13: =SUM(OT!$D$13:$AH$13) | L13: =K13+F13 | M13: =L13-J13 | N13: =SUM(시간!$D$97:$AH$97) | O13: =SUMPRODUCT((시간!$D$3:$AH$3=1)*(시간!$D$41:$AH$41))+SUMPRODUCT((시간!$D$3:$AH$3=1)*(OT!$D$13:$AH$13)) | P13: =SUMPRODUCT((시간!$D$3:$AH$3=2)*(시간!$D$41:$AH$41))+SUMPRODUCT((시간!$D$3:$AH$3=2)*(OT!$D$13:$AH$13)) | Q13: =SUMPRODUCT((시간!$D$3:$AH$3=3)*(시간!$D$41:$AH$41))+SUMPRODUCT((시간!$D$3:$AH$3=3)*(OT!$D$13:$AH$13)) | R13: =SUMPRODUCT((시간!$D$3:$AH$3=4)*(시간!$D$41:$AH$41))+SUMPRODUCT((시간!$D$3:$AH$3=4)*(OT!$D$13:$AH$13)) | S13: =SUMPRODUCT((시간!$D$3:$AH$3=5)*(시간!$D$41:$AH$41))+SUMPRODUCT((시간!$D$3:$AH$3=5)*(OT!$D$13:$AH$13)) | T13: =SUMPRODUCT((시간!$D$3:$AH$3=6)*(시간!$D$41:$AH$41))+SUMPRODUCT((시간!$D$3:$AH$3=6)*(OT!$D$13:$AH$13)) | U13: =MAX(O13:T13) | V13: =IF(U13>64,"초과","적합")
A14: =IF(명부!A8="","",명부!A8) | B14: =IF(명부!C8="","",명부!C8) | C14: =IF(명부!E8="","",명부!E8) | D14: =SUMPRODUCT((시간!$D$4:$AH$4<>"")*(시간!$D$6:$AH$6="")) | E14: =D14*8 | F14: =SUM(시간!$D$70:$AH$70) | G14: =E14-F14 | H14: =SUM(시간!$D$42:$AH$42) | I14: =H14-G14 | J14: =SUM(OT!$D$14:$AH$14) | L14: =K14+F14 | M14: =L14-J14 | N14: =SUM(시간!$D$98:$AH$98) | O14: =SUMPRODUCT((시간!$D$3:$AH$3=1)*(시간!$D$42:$AH$42))+SUMPRODUCT((시간!$D$3:$AH$3=1)*(OT!$D$14:$AH$14)) | P14: =SUMPRODUCT((시간!$D$3:$AH$3=2)*(시간!$D$42:$AH$42))+SUMPRODUCT((시간!$D$3:$AH$3=2)*(OT!$D$14:$AH$14)) | Q14: =SUMPRODUCT((시간!$D$3:$AH$3=3)*(시간!$D$42:$AH$42))+SUMPRODUCT((시간!$D$3:$AH$3=3)*(OT!$D$14:$AH$14)) | R14: =SUMPRODUCT((시간!$D$3:$AH$3=4)*(시간!$D$42:$AH$42))+SUMPRODUCT((시간!$D$3:$AH$3=4)*(OT!$D$14:$AH$14)) | S14: =SUMPRODUCT((시간!$D$3:$AH$3=5)*(시간!$D$42:$AH$42))+SUMPRODUCT((시간!$D$3:$AH$3=5)*(OT!$D$14:$AH$14)) | T14: =SUMPRODUCT((시간!$D$3:$AH$3=6)*(시간!$D$42:$AH$42))+SUMPRODUCT((시간!$D$3:$AH$3=6)*(OT!$D$14:$AH$14)) | U14: =MAX(O14:T14) | V14: =IF(U14>64,"초과","적합")
A15: =IF(명부!A9="","",명부!A9) | B15: =IF(명부!C9="","",명부!C9) | C15: =IF(명부!E9="","",명부!E9) | D15: =SUMPRODUCT((시간!$D$4:$AH$4<>"")*(시간!$D$6:$AH$6="")) | E15: =D15*8 | F15: =SUM(시간!$D$71:$AH$71) | G15: =E15-F15 | H15: =SUM(시간!$D$43:$AH$43) | I15: =H15-G15 | J15: =SUM(OT!$D$15:$AH$15) | L15: =K15+F15 | M15: =L15-J15 | N15: =SUM(시간!$D$99:$AH$99) | O15: =SUMPRODUCT((시간!$D$3:$AH$3=1)*(시간!$D$43:$AH$43))+SUMPRODUCT((시간!$D$3:$AH$3=1)*(OT!$D$15:$AH$15)) | P15: =SUMPRODUCT((시간!$D$3:$AH$3=2)*(시간!$D$43:$AH$43))+SUMPRODUCT((시간!$D$3:$AH$3=2)*(OT!$D$15:$AH$15)) | Q15: =SUMPRODUCT((시간!$D$3:$AH$3=3)*(시간!$D$43:$AH$43))+SUMPRODUCT((시간!$D$3:$AH$3=3)*(OT!$D$15:$AH$15)) | R15: =SUMPRODUCT((시간!$D$3:$AH$3=4)*(시간!$D$43:$AH$43))+SUMPRODUCT((시간!$D$3:$AH$3=4)*(OT!$D$15:$AH$15)) | S15: =SUMPRODUCT((시간!$D$3:$AH$3=5)*(시간!$D$43:$AH$43))+SUMPRODUCT((시간!$D$3:$AH$3=5)*(OT!$D$15:$AH$15)) | T15: =SUMPRODUCT((시간!$D$3:$AH$3=6)*(시간!$D$43:$AH$43))+SUMPRODUCT((시간!$D$3:$AH$3=6)*(OT!$D$15:$AH$15)) | U15: =MAX(O15:T15) | V15: =IF(U15>64,"초과","적합")
A16: =IF(명부!A10="","",명부!A10) | B16: =IF(명부!C10="","",명부!C10) | C16: =IF(명부!E10="","",명부!E10) | D16: =SUMPRODUCT((시간!$D$4:$AH$4<>"")*(시간!$D$6:$AH$6="")) | E16: =D16*8 | F16: =SUM(시간!$D$72:$AH$72) | G16: =E16-F16 | H16: =SUM(시간!$D$44:$AH$44) | I16: =H16-G16 | J16: =SUM(OT!$D$16:$AH$16) | L16: =K16+F16 | M16: =L16-J16 | N16: =SUM(시간!$D$100:$AH$100) | O16: =SUMPRODUCT((시간!$D$3:$AH$3=1)*(시간!$D$44:$AH$44))+SUMPRODUCT((시간!$D$3:$AH$3=1)*(OT!$D$16:$AH$16)) | P16: =SUMPRODUCT((시간!$D$3:$AH$3=2)*(시간!$D$44:$AH$44))+SUMPRODUCT((시간!$D$3:$AH$3=2)*(OT!$D$16:$AH$16)) | Q16: =SUMPRODUCT((시간!$D$3:$AH$3=3)*(시간!$D$44:$AH$44))+SUMPRODUCT((시간!$D$3:$AH$3=3)*(OT!$D$16:$AH$16)) | R16: =SUMPRODUCT((시간!$D$3:$AH$3=4)*(시간!$D$44:$AH$44))+SUMPRODUCT((시간!$D$3:$AH$3=4)*(OT!$D$16:$AH$16)) | S16: =SUMPRODUCT((시간!$D$3:$AH$3=5)*(시간!$D$44:$AH$44))+SUMPRODUCT((시간!$D$3:$AH$3=5)*(OT!$D$16:$AH$16)) | T16: =SUMPRODUCT((시간!$D$3:$AH$3=6)*(시간!$D$44:$AH$44))+SUMPRODUCT((시간!$D$3:$AH$3=6)*(OT!$D$16:$AH$16)) | U16: =MAX(O16:T16) | V16: =IF(U16>64,"초과","적합")
A17: =IF(명부!A11="","",명부!A11) | B17: =IF(명부!C11="","",명부!C11) | C17: =IF(명부!E11="","",명부!E11) | D17: =SUMPRODUCT((시간!$D$4:$AH$4<>"")*(시간!$D$6:$AH$6="")) | E17: =D17*8 | F17: =SUM(시간!$D$73:$AH$73) | G17: =E17-F17 | H17: =SUM(시간!$D$45:$AH$45) | I17: =H17-G17 | J17: =SUM(OT!$D$17:$AH$17) | L17: =K17+F17 | M17: =L17-J17 | N17: =SUM(시간!$D$101:$AH$101) | O17: =SUMPRODUCT((시간!$D$3:$AH$3=1)*(시간!$D$45:$AH$45))+SUMPRODUCT((시간!$D$3:$AH$3=1)*(OT!$D$17:$AH$17)) | P17: =SUMPRODUCT((시간!$D$3:$AH$3=2)*(시간!$D$45:$AH$45))+SUMPRODUCT((시간!$D$3:$AH$3=2)*(OT!$D$17:$AH$17)) | Q17: =SUMPRODUCT((시간!$D$3:$AH$3=3)*(시간!$D$45:$AH$45))+SUMPRODUCT((시간!$D$3:$AH$3=3)*(OT!$D$17:$AH$17)) | R17: =SUMPRODUCT((시간!$D$3:$AH$3=4)*(시간!$D$45:$AH$45))+SUMPRODUCT((시간!$D$3:$AH$3=4)*(OT!$D$17:$AH$17)) | S17: =SUMPRODUCT((시간!$D$3:$AH$3=5)*(시간!$D$45:$AH$45))+SUMPRODUCT((시간!$D$3:$AH$3=5)*(OT!$D$17:$AH$17)) | T17: =SUMPRODUCT((시간!$D$3:$AH$3=6)*(시간!$D$45:$AH$45))+SUMPRODUCT((시간!$D$3:$AH$3=6)*(OT!$D$17:$AH$17)) | U17: =MAX(O17:T17) | V17: =IF(U17>64,"초과","적합")
A18: =IF(명부!A12="","",명부!A12) | B18: =IF(명부!C12="","",명부!C12) | C18: =IF(명부!E12="","",명부!E12) | D18: =SUMPRODUCT((시간!$D$4:$AH$4<>"")*(시간!$D$6:$AH$6="")) | E18: =D18*8 | F18: =SUM(시간!$D$74:$AH$74) | G18: =E18-F18 | H18: =SUM(시간!$D$46:$AH$46) | I18: =H18-G18 | J18: =SUM(OT!$D$18:$AH$18) | L18: =K18+F18 | M18: =L18-J18 | N18: =SUM(시간!$D$102:$AH$102) | O18: =SUMPRODUCT((시간!$D$3:$AH$3=1)*(시간!$D$46:$AH$46))+SUMPRODUCT((시간!$D$3:$AH$3=1)*(OT!$D$18:$AH$18)) | P18: =SUMPRODUCT((시간!$D$3:$AH$3=2)*(시간!$D$46:$AH$46))+SUMPRODUCT((시간!$D$3:$AH$3=2)*(OT!$D$18:$AH$18)) | Q18: =SUMPRODUCT((시간!$D$3:$AH$3=3)*(시간!$D$46:$AH$46))+SUMPRODUCT((시간!$D$3:$AH$3=3)*(OT!$D$18:$AH$18)) | R18: =SUMPRODUCT((시간!$D$3:$AH$3=4)*(시간!$D$46:$AH$46))+SUMPRODUCT((시간!$D$3:$AH$3=4)*(OT!$D$18:$AH$18)) | S18: =SUMPRODUCT((시간!$D$3:$AH$3=5)*(시간!$D$46:$AH$46))+SUMPRODUCT((시간!$D$3:$AH$3=5)*(OT!$D$18:$AH$18)) | T18: =SUMPRODUCT((시간!$D$3:$AH$3=6)*(시간!$D$46:$AH$46))+SUMPRODUCT((시간!$D$3:$AH$3=6)*(OT!$D$18:$AH$18)) | U18: =MAX(O18:T18) | V18: =IF(U18>64,"초과","적합")
A19: =IF(명부!A13="","",명부!A13) | B19: =IF(명부!C13="","",명부!C13) | C19: =IF(명부!E13="","",명부!E13) | D19: =SUMPRODUCT((시간!$D$4:$AH$4<>"")*(시간!$D$6:$AH$6="")) | E19: =D19*8 | F19: =SUM(시간!$D$75:$AH$75) | G19: =E19-F19 | H19: =SUM(시간!$D$47:$AH$47) | I19: =H19-G19 | J19: =SUM(OT!$D$19:$AH$19) | L19: =K19+F19 | M19: =L19-J19 | N19: =SUM(시간!$D$103:$AH$103) | O19: =SUMPRODUCT((시간!$D$3:$AH$3=1)*(시간!$D$47:$AH$47))+SUMPRODUCT((시간!$D$3:$AH$3=1)*(OT!$D$19:$AH$19)) | P19: =SUMPRODUCT((시간!$D$3:$AH$3=2)*(시간!$D$47:$AH$47))+SUMPRODUCT((시간!$D$3:$AH$3=2)*(OT!$D$19:$AH$19)) | Q19: =SUMPRODUCT((시간!$D$3:$AH$3=3)*(시간!$D$47:$AH$47))+SUMPRODUCT((시간!$D$3:$AH$3=3)*(OT!$D$19:$AH$19)) | R19: =SUMPRODUCT((시간!$D$3:$AH$3=4)*(시간!$D$47:$AH$47))+SUMPRODUCT((시간!$D$3:$AH$3=4)*(OT!$D$19:$AH$19)) | S19: =SUMPRODUCT((시간!$D$3:$AH$3=5)*(시간!$D$47:$AH$47))+SUMPRODUCT((시간!$D$3:$AH$3=5)*(OT!$D$19:$AH$19)) | T19: =SUMPRODUCT((시간!$D$3:$AH$3=6)*(시간!$D$47:$AH$47))+SUMPRODUCT((시간!$D$3:$AH$3=6)*(OT!$D$19:$AH$19)) | U19: =MAX(O19:T19) | V19: =IF(U19>64,"초과","적합")
A20: =IF(명부!A14="","",명부!A14) | B20: =IF(명부!C14="","",명부!C14) | C20: =IF(명부!E14="","",명부!E14) | D20: =SUMPRODUCT((시간!$D$4:$AH$4<>"")*(시간!$D$6:$AH$6="")) | E20: =D20*8 | F20: =SUM(시간!$D$76:$AH$76) | G20: =E20-F20 | H20: =SUM(시간!$D$48:$AH$48) | I20: =H20-G20 | J20: =SUM(OT!$D$20:$AH$20) | L20: =K20+F20 | M20: =L20-J20 | N20: =SUM(시간!$D$104:$AH$104) | O20: =SUMPRODUCT((시간!$D$3:$AH$3=1)*(시간!$D$48:$AH$48))+SUMPRODUCT((시간!$D$3:$AH$3=1)*(OT!$D$20:$AH$20)) | P20: =SUMPRODUCT((시간!$D$3:$AH$3=2)*(시간!$D$48:$AH$48))+SUMPRODUCT((시간!$D$3:$AH$3=2)*(OT!$D$20:$AH$20)) | Q20: =SUMPRODUCT((시간!$D$3:$AH$3=3)*(시간!$D$48:$AH$48))+SUMPRODUCT((시간!$D$3:$AH$3=3)*(OT!$D$20:$AH$20)) | R20: =SUMPRODUCT((시간!$D$3:$AH$3=4)*(시간!$D$48:$AH$48))+SUMPRODUCT((시간!$D$3:$AH$3=4)*(OT!$D$20:$AH$20)) | S20: =SUMPRODUCT((시간!$D$3:$AH$3=5)*(시간!$D$48:$AH$48))+SUMPRODUCT((시간!$D$3:$AH$3=5)*(OT!$D$20:$AH$20)) | T20: =SUMPRODUCT((시간!$D$3:$AH$3=6)*(시간!$D$48:$AH$48))+SUMPRODUCT((시간!$D$3:$AH$3=6)*(OT!$D$20:$AH$20)) | U20: =MAX(O20:T20) | V20: =IF(U20>64,"초과","적합")
A21: =IF(명부!A15="","",명부!A15) | B21: =IF(명부!C15="","",명부!C15) | C21: =IF(명부!E15="","",명부!E15) | D21: =SUMPRODUCT((시간!$D$4:$AH$4<>"")*(시간!$D$6:$AH$6="")) | E21: =D21*8 | F21: =SUM(시간!$D$77:$AH$77) | G21: =E21-F21 | H21: =SUM(시간!$D$49:$AH$49) | I21: =H21-G21 | J21: =SUM(OT!$D$21:$AH$21) | L21: =K21+F21 | M21: =L21-J21 | N21: =SUM(시간!$D$105:$AH$105) | O21: =SUMPRODUCT((시간!$D$3:$AH$3=1)*(시간!$D$49:$AH$49))+SUMPRODUCT((시간!$D$3:$AH$3=1)*(OT!$D$21:$AH$21)) | P21: =SUMPRODUCT((시간!$D$3:$AH$3=2)*(시간!$D$49:$AH$49))+SUMPRODUCT((시간!$D$3:$AH$3=2)*(OT!$D$21:$AH$21)) | Q21: =SUMPRODUCT((시간!$D$3:$AH$3=3)*(시간!$D$49:$AH$49))+SUMPRODUCT((시간!$D$3:$AH$3=3)*(OT!$D$21:$AH$21)) | R21: =SUMPRODUCT((시간!$D$3:$AH$3=4)*(시간!$D$49:$AH$49))+SUMPRODUCT((시간!$D$3:$AH$3=4)*(OT!$D$21:$AH$21)) | S21: =SUMPRODUCT((시간!$D$3:$AH$3=5)*(시간!$D$49:$AH$49))+SUMPRODUCT((시간!$D$3:$AH$3=5)*(OT!$D$21:$AH$21)) | T21: =SUMPRODUCT((시간!$D$3:$AH$3=6)*(시간!$D$49:$AH$49))+SUMPRODUCT((시간!$D$3:$AH$3=6)*(OT!$D$21:$AH$21)) | U21: =MAX(O21:T21) | V21: =IF(U21>64,"초과","적합")
A22: =IF(명부!A16="","",명부!A16) | B22: =IF(명부!C16="","",명부!C16) | C22: =IF(명부!E16="","",명부!E16) | D22: =SUMPRODUCT((시간!$D$4:$AH$4<>"")*(시간!$D$6:$AH$6="")) | E22: =D22*8 | F22: =SUM(시간!$D$78:$AH$78) | G22: =E22-F22 | H22: =SUM(시간!$D$50:$AH$50) | I22: =H22-G22 | J22: =SUM(OT!$D$22:$AH$22) | L22: =K22+F22 | M22: =L22-J22 | N22: =SUM(시간!$D$106:$AH$106) | O22: =SUMPRODUCT((시간!$D$3:$AH$3=1)*(시간!$D$50:$AH$50))+SUMPRODUCT((시간!$D$3:$AH$3=1)*(OT!$D$22:$AH$22)) | P22: =SUMPRODUCT((시간!$D$3:$AH$3=2)*(시간!$D$50:$AH$50))+SUMPRODUCT((시간!$D$3:$AH$3=2)*(OT!$D$22:$AH$22)) | Q22: =SUMPRODUCT((시간!$D$3:$AH$3=3)*(시간!$D$50:$AH$50))+SUMPRODUCT((시간!$D$3:$AH$3=3)*(OT!$D$22:$AH$22)) | R22: =SUMPRODUCT((시간!$D$3:$AH$3=4)*(시간!$D$50:$AH$50))+SUMPRODUCT((시간!$D$3:$AH$3=4)*(OT!$D$22:$AH$22)) | S22: =SUMPRODUCT((시간!$D$3:$AH$3=5)*(시간!$D$50:$AH$50))+SUMPRODUCT((시간!$D$3:$AH$3=5)*(OT!$D$22:$AH$22)) | T22: =SUMPRODUCT((시간!$D$3:$AH$3=6)*(시간!$D$50:$AH$50))+SUMPRODUCT((시간!$D$3:$AH$3=6)*(OT!$D$22:$AH$22)) | U22: =MAX(O22:T22) | V22: =IF(U22>64,"초과","적합")
A23: =IF(명부!A17="","",명부!A17) | B23: =IF(명부!C17="","",명부!C17) | C23: =IF(명부!E17="","",명부!E17) | D23: =SUMPRODUCT((시간!$D$4:$AH$4<>"")*(시간!$D$6:$AH$6="")) | E23: =D23*8 | F23: =SUM(시간!$D$79:$AH$79) | G23: =E23-F23 | H23: =SUM(시간!$D$51:$AH$51) | I23: =H23-G23 | J23: =SUM(OT!$D$23:$AH$23) | L23: =K23+F23 | M23: =L23-J23 | N23: =SUM(시간!$D$107:$AH$107) | O23: =SUMPRODUCT((시간!$D$3:$AH$3=1)*(시간!$D$51:$AH$51))+SUMPRODUCT((시간!$D$3:$AH$3=1)*(OT!$D$23:$AH$23)) | P23: =SUMPRODUCT((시간!$D$3:$AH$3=2)*(시간!$D$51:$AH$51))+SUMPRODUCT((시간!$D$3:$AH$3=2)*(OT!$D$23:$AH$23)) | Q23: =SUMPRODUCT((시간!$D$3:$AH$3=3)*(시간!$D$51:$AH$51))+SUMPRODUCT((시간!$D$3:$AH$3=3)*(OT!$D$23:$AH$23)) | R23: =SUMPRODUCT((시간!$D$3:$AH$3=4)*(시간!$D$51:$AH$51))+SUMPRODUCT((시간!$D$3:$AH$3=4)*(OT!$D$23:$AH$23)) | S23: =SUMPRODUCT((시간!$D$3:$AH$3=5)*(시간!$D$51:$AH$51))+SUMPRODUCT((시간!$D$3:$AH$3=5)*(OT!$D$23:$AH$23)) | T23: =SUMPRODUCT((시간!$D$3:$AH$3=6)*(시간!$D$51:$AH$51))+SUMPRODUCT((시간!$D$3:$AH$3=6)*(OT!$D$23:$AH$23)) | U23: =MAX(O23:T23) | V23: =IF(U23>64,"초과","적합")
A24: =IF(명부!A18="","",명부!A18) | B24: =IF(명부!C18="","",명부!C18) | C24: =IF(명부!E18="","",명부!E18) | D24: =SUMPRODUCT((시간!$D$4:$AH$4<>"")*(시간!$D$6:$AH$6="")) | E24: =D24*8 | F24: =SUM(시간!$D$80:$AH$80) | G24: =E24-F24 | H24: =SUM(시간!$D$52:$AH$52) | I24: =H24-G24 | J24: =SUM(OT!$D$24:$AH$24) | L24: =K24+F24 | M24: =L24-J24 | N24: =SUM(시간!$D$108:$AH$108) | O24: =SUMPRODUCT((시간!$D$3:$AH$3=1)*(시간!$D$52:$AH$52))+SUMPRODUCT((시간!$D$3:$AH$3=1)*(OT!$D$24:$AH$24)) | P24: =SUMPRODUCT((시간!$D$3:$AH$3=2)*(시간!$D$52:$AH$52))+SUMPRODUCT((시간!$D$3:$AH$3=2)*(OT!$D$24:$AH$24)) | Q24: =SUMPRODUCT((시간!$D$3:$AH$3=3)*(시간!$D$52:$AH$52))+SUMPRODUCT((시간!$D$3:$AH$3=3)*(OT!$D$24:$AH$24)) | R24: =SUMPRODUCT((시간!$D$3:$AH$3=4)*(시간!$D$52:$AH$52))+SUMPRODUCT((시간!$D$3:$AH$3=4)*(OT!$D$24:$AH$24)) | S24: =SUMPRODUCT((시간!$D$3:$AH$3=5)*(시간!$D$52:$AH$52))+SUMPRODUCT((시간!$D$3:$AH$3=5)*(OT!$D$24:$AH$24)) | T24: =SUMPRODUCT((시간!$D$3:$AH$3=6)*(시간!$D$52:$AH$52))+SUMPRODUCT((시간!$D$3:$AH$3=6)*(OT!$D$24:$AH$24)) | U24: =MAX(O24:T24) | V24: =IF(U24>64,"초과","적합")
A25: =IF(명부!A19="","",명부!A19) | B25: =IF(명부!C19="","",명부!C19) | C25: =IF(명부!E19="","",명부!E19) | D25: =SUMPRODUCT((시간!$D$4:$AH$4<>"")*(시간!$D$6:$AH$6="")) | E25: =D25*8 | F25: =SUM(시간!$D$81:$AH$81) | G25: =E25-F25 | H25: =SUM(시간!$D$53:$AH$53) | I25: =H25-G25 | J25: =SUM(OT!$D$25:$AH$25) | L25: =K25+F25 | M25: =L25-J25 | N25: =SUM(시간!$D$109:$AH$109) | O25: =SUMPRODUCT((시간!$D$3:$AH$3=1)*(시간!$D$53:$AH$53))+SUMPRODUCT((시간!$D$3:$AH$3=1)*(OT!$D$25:$AH$25)) | P25: =SUMPRODUCT((시간!$D$3:$AH$3=2)*(시간!$D$53:$AH$53))+SUMPRODUCT((시간!$D$3:$AH$3=2)*(OT!$D$25:$AH$25)) | Q25: =SUMPRODUCT((시간!$D$3:$AH$3=3)*(시간!$D$53:$AH$53))+SUMPRODUCT((시간!$D$3:$AH$3=3)*(OT!$D$25:$AH$25)) | R25: =SUMPRODUCT((시간!$D$3:$AH$3=4)*(시간!$D$53:$AH$53))+SUMPRODUCT((시간!$D$3:$AH$3=4)*(OT!$D$25:$AH$25)) | S25: =SUMPRODUCT((시간!$D$3:$AH$3=5)*(시간!$D$53:$AH$53))+SUMPRODUCT((시간!$D$3:$AH$3=5)*(OT!$D$25:$AH$25)) | T25: =SUMPRODUCT((시간!$D$3:$AH$3=6)*(시간!$D$53:$AH$53))+SUMPRODUCT((시간!$D$3:$AH$3=6)*(OT!$D$25:$AH$25)) | U25: =MAX(O25:T25) | V25: =IF(U25>64,"초과","적합")
A26: =IF(명부!A20="","",명부!A20) | B26: =IF(명부!C20="","",명부!C20) | C26: =IF(명부!E20="","",명부!E20) | D26: =SUMPRODUCT((시간!$D$4:$AH$4<>"")*(시간!$D$6:$AH$6="")) | E26: =D26*8 | F26: =SUM(시간!$D$82:$AH$82) | G26: =E26-F26 | H26: =SUM(시간!$D$54:$AH$54) | I26: =H26-G26 | J26: =SUM(OT!$D$26:$AH$26) | L26: =K26+F26 | M26: =L26-J26 | N26: =SUM(시간!$D$110:$AH$110) | O26: =SUMPRODUCT((시간!$D$3:$AH$3=1)*(시간!$D$54:$AH$54))+SUMPRODUCT((시간!$D$3:$AH$3=1)*(OT!$D$26:$AH$26)) | P26: =SUMPRODUCT((시간!$D$3:$AH$3=2)*(시간!$D$54:$AH$54))+SUMPRODUCT((시간!$D$3:$AH$3=2)*(OT!$D$26:$AH$26)) | Q26: =SUMPRODUCT((시간!$D$3:$AH$3=3)*(시간!$D$54:$AH$54))+SUMPRODUCT((시간!$D$3:$AH$3=3)*(OT!$D$26:$AH$26)) | R26: =SUMPRODUCT((시간!$D$3:$AH$3=4)*(시간!$D$54:$AH$54))+SUMPRODUCT((시간!$D$3:$AH$3=4)*(OT!$D$26:$AH$26)) | S26: =SUMPRODUCT((시간!$D$3:$AH$3=5)*(시간!$D$54:$AH$54))+SUMPRODUCT((시간!$D$3:$AH$3=5)*(OT!$D$26:$AH$26)) | T26: =SUMPRODUCT((시간!$D$3:$AH$3=6)*(시간!$D$54:$AH$54))+SUMPRODUCT((시간!$D$3:$AH$3=6)*(OT!$D$26:$AH$26)) | U26: =MAX(O26:T26) | V26: =IF(U26>64,"초과","적합")
A27: =IF(명부!A21="","",명부!A21) | B27: =IF(명부!C21="","",명부!C21) | C27: =IF(명부!E21="","",명부!E21) | D27: =SUMPRODUCT((시간!$D$4:$AH$4<>"")*(시간!$D$6:$AH$6="")) | E27: =D27*8 | F27: =SUM(시간!$D$83:$AH$83) | G27: =E27-F27 | H27: =SUM(시간!$D$55:$AH$55) | I27: =H27-G27 | J27: =SUM(OT!$D$27:$AH$27) | L27: =K27+F27 | M27: =L27-J27 | N27: =SUM(시간!$D$111:$AH$111) | O27: =SUMPRODUCT((시간!$D$3:$AH$3=1)*(시간!$D$55:$AH$55))+SUMPRODUCT((시간!$D$3:$AH$3=1)*(OT!$D$27:$AH$27)) | P27: =SUMPRODUCT((시간!$D$3:$AH$3=2)*(시간!$D$55:$AH$55))+SUMPRODUCT((시간!$D$3:$AH$3=2)*(OT!$D$27:$AH$27)) | Q27: =SUMPRODUCT((시간!$D$3:$AH$3=3)*(시간!$D$55:$AH$55))+SUMPRODUCT((시간!$D$3:$AH$3=3)*(OT!$D$27:$AH$27)) | R27: =SUMPRODUCT((시간!$D$3:$AH$3=4)*(시간!$D$55:$AH$55))+SUMPRODUCT((시간!$D$3:$AH$3=4)*(OT!$D$27:$AH$27)) | S27: =SUMPRODUCT((시간!$D$3:$AH$3=5)*(시간!$D$55:$AH$55))+SUMPRODUCT((시간!$D$3:$AH$3=5)*(OT!$D$27:$AH$27)) | T27: =SUMPRODUCT((시간!$D$3:$AH$3=6)*(시간!$D$55:$AH$55))+SUMPRODUCT((시간!$D$3:$AH$3=6)*(OT!$D$27:$AH$27)) | U27: =MAX(O27:T27) | V27: =IF(U27>64,"초과","적합")
A28: =IF(명부!A22="","",명부!A22) | B28: =IF(명부!C22="","",명부!C22) | C28: =IF(명부!E22="","",명부!E22) | D28: =SUMPRODUCT((시간!$D$4:$AH$4<>"")*(시간!$D$6:$AH$6="")) | E28: =D28*8 | F28: =SUM(시간!$D$84:$AH$84) | G28: =E28-F28 | H28: =SUM(시간!$D$56:$AH$56) | I28: =H28-G28 | J28: =SUM(OT!$D$28:$AH$28) | L28: =K28+F28 | M28: =L28-J28 | N28: =SUM(시간!$D$112:$AH$112) | O28: =SUMPRODUCT((시간!$D$3:$AH$3=1)*(시간!$D$56:$AH$56))+SUMPRODUCT((시간!$D$3:$AH$3=1)*(OT!$D$28:$AH$28)) | P28: =SUMPRODUCT((시간!$D$3:$AH$3=2)*(시간!$D$56:$AH$56))+SUMPRODUCT((시간!$D$3:$AH$3=2)*(OT!$D$28:$AH$28)) | Q28: =SUMPRODUCT((시간!$D$3:$AH$3=3)*(시간!$D$56:$AH$56))+SUMPRODUCT((시간!$D$3:$AH$3=3)*(OT!$D$28:$AH$28)) | R28: =SUMPRODUCT((시간!$D$3:$AH$3=4)*(시간!$D$56:$AH$56))+SUMPRODUCT((시간!$D$3:$AH$3=4)*(OT!$D$28:$AH$28)) | S28: =SUMPRODUCT((시간!$D$3:$AH$3=5)*(시간!$D$56:$AH$56))+SUMPRODUCT((시간!$D$3:$AH$3=5)*(OT!$D$28:$AH$28)) | T28: =SUMPRODUCT((시간!$D$3:$AH$3=6)*(시간!$D$56:$AH$56))+SUMPRODUCT((시간!$D$3:$AH$3=6)*(OT!$D$28:$AH$28)) | U28: =MAX(O28:T28) | V28: =IF(U28>64,"초과","적합")
A29: =IF(명부!A23="","",명부!A23) | B29: =IF(명부!C23="","",명부!C23) | C29: =IF(명부!E23="","",명부!E23) | D29: =SUMPRODUCT((시간!$D$4:$AH$4<>"")*(시간!$D$6:$AH$6="")) | E29: =D29*8 | F29: =SUM(시간!$D$85:$AH$85) | G29: =E29-F29 | H29: =SUM(시간!$D$57:$AH$57) | I29: =H29-G29 | J29: =SUM(OT!$D$29:$AH$29) | L29: =K29+F29 | M29: =L29-J29 | N29: =SUM(시간!$D$113:$AH$113) | O29: =SUMPRODUCT((시간!$D$3:$AH$3=1)*(시간!$D$57:$AH$57))+SUMPRODUCT((시간!$D$3:$AH$3=1)*(OT!$D$29:$AH$29)) | P29: =SUMPRODUCT((시간!$D$3:$AH$3=2)*(시간!$D$57:$AH$57))+SUMPRODUCT((시간!$D$3:$AH$3=2)*(OT!$D$29:$AH$29)) | Q29: =SUMPRODUCT((시간!$D$3:$AH$3=3)*(시간!$D$57:$AH$57))+SUMPRODUCT((시간!$D$3:$AH$3=3)*(OT!$D$29:$AH$29)) | R29: =SUMPRODUCT((시간!$D$3:$AH$3=4)*(시간!$D$57:$AH$57))+SUMPRODUCT((시간!$D$3:$AH$3=4)*(OT!$D$29:$AH$29)) | S29: =SUMPRODUCT((시간!$D$3:$AH$3=5)*(시간!$D$57:$AH$57))+SUMPRODUCT((시간!$D$3:$AH$3=5)*(OT!$D$29:$AH$29)) | T29: =SUMPRODUCT((시간!$D$3:$AH$3=6)*(시간!$D$57:$AH$57))+SUMPRODUCT((시간!$D$3:$AH$3=6)*(OT!$D$29:$AH$29)) | U29: =MAX(O29:T29) | V29: =IF(U29>64,"초과","적합")
A30: =IF(명부!A24="","",명부!A24) | B30: =IF(명부!C24="","",명부!C24) | C30: =IF(명부!E24="","",명부!E24) | D30: =SUMPRODUCT((시간!$D$4:$AH$4<>"")*(시간!$D$6:$AH$6="")) | E30: =D30*8 | F30: =SUM(시간!$D$86:$AH$86) | G30: =E30-F30 | H30: =SUM(시간!$D$58:$AH$58) | I30: =H30-G30 | J30: =SUM(OT!$D$30:$AH$30) | L30: =K30+F30 | M30: =L30-J30 | N30: =SUM(시간!$D$114:$AH$114) | O30: =SUMPRODUCT((시간!$D$3:$AH$3=1)*(시간!$D$58:$AH$58))+SUMPRODUCT((시간!$D$3:$AH$3=1)*(OT!$D$30:$AH$30)) | P30: =SUMPRODUCT((시간!$D$3:$AH$3=2)*(시간!$D$58:$AH$58))+SUMPRODUCT((시간!$D$3:$AH$3=2)*(OT!$D$30:$AH$30)) | Q30: =SUMPRODUCT((시간!$D$3:$AH$3=3)*(시간!$D$58:$AH$58))+SUMPRODUCT((시간!$D$3:$AH$3=3)*(OT!$D$30:$AH$30)) | R30: =SUMPRODUCT((시간!$D$3:$AH$3=4)*(시간!$D$58:$AH$58))+SUMPRODUCT((시간!$D$3:$AH$3=4)*(OT!$D$30:$AH$30)) | S30: =SUMPRODUCT((시간!$D$3:$AH$3=5)*(시간!$D$58:$AH$58))+SUMPRODUCT((시간!$D$3:$AH$3=5)*(OT!$D$30:$AH$30)) | T30: =SUMPRODUCT((시간!$D$3:$AH$3=6)*(시간!$D$58:$AH$58))+SUMPRODUCT((시간!$D$3:$AH$3=6)*(OT!$D$30:$AH$30)) | U30: =MAX(O30:T30) | V30: =IF(U30>64,"초과","적합")
A31: =IF(명부!A25="","",명부!A25) | B31: =IF(명부!C25="","",명부!C25) | C31: =IF(명부!E25="","",명부!E25) | D31: =SUMPRODUCT((시간!$D$4:$AH$4<>"")*(시간!$D$6:$AH$6="")) | E31: =D31*8 | F31: =SUM(시간!$D$87:$AH$87) | G31: =E31-F31 | H31: =SUM(시간!$D$59:$AH$59) | I31: =H31-G31 | J31: =SUM(OT!$D$31:$AH$31) | L31: =K31+F31 | M31: =L31-J31 | N31: =SUM(시간!$D$115:$AH$115) | O31: =SUMPRODUCT((시간!$D$3:$AH$3=1)*(시간!$D$59:$AH$59))+SUMPRODUCT((시간!$D$3:$AH$3=1)*(OT!$D$31:$AH$31)) | P31: =SUMPRODUCT((시간!$D$3:$AH$3=2)*(시간!$D$59:$AH$59))+SUMPRODUCT((시간!$D$3:$AH$3=2)*(OT!$D$31:$AH$31)) | Q31: =SUMPRODUCT((시간!$D$3:$AH$3=3)*(시간!$D$59:$AH$59))+SUMPRODUCT((시간!$D$3:$AH$3=3)*(OT!$D$31:$AH$31)) | R31: =SUMPRODUCT((시간!$D$3:$AH$3=4)*(시간!$D$59:$AH$59))+SUMPRODUCT((시간!$D$3:$AH$3=4)*(OT!$D$31:$AH$31)) | S31: =SUMPRODUCT((시간!$D$3:$AH$3=5)*(시간!$D$59:$AH$59))+SUMPRODUCT((시간!$D$3:$AH$3=5)*(OT!$D$31:$AH$31)) | T31: =SUMPRODUCT((시간!$D$3:$AH$3=6)*(시간!$D$59:$AH$59))+SUMPRODUCT((시간!$D$3:$AH$3=6)*(OT!$D$31:$AH$31)) | U31: =MAX(O31:T31) | V31: =IF(U31>64,"초과","적합")
A34: 주별 근로시간은 정규 + OT 이고 64시간을 넘으면 빨갛게 표시됩니다. 탄력근무 3개월 평균 52시간 판정은 달을 넘겨야 하므로 index.html 의 「탄력근무 52/64」 탭에서 확인하세요.

Sheet 명부
A1: 이름 | B1: 팀 | C1: 파트 | D1: 직책 | E1: 그룹 | F1: 휴직
A2: 김동환 | B2: 발전운영팀 | C2: 발전팀장 | D2: 팀장 | E2: A
A3: 고재민 | B3: 정비기술팀 | C3: 정비팀장 | D3: 팀장 | E3: A
A4: 임태균 | B4: 발전운영팀 | C4: 발전지원 | D4: 파트장 | E4: A
A5: 정병철 | B5: 정비기술팀 | C5: 기계 | D5: 파트장 | E5: A
A6: 민준홍 | B6: 정비기술팀 | C6: 전기 | D6: 파트장 | E6: A
A7: 한승백 | B7: 정비기술팀 | C7: 제어 | D7: 파트장 | E7: A
A8: 박상호 | B8: 정비기술팀 | C8: 기계 | D8: 구성원 | E8: B
A9: 최규석 | B9: 정비기술팀 | C9: 기계 | D9: 구성원 | E9: B
A10: 김성진 | B10: 정비기술팀 | C10: 기계 | D10: 구성원 | E10: B
A11: 윤병권 | B11: 정비기술팀 | C11: 기계 | D11: 구성원 | E11: B
A12: 정상우 | B12: 정비기술팀 | C12: 기계 | D12: 구성원 | E12: B
A13: 김형준 | B13: 정비기술팀 | C13: 전기 | D13: 구성원 | E13: B
... A21: 정소망 | B21: 정비기술팀 | C21: 정비지원 | D21: 구성원 | E21: B
A22: 윤승현 | B22: 정비기술팀 | C22: 정비지원 | D22: 구성원 | E22: B | F22: Y
A23: 양시웅 | B23: 발전운영팀 | C23: 발전지원 | D23: 구성원 | E23: C
A24: 한준우 | B24: 발전운영팀 | C24: 발전지원 | D24: 구성원 | E24: C
A25: 권민중 | B25: 발전운영팀 | C25: 발전지원 | D25: 구성원 | E25: C
A27: 활성 인원 | B27: =COUNTA(A2:A25)-COUNTIF(F2:F25,"Y")
A28: 30% 필요 인원 | B28: =ROUNDUP(B27*0.3,0)
A30: 휴직 열에 Y 를 넣으면 30% 모수에서 빠집니다. 순서를 바꾸면 다른 시트의 이름도 함께 바뀝니다.

Sheet 공휴일
A1: 날짜 | B1: 명칭
A2: 2026-01-01 | B2: 신정
A3: 2026-02-16 | B3: 설날 연휴
A4: 2026-02-17 | B4: 설날
A5: 2026-02-18 | B5: 설날 연휴
A6: 2026-03-01 | B6: 삼일절
A7: 2026-03-02 | B7: 삼일절 대체공휴일
A8: 2026-05-01 | B8: 근로자의 날
A9: 2026-05-05 | B9: 어린이날
A10: 2026-05-24 | B10: 부처님오신날
A11: 2026-05-25 | B11: 부처님오신날 대체공휴일
A12: 2026-06-06 | B12: 현충일
... A22: 2026-12-25 | B22: 성탄절
A24: 날짜는 반드시 날짜 형식(2027-01-01)으로 넣으세요. 설날·추석·부처님오신날은 음력이라 매년 확인이 필요합니다. 사내 휴무일도 여기에 추가하세요.

Sheet 코드
A1: 코드 | B1: 유형 | C1: 근무 시각 | D1: 실근로(h) | E1: 휴가(h) | F1: 30%충족 | G1: 휴가 블록 | H1: 구분 | J1: 30% 충족 코드 | K1: 조율 가능 코드 | M1: 요일 | O1: 유형 | P1: 출근 | Q1: 퇴근
A2: 근무 0730-1630 | B2: 근무 | C2: 07:30~16:30 | D2: 8 | E2: 0 | F2: 1 | H2: 근무 | J2: 근무 0730-1630 | K2: 오후반 0730-1200 | M2: 일 | O2: 근무 | P2: 07:30 | Q2: 11:30
A3: 근무 0800-1700 | B3: 근무 | C3: 08:00~17:00 | D3: 8 | E3: 0 | F3: 1 | H3: 근무 | J3: 근무 0800-1700 | K3: 오후반 0730-1300 | M3: 월 | O3: 오전반 | P3: 08:00 | Q3: 12:00
A4: 근무 0830-1730 | B4: 근무 | C4: 08:30~17:30 | D4: 8 | E4: 0 | F4: 1 | H4: 근무 | J4: 근무 0830-1730 | K4: 오후반 0800-1200 | M4: 화 | O4: 오후반 | P4: 08:30 | Q4: 13:00
A5: 연차 | B5: 연차 | D5: 0 | E5: 8 | F5: 0 | H5: 휴가·사외 | J5: 근무 0730-1700 | K5: 오후반 0800-1300 | M5: 수 | O5: 오전반반 | P5: 10:30 | Q5: 13:30
A6: 출장 | B6: 출장 | D6: 8 | E6: 0 | F6: 0 | H6: 휴가·사외 | J6: 근무 0730-1730 | K6: 오후반 0800-1330 | M6: 목 | O6: 오후반반 | P6: 13:00 | Q6: 14:00
A7: 교육 | B7: 교육 | D7: 8 | E7: 0 | F7: 0 | H7: 휴가·사외 | J7: 근무 0730-1800 | K7: 오후반 0830-1200 | M7: 금 | O7: 검진 | P7: 13:30 | Q7: 14:30
A8: 기타 | B8: 기타 | D8: 8 | E8: 0 | F8: 0 | H8: 휴가·사외 | J8: 근무 0730-1830 | K8: 오후반 0830-1300 | M8: 토 | O8: 연차 | Q8: 15:00
A9: 오후반 0730-1200 | B9: 오후반 | C9: 07:30~12:00 | D9: 4.5 | E9: 4 | F9: 0 | G9: 12:00~17:00 | H9: 반차 | J9: 근무 0730-1900 | K9: 오후반 0830-1330 | O9: 출장 | Q9: 15:30
A10: 오후반 0730-1300 | B10: 오후반 | C10: 07:30~13:00 | D10: 4.5 | E10: 4 | F10: 0 | G10: 13:00~17:00 | H10: 반차 | J10: 근무 0730-1930 | K10: 오후반 0830-1400 | O10: 교육 | Q10: 16:00
A11: 오후반 0800-1200 | B11: 오후반 | C11: 08:00~12:00 | D11: 4 | E11: 4 | F11: 0 | G11: 12:00~17:00 | H11: 반차 | J11: 근무 0730-2000 | K11: 오전반 1300-1600 | O11: 기타 | Q11: 16:30
A12: 오후반 0800-1300 | B12: 오후반 | C12: 08:00~13:00 | D12: 4 | E12: 4 | F12: 0 | G12: 13:00~17:00 | H12: 반차 | J12: 근무 0730-2030 | K12: 오전반 1300-1630 | O12: 휴직 | Q12: 17:00
A13: 오후반 0800-1330 | B13: 오후반 | C13: 08:00~13:30 | D13: 4.5 | E13: 4 | F13: 0 | G13: 13:30~17:30 | H13: 반차 | J13: 근무 0800-1730 | K13: 오전반 1300-1700 | Q13: 17:30
A14: 오후반 0830-1200 | B14: 오후반 | C14: 08:30~12:00 | D14: 3.5 | E14: 4 | F14: 0 | G14: 12:00~17:00 | H14: 반차 | J14: 근무 0800-1800 | K14: 오전반 1300-1730 | Q14: 18:00
A15: 오후반 0830-1300 | B15: 오후반 | C15: 08:30~13:00 | D15: 3.5 | E15: 4 | F15: 0 | G15: 13:00~17:00 | H15: 반차 | J15: 근무 0800-1830 | K15: 오전반 1330-1630 | Q15: 18:30
A16: 오후반 0830-1330 | B16: 오후반 | C16: 08:30~13:30 | D16: 4 | E16: 4 | F16: 0 | G16: 13:30~17:30 | H16: 반차 | J16: 근무 0800-1900 | K16: 오전반 1330-1700 | Q16: 19:00
A17: 오후반 0830-1400 | B17: 오후반 | C17: 08:30~14:00 | D17: 4.5 | E17: 4 | F17: 0 | G17: 14:00~18:00 | H17: 반차 | J17: 근무 0800-1930 | K17: 오전반 1330-1730 | Q17: 19:30
A18: 오전반 1300-1600 | B18: 오전반 | C18: 13:00~16:00 | D18: 3 | E18: 4 | F18: 0 | G18: 08:00~13:00 | H18: 반차 | J18: 근무 0800-2000 | K18: 오전반 1330-1800 | Q18: 20:00
A19: 오전반 1300-1630 | B19: 오전반 | C19: 13:00~16:30 | D19: 3.5 | E19: 4 | F19: 0 | G19: 08:00~13:00 | H19: 반차 | J19: 근무 0800-2030 | K19: 오전반 1330-1830 | Q19: 20:30
A20: 오전반 1300-1700 | B20: 오전반 | C20: 13:00~17:00 | D20: 4 | E20: 4 | F20: 0 | G20: 08:00~13:00 | H20: 반차 | J20: 근무 0830-1800 | K20: 오후반반 0800-1530
A21: 오전반 1300-1730 | B21: 오전반 | C21: 13:00~17:30 | D21: 4.5 | E21: 4 | F21: 0 | G21: 08:00~13:00 | H21: 반차 | J21: 근무 0830-1830 | K21: 오후반반 0830-1530
A22: 오전반 1330-1630 | B22: 오전반 | C22: 13:30~16:30 | D22: 3 | E22: 4 | F22: 0 | G22: 08:30~13:30 | H22: 반차 | J22: 근무 0830-1900 | K22: 오전반반 1030-1430
A23: 오전반 1330-1700 | B23: 오전반 | C23: 13:30~17:00 | D23: 3.5 | E23: 4 | F23: 0 | G23: 08:30~13:30 | H23: 반차 | J23: 근무 0830-1930 | K23: 오전반반 1030-1500
A24: 오전반 1330-1730 | B24: 오전반 | C24: 13:30~17:30 | D24: 4 | E24: 4 | F24: 0 | G24: 08:30~13:30 | H24: 반차 | J24: 근무 0830-2000 | K24: 오전반반 1030-1530
A25: 오전반 1330-1800 | B25: 오전반 | C25: 13:30~18:00 | D25: 4.5 | E25: 4 | F25: 0 | G25: 08:30~13:30 | H25: 반차 | J25: 근무 0830-2030 | K25: 오전반반 1030-1600
A26: 오전반 1330-1830 | B26: 오전반 | C26: 13:30~18:30 | D26: 4.5 | E26: 4 | F26: 0 | G26: 08:30~13:30 | H26: 반차 | K26: 오전반반 1030-1630
A27: 오후반반 0800-1530 | B27: 오후반반 | C27: 08:00~15:30 | D27: 6.5 | E27: 2 | F27: 0 | G27: 15:30~17:30 | H27: 반반차 | K27: 오전반반 1030-1700
A28: 오후반반 0830-1530 | B28: 오후반반 | C28: 08:30~15:30 | D28: 6 | E28: 2 | F28: 0 | G28: 15:30~17:30 | H28: 반반차 | K28: 오전반반 1030-1730
A29: 오전반반 1030-1430 | B29: 오전반반 | C29: 10:30~14:30 | D29: 3 | E29: 2 | F29: 0 | G29: 08:30~10:30 | H29: 반반차 | K29: 오전반반 1030-1800
A30: 오전반반 1030-1500 | B30: 오전반반 | C30: 10:30~15:00 | D30: 3.5 | E30: 2 | F30: 0 | G30: 08:30~10:30 | H30: 반반차 | K30: 오전반반 1030-1830
A31: 오전반반 1030-1530 | B31: 오전반반 | C31: 10:30~15:30 | D31: 4 | E31: 2 | F31: 0 | G31: 08:30~10:30 | H31: 반반차 | K31: 근무 0730-1130
A32: 오전반반 1030-1600 | B32: 오전반반 | C32: 10:30~16:00 | D32: 4.5 | E32: 2 | F32: 0 | G32: 08:30~10:30 | H32: 반반차 | K32: 근무 0730-1200
A33: 오전반반 1030-1630 | B33: 오전반반 | C33: 10:30~16:30 | D33: 5 | E33: 2 | F33: 0 | G33: 08:30~10:30 | H33: 반반차 | K33: 근무 0730-1300
A34: 오전반반 1030-1700 | B34: 오전반반 | C34: 10:30~17:00 | D34: 5.5 | E34: 2 | F34: 0 | G34: 08:30~10:30 | H34: 반반차 | K34: 근무 0730-1330
A35: 오전반반 1030-1730 | B35: 오전반반 | C35: 10:30~17:30 | D35: 6 | E35: 2 | F35: 0 | G35: 08:30~10:30 | H35: 반반차 | K35: 근무 0730-1400
A36: 오전반반 1030-1800 | B36: 오전반반 | C36: 10:30~18:00 | D36: 6.5 | E36: 2 | F36: 0 | G36: 08:30~10:30 | H36: 반반차 | K36: 근무 0730-1430
A37: 오전반반 1030-1830 | B37: 오전반반 | C37: 10:30~18:30 | D37: 6.5 | E37: 2 | F37: 0 | G37: 08:30~10:30 | H37: 반반차 | K37: 근무 0730-1500
... A55: 검진 1330-1830 | B55: 검진 | C55: 13:30~18:30 | D55: 4.5 | E55: 4 | F55: 0 | G55: 08:30~13:30 | H55: 건강검진 | K55: 근무 0830-1430
A56: 근무 0730-1130 | B56: 근무 | C56: 07:30~11:30 | D56: 4 | E56: 0 | F56: 0 | H56: 근무 | K56: 근무 0830-1500
A57: 근무 0730-1200 | B57: 근무 | C57: 07:30~12:00 | D57: 4.5 | E57: 0 | F57: 0 | H57: 근무 | K57: 근무 0830-1530
...

Sheet 시간
D1: 시간 (계산용) — 근태 시트를 조합표와 대조한 값입니다
D2: 이 시트는 직접 고치지 마세요
A3: 주 | D3: =IF(D4="","",INT((D4-1+MOD(WEEKDAY(DATE(근태!$B$1,근태!$B$2,1))+5,7))/7)+1) | E3: =IF(E4="","",INT((E4-1+MOD(WEEKDAY(DATE(근태!$B$1,근태!$B$2,1))+5,7))/7)+1) | F3: =IF(F4="","",INT((F4-1+MOD(WEEKDAY(DATE(근태!$B$1,근태!$B$2,1))+5,7))/7)+1) | G3: =IF(G4="","",INT((G4-1+MOD(WEEKDAY(DATE(근태!$B$1,근태!$B$2,1))+5,7))/7)+1) | H3: =IF(H4="","",INT((H4-1+MOD(WEEKDAY(DATE(근태!$B$1,근태!$B$2,1))+5,7))/7)+1) | I3: =IF(I4="","",INT((I4-1+MOD(WEEKDAY(DATE(근태!$B$1,근태!$B$2,1))+5,7))/7)+1) | J3: =IF(J4="","",INT((J4-1+MOD(WEEKDAY(DATE(근태!$B$1,근태!$B$2,1))+5,7))/7)+1) | K3: =IF(K4="","",INT((K4-1+MOD(WEEKDAY(DATE(근태!$B$1,근태!$B$2,1))+5,7))/7)+1) | ... AH3: =IF(AH4="","",INT((AH4-1+MOD(WEEKDAY(DATE(근태!$B$1,근태!$B$2,1))+5,7))/7)+1)
