Workbook

Sheet 온도 Profile
B2: 위례열병합 Baseload Test ('26.04.15) | K2: 적용 대기압 | M2: =AVERAGE(Y8:Y12)-8 -> 1006.2 | P2: 2026-04-15 18:09:12
P3: Update time : | Q3: 17:00
B4: 외기온도 | C4: M3 | E4: M3ECO | G4: M5D25 | I4: M5D50 | K4: M5D75 | M4: M1 | P4: Pressure
C5: GT | D5: CC | E5: GT | F5: CC | G5: GT | H5: CC | I5: GT | J5: CC | K5: GT | L5: CC | M5: GT | N5: CC | P5: Local time | Q5: 0 | R5: 3 | S5: 6 | T5: 9 | U5: 12 | V5: 15 | W5: 18 | X5: 21 | Y5: 중위 | Z5: 최소
B6: -20 | C6: =Mode3!G5 -> 279.86992 | D6: =Mode3!H5 -> 433.50461 | E6: =Mode3!P5 -> 279.86992 | F6: =Mode3!Q5 -> 432.09382 | G6: =Mode5!AA5 -> 279.86992 | H6: =Mode5!AB5 -> 419.17917 | I6: =Mode5!Q5 -> 279.86992 | J6: =Mode5!R5 -> 401.73951 | K6: =Mode5!G5 -> 279.86992 | L6: =Mode5!H5 -> 383.8849 | M6: =Mode1!G5 -> 279.86992 | N6: =Mode1!H5 -> 364.99195 | P6: 수요일, 4월 15일 | Q6: 1010 | R6: 1009 | S6: 1010 | T6: 1010 | U6: 1010 | V6: 1009 | W6: 1009 | X6: 1011 | Y6: 1010 | Z6: 1009
B7: -19 | C7: =Mode3!G6 -> 280.56244 | D7: =Mode3!H6 -> 434.55871 | E7: =Mode3!P6 -> 280.56244 | F7: =Mode3!Q6 -> 433.1445 | G7: =Mode5!AA6 -> 280.56244 | H7: =Mode5!AB6 -> 420.18317 | I7: =Mode5!Q6 -> 280.56244 | J7: =Mode5!R6 -> 402.6825 | K7: =Mode5!G6 -> 280.56244 | L7: =Mode5!H6 -> 384.76543 | M7: =Mode1!G6 -> 280.56244 | N7: =Mode1!H6 -> 365.80639 | P7: 목요일, 4월 16일 | Q7: 1014 | R7: 1015 | S7: 1015 | T7: 1017 | U7: 1017 | V7: 1015 | W7: 1015 | X7: 1015 | Y7: 1015 | Z7: 1014
B8: -18 | C8: =Mode3!G7 -> 281.22581 | D8: =Mode3!H7 -> 435.56846 | E8: =Mode3!P7 -> 281.22581 | F8: =Mode3!Q7 -> 434.15096 | G8: =Mode5!AA7 -> 281.22581 | H8: =Mode5!AB7 -> 421.14419 | I8: =Mode5!Q7 -> 281.22581 | J8: =Mode5!R7 -> 403.58422 | K8: =Mode5!G7 -> 281.22581 | L8: =Mode5!H7 -> 385.60644 | M8: =Mode1!G7 -> 281.22581 | N8: =Mode1!H7 -> 366.58314 | P8: 금요일, 4월 17일 | Q8: 1014 | R8: 1013 | S8: 1013 | T8: 1013 | U8: 1013 | V8: 1012 | W8: 1013 | X8: 1014 | Y8: 1013 | Z8: 1012
B9: -17 | C9: =Mode3!G8 -> 281.8728 | D9: =Mode3!H8 -> 436.55326 | E9: =Mode3!P8 -> 281.8728 | F9: =Mode3!Q8 -> 435.13255 | G9: =Mode5!AA8 -> 281.8728 | H9: =Mode5!AB8 -> 422.08103 | I9: =Mode5!Q8 -> 281.8728 | J9: =Mode5!R8 -> 404.46267 | K9: =Mode5!G8 -> 281.8728 | L9: =Mode5!H8 -> 386.42511 | M9: =Mode1!G8 -> 281.8728 | N9: =Mode1!H8 -> 367.33856 | P9: 토요일, 4월 18일 | Q9: 1015 | R9: 1014 | S9: 1015 | T9: 1015 | U9: 1015 | V9: 1013 | W9: 1014 | X9: 1015 | Y9: 1015 | Z9: 1013
B10: -16 | C10: =Mode3!G9 -> 282.4622 | D10: =Mode3!H9 -> 437.45041 | E10: =Mode3!P9 -> 282.4622 | F10: =Mode3!Q9 -> 436.02678 | G10: =Mode5!AA9 -> 282.4622 | H10: =Mode5!AB9 -> 422.93306 | I10: =Mode5!Q9 -> 282.4622 | J10: =Mode5!R9 -> 405.25977 | K10: =Mode5!G9 -> 282.4622 | L10: =Mode5!H9 -> 387.16597 | M10: =Mode1!G9 -> 282.4622 | N10: =Mode1!H9 -> 368.01992 | P10: 일요일, 4월 19일 | Q10: 1015 | R10: 1015 | S10: 1015 | T10: 1016 | U10: 1015 | V10: 1014 | W10: 1013 | X10: 1014 | Y10: 1015 | Z10: 1013
B11: -15 | C11: =Mode3!G10 -> 283.00768 | D11: =Mode3!H10 -> 438.28071 | E11: =Mode3!P10 -> 283.00768 | F11: =Mode3!Q10 -> 436.85438 | G11: =Mode5!AA10 -> 283.00768 | H11: =Mode5!AB10 -> 423.72039 | I11: =Mode5!Q10 -> 283.00768 | J11: =Mode5!R10 -> 405.9948 | K11: =Mode5!G10 -> 283.00768 | L11: =Mode5!H10 -> 387.84745 | M11: =Mode1!G10 -> 283.00768 | N11: =Mode1!H10 -> 368.64474 | P11: 월요일, 4월 20일 | Q11: 1015 | R11: 1014 | S11: 1014 | T11: 1013 | U11: 1012 | V11: 1012 | W11: 1012 | X11: 1014 | Y11: 1014 | Z11: 1012
B12: -14 | C12: =Mode3!G11 -> 283.57676 | D12: =Mode3!H11 -> 439.14692 | E12: =Mode3!P11 -> 283.57676 | F12: =Mode3!Q11 -> 437.71777 | G12: =Mode5!AA11 -> 283.57676 | H12: =Mode5!AB11 -> 424.54239 | I12: =Mode5!Q11 -> 283.57676 | J12: =Mode5!R11 -> 406.76297 | K12: =Mode5!G11 -> 283.57676 | L12: =Mode5!H11 -> 388.56051 | M12: =Mode1!G11 -> 283.57676 | N12: =Mode1!H11 -> 369.29948 | P12: 화요일, 4월 21일 | Q12: 1015 | R12: 1014 | S12: 1015 | T12: 1015 | U12: 1014 | V12: 1013 | W12: 1014 | X12: 1016 | Y12: 1014 | Z12: 1013
B13: -13 | C13: =Mode3!G12 -> 284.07239 | D13: =Mode3!H12 -> 439.90133 | E13: =Mode3!P12 -> 284.07239 | F13: =Mode3!Q12 -> 438.46973 | G13: =Mode5!AA12 -> 284.07239 | H13: =Mode5!AB12 -> 425.25625 | I13: =Mode5!Q12 -> 284.07239 | J13: =Mode5!R12 -> 407.42746 | K13: =Mode5!G12 -> 284.07239 | L13: =Mode5!H12 -> 389.17446 | M13: =Mode1!G12 -> 284.07239 | N13: =Mode1!H12 -> 369.85994
B14: -12 | C14: =Mode3!G13 -> 284.45408 | D14: =Mode3!H13 -> 440.48232 | E14: =Mode3!P13 -> 284.45408 | F14: =Mode3!Q13 -> 439.04883 | G14: =Mode5!AA13 -> 284.45408 | H14: =Mode5!AB13 -> 425.80241 | I14: =Mode5!Q13 -> 284.45408 | J14: =Mode5!R13 -> 407.93122 | K14: =Mode5!G13 -> 284.45408 | L14: =Mode5!H13 -> 389.63481 | M14: =Mode1!G13 -> 284.45408 | N14: =Mode1!H13 -> 370.27436
B15: -11 | C15: =Mode3!G14 -> 284.95765 | D15: =Mode3!H14 -> 441.24882 | E15: =Mode3!P14 -> 284.95765 | F15: =Mode3!Q14 -> 439.81283 | G15: =Mode5!AA14 -> 284.95765 | H15: =Mode5!AB14 -> 426.52785 | I15: =Mode5!Q14 -> 284.95765 | J15: =Mode5!R14 -> 408.60667 | K15: =Mode5!G14 -> 284.95765 | L15: =Mode5!H14 -> 390.25909 | M15: =Mode1!G14 -> 284.95765 | N15: =Mode1!H14 -> 370.84449
B16: -10 | C16: =Mode3!G15 -> 285.42085 | D16: =Mode3!H15 -> 441.95388 | E16: =Mode3!P15 -> 285.42085 | F16: =Mode3!Q15 -> 440.51559 | G16: =Mode5!AA15 -> 285.42085 | H16: =Mode5!AB15 -> 427.17831 | I16: =Mode5!Q15 -> 285.42085 | J16: =Mode5!R15 -> 409.19066 | K16: =Mode5!G15 -> 285.42085 | L16: =Mode5!H15 -> 390.77503 | M16: =Mode1!G15 -> 285.42085 | N16: =Mode1!H15 -> 371.28842
B17: -9 | C17: =Mode3!G16 -> 285.84307 | D17: =Mode3!H16 -> 442.59655 | E17: =Mode3!P16 -> 285.84307 | F17: =Mode3!Q16 -> 441.15617 | G17: =Mode5!AA16 -> 285.84307 | H17: =Mode5!AB16 -> 427.78393 | I17: =Mode5!Q16 -> 285.84307 | J17: =Mode5!R16 -> 409.75118 | K17: =Mode5!G16 -> 285.84307 | L17: =Mode5!H16 -> 391.28938 | M17: =Mode1!G16 -> 285.84307 | N17: =Mode1!H16 -> 371.75391
B18: -8 | C18: =Mode3!G17 -> 286.22368 | D18: =Mode3!H17 -> 443.17588 | E18: =Mode3!P17 -> 286.22368 | F18: =Mode3!Q17 -> 441.73362 | G18: =Mode5!AA17 -> 286.22368 | H18: =Mode5!AB17 -> 428.3283 | I18: =Mode5!Q17 -> 286.22368 | J18: =Mode5!R17 -> 410.25298 | K18: =Mode5!G17 -> 286.22368 | L18: =Mode5!H17 -> 391.74759 | M18: =Mode1!G17 -> 286.22368 | N18: =Mode1!H17 -> 372.166
B19: -7 | C19: =Mode3!G18 -> 286.56206 | D19: =Mode3!H18 -> 443.69095 | E19: =Mode3!P18 -> 286.56206 | F19: =Mode3!Q18 -> 442.24701 | G19: =Mode5!AA18 -> 286.56206 | H19: =Mode5!AB18 -> 428.81051 | I19: =Mode5!Q18 -> 286.56206 | J19: =Mode5!R18 -> 410.69519 | K19: =Mode5!G18 -> 286.56206 | L19: =Mode5!H18 -> 392.14885 | M19: =Mode1!G18 -> 286.56206 | N19: =Mode1!H18 -> 372.52394
B20: -6 | C20: =Mode3!G19 -> 286.85762 | D20: =Mode3!H19 -> 444.14083 | E20: =Mode3!P19 -> 286.85762 | F20: =Mode3!Q19 -> 442.69543 | G20: =Mode5!AA19 -> 286.85762 | H20: =Mode5!AB19 -> 429.2453 | I20: =Mode5!Q19 -> 286.85762 | J20: =Mode5!R19 -> 411.11161 | K20: =Mode5!G19 -> 286.85762 | L20: =Mode5!H19 -> 392.54647 | M20: =Mode1!G19 -> 286.85762 | N20: =Mode1!H19 -> 372.90165
B21: -5 | C21: =Mode3!G20 -> 287.10974 | D21: =Mode3!H20 -> 444.52459 | E21: =Mode3!P20 -> 287.10974 | F21: =Mode3!Q20 -> 443.07794 | G21: =Mode5!AA20 -> 287.10974 | H21: =Mode5!AB20 -> 429.60057 | I21: =Mode5!Q20 -> 287.10974 | J21: =Mode5!R20 -> 411.43218 | K21: =Mode5!G20 -> 287.10974 | L21: =Mode5!H20 -> 392.83152 | M21: =Mode1!G20 -> 287.10974 | N21: =Mode1!H20 -> 373.14912
B22: -4 | C22: =Mode3!G21 -> 287.29073 | D22: =Mode3!H21 -> 444.80009 | E22: =Mode3!P21 -> 287.29073 | F22: =Mode3!Q21 -> 443.35254 | G22: =Mode5!AA21 -> 287.29073 | H22: =Mode5!AB21 -> 429.86647 | I22: =Mode5!Q21 -> 287.29073 | J22: =Mode5!R21 -> 411.68641 | K22: =Mode5!G21 -> 287.29073 | L22: =Mode5!H21 -> 393.0738 | M22: =Mode1!G21 -> 287.29073 | N22: =Mode1!H21 -> 373.37875
B23: -3 | C23: =Mode3!G22 -> 287.43376 | D23: =Mode3!H22 -> 445.0178 | E23: =Mode3!P22 -> 287.43376 | F23: =Mode3!Q22 -> 443.56954 | G23: =Mode5!AA22 -> 287.43376 | H23: =Mode5!AB22 -> 430.07653 | I23: =Mode5!Q22 -> 287.43376 | J23: =Mode5!R22 -> 411.88716 | K23: =Mode5!G22 -> 287.43376 | L23: =Mode5!H22 -> 393.26501 | M23: =Mode1!G22 -> 287.43376 | N23: =Mode1!H22 -> 373.55987
B24: -2 | C24: =Mode3!G23 -> 288.60695 | D24: =Mode3!H23 -> 446.80355 | E24: =Mode3!P23 -> 288.60695 | F24: =Mode3!Q23 -> 445.34948 | G24: =Mode5!AA23 -> 288.60695 | H24: =Mode5!AB23 -> 431.80198 | I24: =Mode5!Q23 -> 288.60695 | J24: =Mode5!R23 -> 413.5392 | K24: =Mode5!G23 -> 288.60695 | L24: =Mode5!H23 -> 394.8419 | M24: =Mode1!G23 -> 288.60695 | N24: =Mode1!H23 -> 375.05723
... B66: 40 | C66: =Mode3!G65 -> 224.34417 | D66: =Mode3!H65 -> 348.98687 | E66: =Mode3!P65 -> 224.34417 | F66: =Mode3!Q65 -> 347.8613 | G66: =Mode5!AA65 -> 224.34417 | H66: =Mode5!AB65 -> 339.29196 | I66: =Mode5!Q65 -> 224.34417 | J66: =Mode5!R65 -> 327.48947 | K66: =Mode5!G65 -> 224.34417 | L66: =Mode5!H65 -> 315.40616 | M66: =Mode1!G65 -> 224.34417 | N66: =Mode1!H65 -> 302.62013

Sheet Mode3
A1: MODE 3 | J1: MODE 3 - DH ECO
X2: 발전량 | Y2: 열생산량 | Z2: 열전비 | AA2: 감발량 | AB2: (15도씨 기준)
A3: 외기 온도 | B3: GROSS (MW) | E3: Aux Power (MW) | G3: NET (MW) | J3: 외기 온도 | K3: GROSS (MW) | N3: Aux Power (MW) | P3: NET (MW) | R3: DH (Gcal/h) | W3: M3 | X3: 450.4
B4: GT | C4: ST | D4: CC | E4: GT | F4: CC | G4: GT | H4: CC | K4: GT | L4: ST | M4: CC | N4: GT | O4: CC | P4: GT | Q4: CC | R4: ECO | U4: M3 | W4: M3ECO | X4: 449 | Y4: 7.69 | Z4: 0.18205462 | AA4: =$X$3-X4 -> 1.4
A5: -20 | B5: 291.36992 | C5: 152.13468 | D5: =B5+C5 -> 443.50461 | E5: 11.5 | F5: 10 | G5: =B5-E5 -> 279.86992 | H5: =D5-F5 -> 433.50461 | J5: -20 | K5: =B5 -> 291.36992 | L5: =M5-K5 -> 150.7239 | M5: =Q5+O5 -> 442.09382 | N5: =$E$5 -> 11.5 | O5: =$F$5 -> 10 | P5: =K5-N5 -> 279.86992 | Q5: =U5-(R5*$Z$4) -> 432.09382 | R5: =(R6*U5)/U6 -> 7.7492518 | U5: =H5 -> 433.50461 | Z5: 19년 기준 | AA5: =$X$3-X5 -> 450.4
A6: -19 | B6: 292.06244 | C6: 152.49627 | D6: =B6+C6 -> 444.55871 | E6: =$E$5 -> 11.5 | F6: =$F$5 -> 10 | G6: =B6-E6 -> 280.56244 | H6: =D6-F6 -> 434.55871 | I6: =H6-H5 -> 1.0541058 | J6: -19 | K6: =B6 -> 292.06244 | L6: =M6-K6 -> 151.08206 | M6: =Q6+O6 -> 443.1445 | N6: =$E$5 -> 11.5 | O6: =$F$5 -> 10 | P6: =K6-N6 -> 280.56244 | Q6: =U6-(R6*$Z$4) -> 433.1445 | R6: =(R7*U6)/U7 -> 7.7680948 | U6: =H6 -> 434.55871 | AA6: =$X$3-X6 -> 450.4
A7: -18 | B7: 292.72581 | C7: 152.84264 | D7: =B7+C7 -> 445.56846 | E7: =$E$5 -> 11.5 | F7: =$F$5 -> 10 | G7: =B7-E7 -> 281.22581 | H7: =D7-F7 -> 435.56846 | I7: =H7-H6 -> 1.0097444 | J7: -18 | K7: =B7 -> 292.72581 | L7: =M7-K7 -> 151.42514 | M7: =Q7+O7 -> 444.15096 | N7: =$E$5 -> 11.5 | O7: =$F$5 -> 10 | P7: =K7-N7 -> 281.22581 | Q7: =U7-(R7*$Z$4) -> 434.15096 | R7: =(R8*U7)/U8 -> 7.7861448 | U7: =H7 -> 435.56846 | AA7: =$X$3-X7 -> 450.4
A8: -17 | B8: 293.3728 | C8: 153.18046 | D8: =B8+C8 -> 446.55326 | E8: =$E$5 -> 11.5 | F8: =$F$5 -> 10 | G8: =B8-E8 -> 281.8728 | H8: =D8-F8 -> 436.55326 | I8: =H8-H7 -> 0.98479888 | J8: -17 | K8: =B8 -> 293.3728 | L8: =M8-K8 -> 151.75975 | M8: =Q8+O8 -> 445.13255 | N8: =$E$5 -> 11.5 | O8: =$F$5 -> 10 | P8: =K8-N8 -> 281.8728 | Q8: =U8-(R8*$Z$4) -> 435.13255 | R8: =(R9*U8)/U9 -> 7.8037489 | U8: =H8 -> 436.55326 | AA8: =$X$3-X8 -> 450.4
A9: -16 | B9: 293.9622 | C9: 153.48821 | D9: =B9+C9 -> 447.45041 | E9: =$E$5 -> 11.5 | F9: =$F$5 -> 10 | G9: =B9-E9 -> 282.4622 | H9: =D9-F9 -> 437.45041 | I9: =H9-H8 -> 0.89715382 | J9: -16 | K9: =B9 -> 293.9622 | L9: =M9-K9 -> 152.06458 | M9: =Q9+O9 -> 446.02678 | N9: =$E$5 -> 11.5 | O9: =$F$5 -> 10 | P9: =K9-N9 -> 282.4622 | Q9: =U9-(R9*$Z$4) -> 436.02678 | R9: =(R10*U9)/U10 -> 7.8197863 | U9: =H9 -> 437.45041
A10: -15 | B10: 294.50768 | C10: 153.77302 | D10: =B10+C10 -> 448.28071 | E10: =$E$5 -> 11.5 | F10: =$F$5 -> 10 | G10: =B10-E10 -> 283.00768 | H10: =D10-F10 -> 438.28071 | I10: =H10-H9 -> 0.83029398 | J10: -15 | K10: =B10 -> 294.50768 | L10: =M10-K10 -> 152.34669 | M10: =Q10+O10 -> 446.85438 | N10: =$E$5 -> 11.5 | O10: =$F$5 -> 10 | P10: =K10-N10 -> 283.00768 | Q10: =U10-(R10*$Z$4) -> 436.85438 | R10: =(R11*U10)/U11 -> 7.8346285 | U10: =H10 -> 438.28071
A11: -14 | B11: 295.07676 | C11: 154.07016 | D11: =B11+C11 -> 449.14692 | E11: =$E$5 -> 11.5 | F11: =$F$5 -> 10 | G11: =B11-E11 -> 283.57676 | H11: =D11-F11 -> 439.14692 | I11: =H11-H10 -> 0.86621423 | J11: -14 | K11: =B11 -> 295.07676 | L11: =M11-K11 -> 152.64101 | M11: =Q11+O11 -> 447.71777 | N11: =$E$5 -> 11.5 | O11: =$F$5 -> 10 | P11: =K11-N11 -> 283.57676 | Q11: =U11-(R11*$Z$4) -> 437.71777 | R11: =(R12*U11)/U12 -> 7.8501128 | U11: =H11 -> 439.14692
A12: -13 | B12: 295.57239 | C12: 154.32894 | D12: =B12+C12 -> 449.90133 | E12: =$E$5 -> 11.5 | F12: =$F$5 -> 10 | G12: =B12-E12 -> 284.07239 | H12: =D12-F12 -> 439.90133 | I12: =H12-H11 -> 0.75441448 | J12: -13 | K12: =B12 -> 295.57239 | L12: =M12-K12 -> 152.89734 | M12: =Q12+O12 -> 448.46973 | N12: =$E$5 -> 11.5 | O12: =$F$5 -> 10 | P12: =K12-N12 -> 284.07239 | Q12: =U12-(R12*$Z$4) -> 438.46973 | R12: =(R13*U12)/U13 -> 7.8635985 | U12: =H12 -> 439.90133
A13: -12 | B13: 295.95408 | C13: 154.52824 | D13: =B13+C13 -> 450.48232 | E13: =$E$5 -> 11.5 | F13: =$F$5 -> 10 | G13: =B13-E13 -> 284.45408 | H13: =D13-F13 -> 440.48232 | I13: =H13-H12 -> 0.58099014 | J13: -12 | K13: =B13 -> 295.95408 | L13: =M13-K13 -> 153.09474 | M13: =Q13+O13 -> 449.04883 | N13: =$E$5 -> 11.5 | O13: =$F$5 -> 10 | P13: =K13-N13 -> 284.45408 | Q13: =U13-(R13*$Z$4) -> 439.04883 | R13: =(R14*U13)/U14 -> 7.8739842 | U13: =H13 -> 440.48232
A14: -11 | B14: 296.45765 | C14: 154.79117 | D14: =B14+C14 -> 451.24882 | E14: =$E$5 -> 11.5 | F14: =$F$5 -> 10 | G14: =B14-E14 -> 284.95765 | H14: =D14-F14 -> 441.24882 | I14: =H14-H13 -> 0.76649564 | J14: -11 | K14: =B14 -> 296.45765 | L14: =M14-K14 -> 153.35518 | M14: =Q14+O14 -> 449.81283 | N14: =$E$5 -> 11.5 | O14: =$F$5 -> 10 | P14: =K14-N14 -> 284.95765 | Q14: =U14-(R14*$Z$4) -> 439.81283 | R14: =(R15*U14)/U15 -> 7.887686 | U14: =H14 -> 441.24882
A15: -10 | B15: 296.92085 | C15: 155.03302 | D15: =B15+C15 -> 451.95388 | E15: =$E$5 -> 11.5 | F15: =$F$5 -> 10 | G15: =B15-E15 -> 285.42085 | H15: =D15-F15 -> 441.95388 | I15: =H15-H14 -> 0.70505778 | J15: -10 | K15: =B15 -> 296.92085 | L15: =M15-K15 -> 153.59474 | M15: =Q15+O15 -> 450.51559 | N15: =$E$5 -> 11.5 | O15: =$F$5 -> 10 | P15: =K15-N15 -> 285.42085 | Q15: =U15-(R15*$Z$4) -> 440.51559 | R15: =(R16*U15)/U16 -> 7.9002894 | U15: =H15 -> 441.95388
A16: -9 | B16: 297.34307 | C16: 155.25348 | D16: =B16+C16 -> 452.59655 | E16: =$E$5 -> 11.5 | F16: =$F$5 -> 10 | G16: =B16-E16 -> 285.84307 | H16: =D16-F16 -> 442.59655 | I16: =H16-H15 -> 0.64266816 | J16: -9 | K16: =B16 -> 297.34307 | L16: =M16-K16 -> 153.8131 | M16: =Q16+O16 -> 451.15617 | N16: =$E$5 -> 11.5 | O16: =$F$5 -> 10 | P16: =K16-N16 -> 285.84307 | Q16: =U16-(R16*$Z$4) -> 441.15617 | R16: =(R17*U16)/U17 -> 7.9117777 | U16: =H16 -> 442.59655
A17: -8 | B17: 297.72368 | C17: 155.45221 | D17: =B17+C17 -> 453.17588 | E17: =$E$5 -> 11.5 | F17: =$F$5 -> 10 | G17: =B17-E17 -> 286.22368 | H17: =D17-F17 -> 443.17588 | I17: =H17-H16 -> 0.57933582 | J17: -8 | K17: =B17 -> 297.72368 | L17: =M17-K17 -> 154.00995 | M17: =Q17+O17 -> 451.73362 | N17: =$E$5 -> 11.5 | O17: =$F$5 -> 10 | P17: =K17-N17 -> 286.22368 | Q17: =U17-(R17*$Z$4) -> 441.73362 | R17: =(R18*U17)/U18 -> 7.9221338 | U17: =H17 -> 443.17588
A18: -7 | B18: 298.06206 | C18: 155.62889 | D18: =B18+C18 -> 453.69095 | E18: =$E$5 -> 11.5 | F18: =$F$5 -> 10 | G18: =B18-E18 -> 286.56206 | H18: =D18-F18 -> 443.69095 | I18: =H18-H17 -> 0.51506928 | J18: -7 | K18: =B18 -> 298.06206 | L18: =M18-K18 -> 154.18495 | M18: =Q18+O18 -> 452.24701 | N18: =$E$5 -> 11.5 | O18: =$F$5 -> 10 | P18: =K18-N18 -> 286.56206 | Q18: =U18-(R18*$Z$4) -> 442.24701 | R18: =(R19*U18)/U19 -> 7.9313411 | U18: =H18 -> 443.69095
A19: -6 | B19: 298.35762 | C19: 155.78321 | D19: =B19+C19 -> 454.14083 | E19: =$E$5 -> 11.5 | F19: =$F$5 -> 10 | G19: =B19-E19 -> 286.85762 | H19: =D19-F19 -> 444.14083 | I19: =H19-H18 -> 0.44987645 | J19: -6 | K19: =B19 -> 298.35762 | L19: =M19-K19 -> 154.33781 | M19: =Q19+O19 -> 452.69543 | N19: =$E$5 -> 11.5 | O19: =$F$5 -> 10 | P19: =K19-N19 -> 286.85762 | Q19: =U19-(R19*$Z$4) -> 442.69543 | R19: =(R20*U19)/U20 -> 7.939383 | U19: =H19 -> 444.14083
A20: -5 | B20: 298.60974 | C20: 155.91485 | D20: =B20+C20 -> 454.52459 | E20: =$E$5 -> 11.5 | F20: =$F$5 -> 10 | G20: =B20-E20 -> 287.10974 | H20: =D20-F20 -> 444.52459 | I20: =H20-H19 -> 0.38376463 | J20: -5 | K20: =B20 -> 298.60974 | L20: =M20-K20 -> 154.4682 | M20: =Q20+O20 -> 453.07794 | N20: =$E$5 -> 11.5 | O20: =$F$5 -> 10 | P20: =K20-N20 -> 287.10974 | Q20: =U20-(R20*$Z$4) -> 443.07794 | R20: =(R21*U20)/U21 -> 7.9462431 | U20: =H20 -> 444.52459
... A39: 14 | B39: 290.56976 | C39: 151.71689 | D39: =B39+C39 -> 442.28664 | E39: =$E$5 -> 11.5 | F39: =$F$5 -> 10 | G39: =B39-E39 -> 279.06976 | H39: =D39-F39 -> 432.28664 | I39: =H39-H38 -> -1.9594323 | J39: 14 | K39: =B39 -> 290.56976 | L39: =M39-K39 -> 150.31006 | M39: =Q39+O39 -> 440.87982 | N39: =$E$5 -> 11.5 | O39: =$F$5 -> 10 | P39: =K39-N39 -> 279.06976 | Q39: =U39-(R39*$Z$4) -> 430.87982 | R39: =(R40*U39)/U40 -> 7.7274797 | U39: =H39 -> 432.28664
A40: 15 | B40: 289.1923 | C40: 150.99767 | D40: =B40+C40 -> 440.18998 | E40: =$E$5 -> 11.5 | F40: =$F$5 -> 10 | G40: =B40-E40 -> 277.6923 | H40: =D40-F40 -> 430.18998 | I40: =H40-H39 -> -2.0966682 | J40: 15 | K40: =B40 -> 289.1923 | L40: =M40-K40 -> 149.59767 | M40: =Q40+O40 -> 438.78998 | N40: =$E$5 -> 11.5 | O40: =$F$5 -> 10 | P40: =K40-N40 -> 277.6923 | Q40: =U40-(R40*$Z$4) -> 428.78998 | R40: =Y4 -> 7.69 | U40: =H40 -> 430.18998
A41: 16 | B41: 287.86295 | C41: 150.30357 | D41: =B41+C41 -> 438.16652 | E41: =$E$5 -> 11.5 | F41: =$F$5 -> 10 | G41: =B41-E41 -> 276.36295 | H41: =D41-F41 -> 428.16652 | I41: =H41-H40 -> -2.0234518 | J41: 16 | K41: =B41 -> 287.86295 | L41: =M41-K41 -> 148.9105 | M41: =Q41+O41 -> 436.77346 | N41: =$E$5 -> 11.5 | O41: =$F$5 -> 10 | P41: =K41-N41 -> 276.36295 | Q41: =U41-(R41*$Z$4) -> 426.77346 | R41: =(R40*U42)/U41 -> 7.6519081 | U41: =H41 -> 428.16652
A42: 17 | B42: 286.46959 | C42: 149.57604 | D42: =B42+C42 -> 436.04563 | E42: =$E$5 -> 11.5 | F42: =$F$5 -> 10 | G42: =B42-E42 -> 274.96959 | H42: =D42-F42 -> 426.04563 | I42: =H42-H41 -> -2.1208926 | J42: 17 | K42: =B42 -> 286.46959 | L42: =M42-K42 -> 148.19023 | M42: =Q42+O42 -> 434.65982 | N42: =$E$5 -> 11.5 | O42: =$F$5 -> 10 | P42: =K42-N42 -> 274.96959 | Q42: =U42-(R42*$Z$4) -> 424.65982 | R42: =(R41*U43)/U42 -> 7.6120614 | U42: =H42 -> 426.04563
A43: 18 | B43: 285.01203 | C43: 148.815 | D43: =B43+C43 -> 433.82703 | E43: =$E$5 -> 11.5 | F43: =$F$5 -> 10 | G43: =B43-E43 -> 273.51203 | H43: =D43-F43 -> 423.82703 | I43: =H43-H42 -> -2.2186022 | J43: 18 | K43: =B43 -> 285.01203 | L43: =M43-K43 -> 147.43677 | M43: =Q43+O43 -> 432.44879 | N43: =$E$5 -> 11.5 | O43: =$F$5 -> 10 | P43: =K43-N43 -> 273.51203 | Q43: =U43-(R43*$Z$4) -> 422.44879 | R43: =(R42*U44)/U43 -> 7.5704472 | U43: =H43 -> 423.82703
A44: 19 | B44: 283.48982 | C44: 148.0202 | D44: =B44+C44 -> 431.51002 | E44: =$E$5 -> 11.5 | F44: =$F$5 -> 10 | G44: =B44-E44 -> 271.98982 | H44: =D44-F44 -> 421.51002 | I44: =H44-H43 -> -2.3170094 | J44: 19 | K44: =B44 -> 283.48982 | L44: =M44-K44 -> 146.64987 | M44: =Q44+O44 -> 430.13969 | N44: =$E$5 -> 11.5 | O44: =$F$5 -> 10 | P44: =K44-N44 -> 271.98982 | Q44: =U44-(R44*$Z$4) -> 420.13969 | R44: =(R43*U45)/U44 -> 7.5270458 | T44: =H51-[1]Mode3!$H$51 -> 11.960984 | U44: =H44 -> 421.51002
A45: 20 | B45: 281.90224 | C45: 147.19127 | D45: =B45+C45 -> 429.0935 | E45: =$E$5 -> 11.5 | F45: =$F$5 -> 10 | G45: =B45-E45 -> 270.40224 | H45: =D45-F45 -> 419.0935 | I45: =H45-H44 -> -2.4165195 | J45: 20 | K45: =B45 -> 281.90224 | L45: =M45-K45 -> 145.82916 | M45: =Q45+O45 -> 427.7314 | N45: =$E$5 -> 11.5 | O45: =$F$5 -> 10 | P45: =K45-N45 -> 270.40224 | Q45: =U45-(R45*$Z$4) -> 417.7314 | R45: =(R44*U46)/U45 -> 7.4818303 | T45: =(H51+H52)/2 -> 402.40073 | U45: =H45 -> 419.0935
A46: 21 | B46: 280.2483 | C46: 146.32768 | D46: =B46+C46 -> 426.57598 | E46: =$E$5 -> 11.5 | F46: =$F$5 -> 10 | G46: =B46-E46 -> 268.7483 | H46: =D46-F46 -> 416.57598 | I46: =H46-H45 -> -2.517521 | J46: 21 | K46: =B46 -> 280.2483 | L46: =M46-K46 -> 144.97415 | M46: =Q46+O46 -> 425.22245 | N46: =$E$5 -> 11.5 | O46: =$F$5 -> 10 | P46: =K46-N46 -> 268.7483 | Q46: =U46-(R46*$Z$4) -> 415.22245 | R46: =(R45*U47)/U46 -> 7.4347673 | U46: =H46 -> 416.57598
A47: 22 | B47: 278.52677 | C47: 145.42881 | D47: =B47+C47 -> 423.95559 | E47: =$E$5 -> 11.5 | F47: =$F$5 -> 10 | G47: =B47-E47 -> 267.02677 | H47: =D47-F47 -> 413.95559 | I47: =H47-H46 -> -2.6203932 | J47: 22 | K47: =B47 -> 278.52677 | L47: =M47-K47 -> 144.08419 | M47: =Q47+O47 -> 422.61096 | N47: =$E$5 -> 11.5 | O47: =$F$5 -> 10 | P47: =K47-N47 -> 267.02677 | Q47: =U47-(R47*$Z$4) -> 412.61096 | R47: =(R46*U48)/U47 -> 7.3858163 | U47: =H47 -> 413.95559
A48: 23 | B48: 276.73619 | C48: 144.49389 | D48: =B48+C48 -> 421.23007 | E48: =$E$5 -> 11.5 | F48: =$F$5 -> 10 | G48: =B48-E48 -> 265.23619 | H48: =D48-F48 -> 411.23007 | I48: =H48-H47 -> -2.7255116 | J48: 23 | K48: =B48 -> 276.73619 | L48: =M48-K48 -> 143.15853 | M48: =Q48+O48 -> 419.89472 | N48: =$E$5 -> 11.5 | O48: =$F$5 -> 10 | P48: =K48-N48 -> 265.23619 | Q48: =U48-(R48*$Z$4) -> 409.89472 | R48: =(R47*U49)/U48 -> 7.3349302 | U48: =H48 -> 411.23007
A49: 24 | B49: 274.87482 | C49: 143.522 | D49: =B49+C49 -> 418.39682 | E49: =$E$5 -> 11.5 | F49: =$F$5 -> 10 | G49: =B49-E49 -> 263.37482 | H49: =D49-F49 -> 408.39682 | I49: =H49-H48 -> -2.8332528 | J49: 24 | K49: =B49 -> 274.87482 | L49: =M49-K49 -> 142.18973 | M49: =Q49+O49 -> 417.06455 | N49: =$E$5 -> 11.5 | O49: =$F$5 -> 10 | P49: =K49-N49 -> 263.37482 | Q49: =U49-(R49*$Z$4) -> 407.06455 | R49: =(R48*U50)/U49 -> 7.3179757 | U49: =H49 -> 408.39682
A50: 25 | B50: 274.25464 | C50: 143.19818 | D50: =B50+C50 -> 417.45282 | E50: =$E$5 -> 11.5 | F50: =$F$5 -> 10 | G50: =B50-E50 -> 262.75464 | H50: =D50-F50 -> 407.45282 | I50: =H50-H49 -> -0.94399701 | J50: 25 | K50: =B50 -> 274.25464 | L50: =M50-K50 -> 141.87742 | M50: =Q50+O50 -> 416.13207 | N50: =$E$5 -> 11.5 | O50: =$F$5 -> 10 | P50: =K50-N50 -> 262.75464 | Q50: =U50-(R50*$Z$4) -> 406.13207 | R50: =(R49*U51)/U50 -> 7.2547417 | U50: =H50 -> 407.45282
A51: 26 | B51: 271.9416 | C51: 141.99046 | D51: =B51+C51 -> 413.93206 | E51: =$E$5 -> 11.5 | F51: =$F$5 -> 10 | G51: =B51-E51 -> 260.4416 | H51: =D51-F51 -> 403.93206 | I51: =H51-H50 -> -3.5207654 | J51: 26 | K51: =B51 -> 271.9416 | L51: =M51-K51 -> 140.67971 | M51: =Q51+O51 -> 412.62131 | N51: =$E$5 -> 11.5 | O51: =$F$5 -> 10 | P51: =K51-N51 -> 260.4416 | Q51: =U51-(R51*$Z$4) -> 402.62131 | R51: =(R50*U52)/U51 -> 7.1997353 | U51: =H51 -> 403.93206
A52: 27 | B52: 269.92951 | C52: 140.93988 | D52: =B52+C52 -> 410.86939 | E52: =$E$5 -> 11.5 | F52: =$F$5 -> 10 | G52: =B52-E52 -> 258.42951 | H52: =D52-F52 -> 400.86939 | I52: =H52-H51 -> -3.0626673 | J52: 27 | K52: =B52 -> 269.92951 | L52: =M52-K52 -> 139.63954 | M52: =Q52+O52 -> 409.56905 | N52: =$E$5 -> 11.5 | O52: =$F$5 -> 10 | P52: =K52-N52 -> 258.42951 | Q52: =U52-(R52*$Z$4) -> 399.56905 | R52: =(R51*U53)/U52 -> 7.1425724 | U52: =H52 -> 400.86939
A53: 28 | B53: 267.83855 | C53: 139.84811 | D53: =B53+C53 -> 407.68665 | E53: =$E$5 -> 11.5 | F53: =$F$5 -> 10 | G53: =B53-E53 -> 256.33855 | H53: =D53-F53 -> 397.68665 | I53: =H53-H52 -> -3.1827372 | J53: 28 | K53: =B53 -> 267.83855 | L53: =M53-K53 -> 138.55859 | M53: =Q53+O53 -> 406.39713 | N53: =$E$5 -> 11.5 | O53: =$F$5 -> 10 | P53: =K53-N53 -> 256.33855 | Q53: =U53-(R53*$Z$4) -> 396.39713 | R53: =(R52*U54)/U53 -> 7.0831574 | T53: =(H51+H52)/2 -> 402.40073 | U53: =H53 -> 397.68665
A54: 29 | B54: 265.6652 | C54: 138.71333 | D54: =B54+C54 -> 404.37853 | E54: =$E$5 -> 11.5 | F54: =$F$5 -> 10 | G54: =B54-E54 -> 254.1652 | H54: =D54-F54 -> 394.37853 | I54: =H54-H53 -> -3.3081263 | J54: 29 | K54: =B54 -> 265.6652 | L54: =M54-K54 -> 137.43505 | M54: =Q54+O54 -> 403.10025 | N54: =$E$5 -> 11.5 | O54: =$F$5 -> 10 | P54: =K54-N54 -> 254.1652 | Q54: =U54-(R54*$Z$4) -> 393.10025 | R54: =(R53*U55)/U54 -> 7.0213869 | U54: =H54 -> 394.37853
A55: 30 | B55: 263.40569 | C55: 137.53356 | D55: =B55+C55 -> 400.93925 | E55: =$E$5 -> 11.5 | F55: =$F$5 -> 10 | G55: =B55-E55 -> 251.90569 | H55: =D55-F55 -> 390.93925 | I55: =H55-H54 -> -3.4392791 | J55: 30 | K55: =B55 -> 263.40569 | L55: =M55-K55 -> 136.26725 | M55: =Q55+O55 -> 399.67294 | N55: =$E$5 -> 11.5 | O55: =$F$5 -> 10 | P55: =K55-N55 -> 251.90569 | Q55: =U55-(R55*$Z$4) -> 389.67294 | R55: =(R54*U56)/U55 -> 6.9556621 | U55: =H55 -> 390.93925
A56: 31 | B56: 261.00154 | C56: 136.27826 | D56: =B56+C56 -> 397.2798 | E56: =$E$5 -> 11.5 | F56: =$F$5 -> 10 | G56: =B56-E56 -> 249.50154 | H56: =D56-F56 -> 387.2798 | I56: =H56-H55 -> -3.6594479 | J56: 31 | K56: =B56 -> 261.00154 | L56: =M56-K56 -> 135.02439 | M56: =Q56+O56 -> 396.02592 | N56: =$E$5 -> 11.5 | O56: =$F$5 -> 10 | P56: =K56-N56 -> 249.50154 | Q56: =U56-(R56*$Z$4) -> 386.02592 | R56: =(R55*U57)/U56 -> 6.8873677 | U56: =H56 -> 387.2798
A57: 32 | B57: 258.50339 | C57: 134.97389 | D57: =B57+C57 -> 393.47728 | E57: =$E$5 -> 11.5 | F57: =$F$5 -> 10 | G57: =B57-E57 -> 247.00339 | H57: =D57-F57 -> 383.47728 | I57: =H57-H56 -> -3.802522 | J57: 32 | K57: =B57 -> 258.50339 | L57: =M57-K57 -> 133.73293 | M57: =Q57+O57 -> 392.23632 | N57: =$E$5 -> 11.5 | O57: =$F$5 -> 10 | P57: =K57-N57 -> 247.00339 | Q57: =U57-(R57*$Z$4) -> 382.23632 | R57: =(R56*U58)/U57 -> 6.8163893 | U57: =H57 -> 383.47728
A58: 33 | B58: 255.90707 | C58: 133.61825 | D58: =B58+C58 -> 389.52532 | E58: =$E$5 -> 11.5 | F58: =$F$5 -> 10 | G58: =B58-E58 -> 244.40707 | H58: =D58-F58 -> 379.52532 | I58: =H58-H57 -> -3.9519595 | J58: 33 | K58: =B58 -> 255.90707 | L58: =M58-K58 -> 132.39073 | M58: =Q58+O58 -> 388.2978 | N58: =$E$5 -> 11.5 | O58: =$F$5 -> 10 | P58: =K58-N58 -> 244.40707 | Q58: =U58-(R58*$Z$4) -> 378.2978 | R58: =(R57*U59)/U58 -> 6.7426074 | U58: =H58 -> 379.52532
...

Sheet Mode5
A1: MODE 5 - DH75% | K1: MODE 5 - DH50% | U1: MODE 5 - DH25% | AE1: MODE 5 - DH Dmin
AS2: 발전량 | AT2: 열생산량 | AU2: 열전비 | AV2: 비고 | AW2: (15도씨 기준)
A3: 외기 온도 | B3: GROSS (MW) | E3: Aux Power (MW) | G3: NET (MW) | K3: 외기 온도 | L3: GROSS (MW) | O3: Aux Power (MW) | Q3: NET (MW) | U3: 외기 온도 | V3: GROSS (MW) | Y3: Aux Power (MW) | AA3: NET (MW) | AE3: 외기 온도 | AF3: GROSS (MW) | AI3: Aux Power (MW) | AK3: NET (MW) | AR3: M3 | AS3: 450.4
B4: GT | C4: ST | D4: CC | E4: GT | F4: CC | G4: GT | H4: CC | I4: 열생산량 | L4: GT | M4: ST | N4: CC | O4: GT | P4: CC | Q4: GT | R4: CC | S4: 열생산량 | V4: GT | W4: ST | X4: CC | Y4: GT | Z4: CC | AA4: GT | AB4: CC | AC4: 열생산량 | AF4: GT | AG4: ST | AH4: CC | AI4: GT | AJ4: CC | AK4: GT | AL4: CC | AM4: 열생산량 | AO4: 온도별 차등적용 | AP4: M3 | AR4: M3ECO | AT4: 7.69 | AU4: 0.18205462 | AV4: 설계치
A5: -20 | B5: =Mode3!B5 -> 291.36992 | C5: =D5-B5 -> 102.51498 | D5: =H5+F5 -> 393.8849 | E5: =Mode3!E5 -> 11.5 | F5: =Mode3!$F$5 -> 10 | G5: =B5-E5 -> 279.86992 | H5: =AP5-I5*$AU$7*AO5 -> 383.8849 | I5: =(I6*AP5)/AP6 -> 181.38691 | K5: -20 | L5: =B5 -> 291.36992 | M5: =N5-L5 -> 120.36959 | N5: =R5+P5 -> 411.73951 | O5: =$E$5 -> 11.5 | P5: =$F$5 -> 10 | Q5: =L5-O5 -> 279.86992 | R5: =$AP5-S5*$AU$6*AO5 -> 401.73951 | S5: =(S6*AP5)/AP6 -> 120.92461 | U5: -20 | V5: =B5 -> 291.36992 | W5: =X5-V5 -> 137.80925 | X5: =AB5+Z5 -> 429.17917 | Y5: =$E$5 -> 11.5 | Z5: =$F$5 -> 10 | AA5: =V5-Y5 -> 279.86992 | AB5: =$AP5-AC5*$AU$5*AO5 -> 419.17917 | AC5: =(AC6*AP5)/AP6 -> 60.462303 | AE5: -20 | AF5: =L5 -> 291.36992 | AG5: =AH5-AF5 -> 146.07112 | AH5: =AL5+AJ5 -> 437.44105 | AI5: =$E$5 -> 11.5 | AJ5: =$F$5 -> 10 | AK5: =AF5-AI5 -> 279.86992 | AL5: =$AP5-AM5*$AU$9*AO5 -> 427.44105 | AM5: =(AM6*AP5)/AP6 -> 30.231151 | AO5: 0.99787738 | AP5: =Mode3!H5 -> 433.50461 | AR5: M5D25 | AT5: 60 | AU5: 0.23743569 | AV5: 설계치
A6: -19 | B6: =Mode3!B6 -> 292.06244 | C6: =D6-B6 -> 102.70299 | D6: =H6+F6 -> 394.76543 | E6: =$E$5 -> 11.5 | F6: =$F$5 -> 10 | G6: =B6-E6 -> 280.56244 | H6: =AP6-I6*$AU$7*AO6 -> 384.76543 | I6: =(I7*AP6)/AP7 -> 181.82797 | K6: -19 | L6: =B6 -> 292.06244 | M6: =N6-L6 -> 120.62006 | N6: =R6+P6 -> 412.6825 | O6: =$E$5 -> 11.5 | P6: =$F$5 -> 10 | Q6: =L6-O6 -> 280.56244 | R6: =$AP6-S6*$AU$6*AO6 -> 402.6825 | S6: =(S7*AP6)/AP7 -> 121.21864 | U6: -19 | V6: =B6 -> 292.06244 | W6: =X6-V6 -> 138.12072 | X6: =AB6+Z6 -> 430.18317 | Y6: =$E$5 -> 11.5 | Z6: =$F$5 -> 10 | AA6: =V6-Y6 -> 280.56244 | AB6: =$AP6-AC6*$AU$5*AO6 -> 420.18317 | AC6: =(AC7*AP6)/AP7 -> 60.609322 | AE6: -19 | AF6: =L6 -> 292.06244 | AG6: =AH6-AF6 -> 146.4115 | AH6: =AL6+AJ6 -> 438.47394 | AI6: =$E$5 -> 11.5 | AJ6: =$F$5 -> 10 | AK6: =AF6-AI6 -> 280.56244 | AL6: =$AP6-AM6*$AU$9*AO6 -> 428.47394 | AM6: =(AM7*AP6)/AP7 -> 30.304661 | AO6: 0.99893904 | AP6: =Mode3!H6 -> 434.55871 | AR6: M5D50 | AT6: 120 | AU6: 0.26324392 | AV6: 설계치
A7: -18 | B7: =Mode3!B7 -> 292.72581 | C7: =D7-B7 -> 102.88062 | D7: =H7+F7 -> 395.60644 | E7: =$E$5 -> 11.5 | F7: =$F$5 -> 10 | G7: =B7-E7 -> 281.22581 | H7: =AP7-I7*$AU$7*AO7 -> 385.60644 | I7: =(I8*AP7)/AP8 -> 182.25046 | K7: -18 | L7: =B7 -> 292.72581 | M7: =N7-L7 -> 120.8584 | N7: =R7+P7 -> 413.58422 | O7: =$E$5 -> 11.5 | P7: =$F$5 -> 10 | Q7: =L7-O7 -> 281.22581 | R7: =$AP7-S7*$AU$6*AO7 -> 403.58422 | S7: =(S8*AP7)/AP8 -> 121.50031 | U7: -18 | V7: =B7 -> 292.72581 | W7: =X7-V7 -> 138.41838 | X7: =AB7+Z7 -> 431.14419 | Y7: =$E$5 -> 11.5 | Z7: =$F$5 -> 10 | AA7: =V7-Y7 -> 281.22581 | AB7: =$AP7-AC7*$AU$5*AO7 -> 421.14419 | AC7: =(AC8*AP7)/AP8 -> 60.750155 | AE7: -18 | AF7: =L7 -> 292.72581 | AG7: =AH7-AF7 -> 146.73725 | AH7: =AL7+AJ7 -> 439.46306 | AI7: =$E$5 -> 11.5 | AJ7: =$F$5 -> 10 | AK7: =AF7-AI7 -> 281.22581 | AL7: =$AP7-AM7*$AU$9*AO7 -> 429.46306 | AM7: =(AM8*AP7)/AP8 -> 30.375077 | AO7: 1.0000007 | AP7: =Mode3!H7 -> 435.56846 | AR7: M5D75 | AT7: 180 | AU7: 0.27413916 | AV7: 설계치
A8: -17 | B8: =Mode3!B8 -> 293.3728 | C8: =D8-B8 -> 103.05231 | D8: =H8+F8 -> 396.42511 | E8: =$E$5 -> 11.5 | F8: =$F$5 -> 10 | G8: =B8-E8 -> 281.8728 | H8: =AP8-I8*$AU$7*AO8 -> 386.42511 | I8: =(I9*AP8)/AP9 -> 182.66252 | K8: -17 | L8: =B8 -> 293.3728 | M8: =N8-L8 -> 121.08987 | N8: =R8+P8 -> 414.46267 | O8: =$E$5 -> 11.5 | P8: =$F$5 -> 10 | Q8: =L8-O8 -> 281.8728 | R8: =$AP8-S8*$AU$6*AO8 -> 404.46267 | S8: =(S9*AP8)/AP9 -> 121.77502 | U8: -17 | V8: =B8 -> 293.3728 | W8: =X8-V8 -> 138.70823 | X8: =AB8+Z8 -> 432.08103 | Y8: =$E$5 -> 11.5 | Z8: =$F$5 -> 10 | AA8: =V8-Y8 -> 281.8728 | AB8: =$AP8-AC8*$AU$5*AO8 -> 422.08103 | AC8: =(AC9*AP8)/AP9 -> 60.887508 | AE8: -17 | AF8: =L8 -> 293.3728 | AG8: =AH8-AF8 -> 147.05476 | AH8: =AL8+AJ8 -> 440.42756 | AI8: =$E$5 -> 11.5 | AJ8: =$F$5 -> 10 | AK8: =AF8-AI8 -> 281.8728 | AL8: =$AP8-AM8*$AU$9*AO8 -> 430.42756 | AM8: =(AM9*AP8)/AP9 -> 30.443754 | AO8: 1.0010624 | AP8: =Mode3!H8 -> 436.55326 | AR8: M1 | AT8: 240 | AU8: 0.28388928 | AV8: 설계치
A9: -16 | B9: =Mode3!B9 -> 293.9622 | C9: =D9-B9 -> 103.20377 | D9: =H9+F9 -> 397.16597 | E9: =$E$5 -> 11.5 | F9: =$F$5 -> 10 | G9: =B9-E9 -> 282.4622 | H9: =AP9-I9*$AU$7*AO9 -> 387.16597 | I9: =(I10*AP9)/AP10 -> 183.03791 | K9: -16 | L9: =B9 -> 293.9622 | M9: =N9-L9 -> 121.29757 | N9: =R9+P9 -> 415.25977 | O9: =$E$5 -> 11.5 | P9: =$F$5 -> 10 | Q9: =L9-O9 -> 282.4622 | R9: =$AP9-S9*$AU$6*AO9 -> 405.25977 | S9: =(S10*AP9)/AP10 -> 122.02527 | U9: -16 | V9: =B9 -> 293.9622 | W9: =X9-V9 -> 138.97086 | X9: =AB9+Z9 -> 432.93306 | Y9: =$E$5 -> 11.5 | Z9: =$F$5 -> 10 | AA9: =V9-Y9 -> 282.4622 | AB9: =$AP9-AC9*$AU$5*AO9 -> 422.93306 | AC9: =(AC10*AP9)/AP10 -> 61.012637 | AE9: -16 | AF9: =L9 -> 293.9622 | AG9: =AH9-AF9 -> 147.34341 | AH9: =AL9+AJ9 -> 441.30562 | AI9: =$E$5 -> 11.5 | AJ9: =$F$5 -> 10 | AK9: =AF9-AI9 -> 282.4622 | AL9: =$AP9-AM9*$AU$9*AO9 -> 431.30562 | AM9: =(AM10*AP9)/AP10 -> 30.506318 | AO9: 1.002124 | AP9: =Mode3!H9 -> 437.45041 | AR9: M5Dmin | AT9: 30 | AU9: 0.201 | AV9: 계산값
A10: -15 | B10: =Mode3!B10 -> 294.50768 | C10: =D10-B10 -> 103.33977 | D10: =H10+F10 -> 397.84745 | E10: =$E$5 -> 11.5 | F10: =$F$5 -> 10 | G10: =B10-E10 -> 283.00768 | H10: =AP10-I10*$AU$7*AO10 -> 387.84745 | I10: =(I11*AP10)/AP11 -> 183.38532 | K10: -15 | L10: =B10 -> 294.50768 | M10: =N10-L10 -> 121.48712 | N10: =R10+P10 -> 415.9948 | O10: =$E$5 -> 11.5 | P10: =$F$5 -> 10 | Q10: =L10-O10 -> 283.00768 | R10: =$AP10-S10*$AU$6*AO10 -> 405.9948 | S10: =(S11*AP10)/AP11 -> 122.25688 | U10: -15 | V10: =B10 -> 294.50768 | W10: =X10-V10 -> 139.21271 | X10: =AB10+Z10 -> 433.72039 | Y10: =$E$5 -> 11.5 | Z10: =$F$5 -> 10 | AA10: =V10-Y10 -> 283.00768 | AB10: =$AP10-AC10*$AU$5*AO10 -> 423.72039 | AC10: =(AC11*AP10)/AP11 -> 61.128441 | AE10: -15 | AF10: =L10 -> 294.50768 | AG10: =AH10-AF10 -> 147.61004 | AH10: =AL10+AJ10 -> 442.11773 | AI10: =$E$5 -> 11.5 | AJ10: =$F$5 -> 10 | AK10: =AF10-AI10 -> 283.00768 | AL10: =$AP10-AM10*$AU$9*AO10 -> 432.11773 | AM10: =(AM11*AP10)/AP11 -> 30.56422 | AO10: 1.0031857 | AP10: =Mode3!H10 -> 438.28071
A11: -14 | B11: =Mode3!B11 -> 295.07676 | C11: =D11-B11 -> 103.48375 | D11: =H11+F11 -> 398.56051 | E11: =$E$5 -> 11.5 | F11: =$F$5 -> 10 | G11: =B11-E11 -> 283.57676 | H11: =AP11-I11*$AU$7*AO11 -> 388.56051 | I11: =(I12*AP11)/AP12 -> 183.74776 | K11: -14 | L11: =B11 -> 295.07676 | M11: =N11-L11 -> 121.68621 | N11: =R11+P11 -> 416.76297 | O11: =$E$5 -> 11.5 | P11: =$F$5 -> 10 | Q11: =L11-O11 -> 283.57676 | R11: =$AP11-S11*$AU$6*AO11 -> 406.76297 | S11: =(S12*AP11)/AP12 -> 122.49851 | U11: -14 | V11: =B11 -> 295.07676 | W11: =X11-V11 -> 139.46563 | X11: =AB11+Z11 -> 434.54239 | Y11: =$E$5 -> 11.5 | Z11: =$F$5 -> 10 | AA11: =V11-Y11 -> 283.57676 | AB11: =$AP11-AC11*$AU$5*AO11 -> 424.54239 | AC11: =(AC12*AP11)/AP12 -> 61.249254 | AE11: -14 | AF11: =L11 -> 295.07676 | AG11: =AH11-AF11 -> 147.88846 | AH11: =AL11+AJ11 -> 442.96523 | AI11: =$E$5 -> 11.5 | AJ11: =$F$5 -> 10 | AK11: =AF11-AI11 -> 283.57676 | AL11: =$AP11-AM11*$AU$9*AO11 -> 432.96523 | AM11: =(AM12*AP11)/AP12 -> 30.624627 | AO11: 1.0042473 | AP11: =Mode3!H11 -> 439.14692
A12: -13 | B12: =Mode3!B12 -> 295.57239 | C12: =D12-B12 -> 103.60206 | D12: =H12+F12 -> 399.17446 | E12: =$E$5 -> 11.5 | F12: =$F$5 -> 10 | G12: =B12-E12 -> 284.07239 | H12: =AP12-I12*$AU$7*AO12 -> 389.17446 | I12: =(I13*AP12)/AP13 -> 184.06342 | K12: -13 | L12: =B12 -> 295.57239 | M12: =N12-L12 -> 121.85506 | N12: =R12+P12 -> 417.42746 | O12: =$E$5 -> 11.5 | P12: =$F$5 -> 10 | Q12: =L12-O12 -> 284.07239 | R12: =$AP12-S12*$AU$6*AO12 -> 407.42746 | S12: =(S13*AP12)/AP13 -> 122.70895 | U12: -13 | V12: =B12 -> 295.57239 | W12: =X12-V12 -> 139.68386 | X12: =AB12+Z12 -> 435.25625 | Y12: =$E$5 -> 11.5 | Z12: =$F$5 -> 10 | AA12: =V12-Y12 -> 284.07239 | AB12: =$AP12-AC12*$AU$5*AO12 -> 425.25625 | AC12: =(AC13*AP12)/AP13 -> 61.354475 | AE12: -13 | AF12: =L12 -> 295.57239 | AG12: =AH12-AF12 -> 148.13008 | AH12: =AL12+AJ12 -> 443.70247 | AI12: =$E$5 -> 11.5 | AJ12: =$F$5 -> 10 | AK12: =AF12-AI12 -> 284.07239 | AL12: =$AP12-AM12*$AU$9*AO12 -> 433.70247 | AM12: =(AM13*AP12)/AP13 -> 30.677237 | AO12: 1.005309 | AP12: =Mode3!H12 -> 439.90133
A13: -12 | B13: =Mode3!B13 -> 295.95408 | C13: =D13-B13 -> 103.68072 | D13: =H13+F13 -> 399.63481 | E13: =$E$5 -> 11.5 | F13: =$F$5 -> 10 | G13: =B13-E13 -> 284.45408 | H13: =AP13-I13*$AU$7*AO13 -> 389.63481 | I13: =(I14*AP13)/AP14 -> 184.30652 | K13: -12 | L13: =B13 -> 295.95408 | M13: =N13-L13 -> 121.97713 | N13: =R13+P13 -> 417.93122 | O13: =$E$5 -> 11.5 | P13: =$F$5 -> 10 | Q13: =L13-O13 -> 284.45408 | R13: =$AP13-S13*$AU$6*AO13 -> 407.93122 | S13: =(S14*AP13)/AP14 -> 122.87101 | U13: -12 | V13: =B13 -> 295.95408 | W13: =X13-V13 -> 139.84833 | X13: =AB13+Z13 -> 435.80241 | Y13: =$E$5 -> 11.5 | Z13: =$F$5 -> 10 | AA13: =V13-Y13 -> 284.45408 | AB13: =$AP13-AC13*$AU$5*AO13 -> 425.80241 | AC13: =(AC14*AP13)/AP14 -> 61.435507 | AE13: -12 | AF13: =L13 -> 295.95408 | AG13: =AH13-AF13 -> 148.31464 | AH13: =AL13+AJ13 -> 444.26872 | AI13: =$E$5 -> 11.5 | AJ13: =$F$5 -> 10 | AK13: =AF13-AI13 -> 284.45408 | AL13: =$AP13-AM13*$AU$9*AO13 -> 434.26872 | AM13: =(AM14*AP13)/AP14 -> 30.717754 | AO13: 1.0063707 | AP13: =Mode3!H13 -> 440.48232
A14: -11 | B14: =Mode3!B14 -> 296.45765 | C14: =D14-B14 -> 103.80144 | D14: =H14+F14 -> 400.25909 | E14: =$E$5 -> 11.5 | F14: =$F$5 -> 10 | G14: =B14-E14 -> 284.95765 | H14: =AP14-I14*$AU$7*AO14 -> 390.25909 | I14: =(I15*AP14)/AP15 -> 184.62724 | K14: -11 | L14: =B14 -> 296.45765 | M14: =N14-L14 -> 122.14902 | N14: =R14+P14 -> 418.60667 | O14: =$E$5 -> 11.5 | P14: =$F$5 -> 10 | Q14: =L14-O14 -> 284.95765 | R14: =$AP14-S14*$AU$6*AO14 -> 408.60667 | S14: =(S15*AP14)/AP15 -> 123.08483 | U14: -11 | V14: =B14 -> 296.45765 | W14: =X14-V14 -> 140.0702 | X14: =AB14+Z14 -> 436.52785 | Y14: =$E$5 -> 11.5 | Z14: =$F$5 -> 10 | AA14: =V14-Y14 -> 284.95765 | AB14: =$AP14-AC14*$AU$5*AO14 -> 426.52785 | AC14: =(AC15*AP14)/AP15 -> 61.542413 | AE14: -11 | AF14: =L14 -> 296.45765 | AG14: =AH14-AF14 -> 148.56019 | AH14: =AL14+AJ14 -> 445.01784 | AI14: =$E$5 -> 11.5 | AJ14: =$F$5 -> 10 | AK14: =AF14-AI14 -> 284.95765 | AL14: =$AP14-AM14*$AU$9*AO14 -> 435.01784 | AM14: =(AM15*AP14)/AP15 -> 30.771207 | AO14: 1.0074323 | AP14: =Mode3!H14 -> 441.24882
A15: -10 | B15: =Mode3!B15 -> 296.92085 | C15: =D15-B15 -> 103.85418 | D15: =H15+F15 -> 400.77503 | E15: =$E$5 -> 11.5 | F15: =$F$5 -> 10 | G15: =B15-E15 -> 285.42085 | H15: =AP15-I15*$AU$7*AO15 -> 390.77503 | I15: =(I16*AP15)/AP16 -> 184.92225 | K15: -10 | L15: =B15 -> 296.92085 | M15: =N15-L15 -> 122.26981 | N15: =R15+P15 -> 419.19066 | O15: =$E$5 -> 11.5 | P15: =$F$5 -> 10 | Q15: =L15-O15 -> 285.42085 | R15: =$AP15-S15*$AU$6*AO15 -> 409.19066 | S15: =(S16*AP15)/AP16 -> 123.2815 | U15: -10 | V15: =B15 -> 296.92085 | W15: =X15-V15 -> 140.25746 | X15: =AB15+Z15 -> 437.17831 | Y15: =$E$5 -> 11.5 | Z15: =$F$5 -> 10 | AA15: =V15-Y15 -> 285.42085 | AB15: =$AP15-AC15*$AU$5*AO15 -> 427.17831 | AC15: =(AC16*AP15)/AP16 -> 61.64075 | AE15: -10 | AF15: =L15 -> 296.92085 | AG15: =AH15-AF15 -> 148.77893 | AH15: =AL15+AJ15 -> 445.69979 | AI15: =$E$5 -> 11.5 | AJ15: =$F$5 -> 10 | AK15: =AF15-AI15 -> 285.42085 | AL15: =$AP15-AM15*$AU$9*AO15 -> 435.69979 | AM15: =(AM16*AP15)/AP16 -> 30.820375 | AO15: 1.0095556 | AP15: =Mode3!H15 -> 441.95388
A16: -9 | B16: =Mode3!B16 -> 297.34307 | C16: =D16-B16 -> 103.94631 | D16: =H16+F16 -> 401.28938 | E16: =$E$5 -> 11.5 | F16: =$F$5 -> 10 | G16: =B16-E16 -> 285.84307 | H16: =AP16-I16*$AU$7*AO16 -> 391.28938 | I16: =(I17*AP16)/AP17 -> 185.19115 | K16: -9 | L16: =B16 -> 297.34307 | M16: =N16-L16 -> 122.40812 | N16: =R16+P16 -> 419.75118 | O16: =$E$5 -> 11.5 | P16: =$F$5 -> 10 | Q16: =L16-O16 -> 285.84307 | R16: =$AP16-S16*$AU$6*AO16 -> 409.75118 | S16: =(S17*AP16)/AP17 -> 123.46077 | U16: -9 | V16: =B16 -> 297.34307 | W16: =X16-V16 -> 140.44086 | X16: =AB16+Z16 -> 437.78393 | Y16: =$E$5 -> 11.5 | Z16: =$F$5 -> 10 | AA16: =V16-Y16 -> 285.84307 | AB16: =$AP16-AC16*$AU$5*AO16 -> 427.78393 | AC16: =(AC17*AP16)/AP17 -> 61.730385 | AE16: -9 | AF16: =L16 -> 297.34307 | AG16: =AH16-AF16 -> 148.98371 | AH16: =AL16+AJ16 -> 446.32677 | AI16: =$E$5 -> 11.5 | AJ16: =$F$5 -> 10 | AK16: =AF16-AI16 -> 285.84307 | AL16: =$AP16-AM16*$AU$9*AO16 -> 436.32677 | AM16: =(AM17*AP16)/AP17 -> 30.865192 | AO16: 1.0106173 | AP16: =Mode3!H16 -> 442.59655
A17: -8 | B17: =Mode3!B17 -> 297.72368 | C17: =D17-B17 -> 104.02391 | D17: =H17+F17 -> 401.74759 | E17: =$E$5 -> 11.5 | F17: =$F$5 -> 10 | G17: =B17-E17 -> 286.22368 | H17: =AP17-I17*$AU$7*AO17 -> 391.74759 | I17: =(I18*AP17)/AP18 -> 185.43356 | K17: -8 | L17: =B17 -> 297.72368 | M17: =N17-L17 -> 122.5293 | N17: =R17+P17 -> 420.25298 | O17: =$E$5 -> 11.5 | P17: =$F$5 -> 10 | Q17: =L17-O17 -> 286.22368 | R17: =$AP17-S17*$AU$6*AO17 -> 410.25298 | S17: =(S18*AP17)/AP18 -> 123.62237 | U17: -8 | V17: =B17 -> 297.72368 | W17: =X17-V17 -> 140.60462 | X17: =AB17+Z17 -> 438.3283 | Y17: =$E$5 -> 11.5 | Z17: =$F$5 -> 10 | AA17: =V17-Y17 -> 286.22368 | AB17: =$AP17-AC17*$AU$5*AO17 -> 428.3283 | AC17: =(AC18*AP17)/AP18 -> 61.811187 | AE17: -8 | AF17: =L17 -> 297.72368 | AG17: =AH17-AF17 -> 149.16763 | AH17: =AL17+AJ17 -> 446.89131 | AI17: =$E$5 -> 11.5 | AJ17: =$F$5 -> 10 | AK17: =AF17-AI17 -> 286.22368 | AL17: =$AP17-AM17*$AU$9*AO17 -> 436.89131 | AM17: =(AM18*AP17)/AP18 -> 30.905593 | AO17: 1.011679 | AP17: =Mode3!H17 -> 443.17588
A18: -7 | B18: =Mode3!B18 -> 298.06206 | C18: =D18-B18 -> 104.08679 | D18: =H18+F18 -> 402.14885 | E18: =$E$5 -> 11.5 | F18: =$F$5 -> 10 | G18: =B18-E18 -> 286.56206 | H18: =AP18-I18*$AU$7*AO18 -> 392.14885 | I18: =(I19*AP18)/AP19 -> 185.64908 | K18: -7 | L18: =B18 -> 298.06206 | M18: =N18-L18 -> 122.63313 | N18: =R18+P18 -> 420.69519 | O18: =$E$5 -> 11.5 | P18: =$F$5 -> 10 | Q18: =L18-O18 -> 286.56206 | R18: =$AP18-S18*$AU$6*AO18 -> 410.69519 | S18: =(S19*AP18)/AP19 -> 123.76605 | U18: -7 | V18: =B18 -> 298.06206 | W18: =X18-V18 -> 140.74845 | X18: =AB18+Z18 -> 438.81051 | Y18: =$E$5 -> 11.5 | Z18: =$F$5 -> 10 | AA18: =V18-Y18 -> 286.56206 | AB18: =$AP18-AC18*$AU$5*AO18 -> 428.81051 | AC18: =(AC19*AP18)/AP19 -> 61.883025 | AE18: -7 | AF18: =L18 -> 298.06206 | AG18: =AH18-AF18 -> 149.33041 | AH18: =AL18+AJ18 -> 447.39247 | AI18: =$E$5 -> 11.5 | AJ18: =$F$5 -> 10 | AK18: =AF18-AI18 -> 286.56206 | AL18: =$AP18-AM18*$AU$9*AO18 -> 437.39247 | AM18: =(AM19*AP18)/AP19 -> 30.941513 | AO18: 1.0127406 | AP18: =Mode3!H18 -> 443.69095
A19: -6 | B19: =Mode3!B19 -> 298.35762 | C19: =D19-B19 -> 104.18885 | D19: =H19+F19 -> 402.54647 | E19: =$E$5 -> 11.5 | F19: =$F$5 -> 10 | G19: =B19-E19 -> 286.85762 | H19: =AP19-I19*$AU$7*AO19 -> 392.54647 | I19: =(I20*AP19)/AP20 -> 185.83731 | K19: -6 | L19: =B19 -> 298.35762 | M19: =N19-L19 -> 122.754 | N19: =R19+P19 -> 421.11161 | O19: =$E$5 -> 11.5 | P19: =$F$5 -> 10 | Q19: =L19-O19 -> 286.85762 | R19: =$AP19-S19*$AU$6*AO19 -> 411.11161 | S19: =(S20*AP19)/AP20 -> 123.89154 | U19: -6 | V19: =B19 -> 298.35762 | W19: =X19-V19 -> 140.88768 | X19: =AB19+Z19 -> 439.2453 | Y19: =$E$5 -> 11.5 | Z19: =$F$5 -> 10 | AA19: =V19-Y19 -> 286.85762 | AB19: =$AP19-AC19*$AU$5*AO19 -> 429.2453 | AC19: =(AC20*AP19)/AP20 -> 61.945771 | AE19: -6 | AF19: =L19 -> 298.35762 | AG19: =AH19-AF19 -> 149.47834 | AH19: =AL19+AJ19 -> 447.83596 | AI19: =$E$5 -> 11.5 | AJ19: =$F$5 -> 10 | AK19: =AF19-AI19 -> 286.85762 | AL19: =$AP19-AM19*$AU$9*AO19 -> 437.83596 | AM19: =(AM20*AP19)/AP20 -> 30.972885 | AO19: 1.0127406 | AP19: =Mode3!H19 -> 444.14083
A20: -5 | B20: =Mode3!B20 -> 298.60974 | C20: =D20-B20 -> 104.22178 | D20: =H20+F20 -> 402.83152 | E20: =$E$5 -> 11.5 | F20: =$F$5 -> 10 | G20: =B20-E20 -> 287.10974 | H20: =AP20-I20*$AU$7*AO20 -> 392.83152 | I20: =(I21*AP20)/AP21 -> 185.99789 | K20: -5 | L20: =B20 -> 298.60974 | M20: =N20-L20 -> 122.82244 | N20: =R20+P20 -> 421.43218 | O20: =$E$5 -> 11.5 | P20: =$F$5 -> 10 | Q20: =L20-O20 -> 287.10974 | R20: =$AP20-S20*$AU$6*AO20 -> 411.43218 | S20: =(S21*AP20)/AP21 -> 123.99859 | U20: -5 | V20: =B20 -> 298.60974 | W20: =X20-V20 -> 140.99083 | X20: =AB20+Z20 -> 439.60057 | Y20: =$E$5 -> 11.5 | Z20: =$F$5 -> 10 | AA20: =V20-Y20 -> 287.10974 | AB20: =$AP20-AC20*$AU$5*AO20 -> 429.60057 | AC20: =(AC21*AP20)/AP21 -> 61.999296 | AE20: -5 | AF20: =L20 -> 298.60974 | AG20: =AH20-AF20 -> 149.59792 | AH20: =AL20+AJ20 -> 448.20766 | AI20: =$E$5 -> 11.5 | AJ20: =$F$5 -> 10 | AK20: =AF20-AI20 -> 287.10974 | AL20: =$AP20-AM20*$AU$9*AO20 -> 438.20766 | AM20: =(AM21*AP20)/AP21 -> 30.999648 | AO20: 1.0138023 | AP20: =Mode3!H20 -> 444.52459
A21: -4 | B21: =Mode3!B21 -> 298.79073 | C21: =D21-B21 -> 104.28306 | D21: =H21+F21 -> 403.0738 | E21: =$E$5 -> 11.5 | F21: =$F$5 -> 10 | G21: =B21-E21 -> 287.29073 | H21: =AP21-I21*$AU$7*AO21 -> 393.0738 | I21: =(I22*AP21)/AP22 -> 186.11316 | K21: -4 | L21: =B21 -> 298.79073 | M21: =N21-L21 -> 122.89568 | N21: =R21+P21 -> 421.68641 | O21: =$E$5 -> 11.5 | P21: =$F$5 -> 10 | Q21: =L21-O21 -> 287.29073 | R21: =$AP21-S21*$AU$6*AO21 -> 411.68641 | S21: =(S22*AP21)/AP22 -> 124.07544 | U21: -4 | V21: =B21 -> 298.79073 | W21: =X21-V21 -> 141.07574 | X21: =AB21+Z21 -> 439.86647 | Y21: =$E$5 -> 11.5 | Z21: =$F$5 -> 10 | AA21: =V21-Y21 -> 287.29073 | AB21: =$AP21-AC21*$AU$5*AO21 -> 429.86647 | AC21: =(AC22*AP21)/AP22 -> 62.03772 | AE21: -4 | AF21: =L21 -> 298.79073 | AG21: =AH21-AF21 -> 149.68837 | AH21: =AL21+AJ21 -> 448.4791 | AI21: =$E$5 -> 11.5 | AJ21: =$F$5 -> 10 | AK21: =AF21-AI21 -> 287.29073 | AL21: =$AP21-AM21*$AU$9*AO21 -> 438.4791 | AM21: =(AM22*AP21)/AP22 -> 31.01886 | AO21: 1.0138254 | AP21: =Mode3!H21 -> 444.80009
... A39: 14 | B39: =Mode3!B39 -> 290.56976 | C39: =D39-B39 -> 101.99102 | D39: =H39+F39 -> 392.56077 | E39: =$E$5 -> 11.5 | F39: =$F$5 -> 10 | G39: =B39-E39 -> 279.06976 | H39: =AP39-I39*$AU$7*AO39 -> 382.56077 | I39: =(I40*AP39)/AP40 -> 180.87729 | K39: 14 | L39: =B39 -> 290.56976 | M39: =N39-L39 -> 119.88383 | N39: =R39+P39 -> 410.45358 | O39: =$E$5 -> 11.5 | P39: =$F$5 -> 10 | Q39: =L39-O39 -> 279.06976 | R39: =$AP39-S39*$AU$6*AO39 -> 400.45358 | S39: =(S40*AP39)/AP40 -> 120.58486 | U39: 14 | V39: =B39 -> 290.56976 | W39: =X39-V39 -> 137.3608 | X39: =AB39+Z39 -> 427.93056 | Y39: =$E$5 -> 11.5 | Z39: =$F$5 -> 10 | AA39: =V39-Y39 -> 279.06976 | AB39: =$AP39-AC39*$AU$5*AO39 -> 417.93056 | AC39: =(AC40*AP39)/AP40 -> 60.292429 | AE39: 14 | AF39: =L39 -> 290.56976 | AG39: =AH39-AF39 -> 145.64035 | AH39: =AL39+AJ39 -> 436.21011 | AI39: =$E$5 -> 11.5 | AJ39: =$F$5 -> 10 | AK39: =AF39-AI39 -> 279.06976 | AL39: =$AP39-AM39*$AU$9*AO39 -> 426.21011 | AM39: =(AM40*AP39)/AP40 -> 30.146215 | AO39: 1.00283 | AP39: =Mode3!H39 -> 432.28664
A40: 15 | B40: =Mode3!B40 -> 289.1923 | C40: =D40-B40 -> 101.65262 | D40: =H40+F40 -> 390.84493 | E40: =$E$5 -> 11.5 | F40: =$F$5 -> 10 | G40: =B40-E40 -> 277.6923 | H40: =AP40-I40*$AU$7*AO40 -> 380.84493 | I40: =AT7 -> 180 | K40: 15 | L40: =B40 -> 289.1923 | M40: =N40-L40 -> 119.4084 | N40: =R40+P40 -> 408.60071 | O40: =$E$5 -> 11.5 | P40: =$F$5 -> 10 | Q40: =L40-O40 -> 277.6923 | R40: =$AP40-S40*$AU$6*AO40 -> 398.60071 | S40: =AT6 -> 120 | U40: 15 | V40: =B40 -> 289.1923 | W40: =X40-V40 -> 136.75153 | X40: =AB40+Z40 -> 425.94383 | Y40: =$E$5 -> 11.5 | Z40: =$F$5 -> 10 | AA40: =V40-Y40 -> 277.6923 | AB40: =$AP40-AC40*$AU$5*AO40 -> 415.94383 | AC40: =AT5 -> 60 | AE40: 15 | AF40: =L40 -> 289.1923 | AG40: =AH40-AF40 -> 144.96767 | AH40: =AL40+AJ40 -> 434.15998 | AI40: =$E$5 -> 11.5 | AJ40: =$F$5 -> 10 | AK40: =AF40-AI40 -> 277.6923 | AL40: =$AP40-AM40*$AU$9*AO40 -> 424.15998 | AM40: =AT9 -> 30 | AO40: 1 | AP40: =Mode3!H40 -> 430.18998
A41: 16 | B41: =Mode3!B41 -> 287.86295 | C41: =D41-B41 -> 101.3419 | D41: =H41+F41 -> 389.20486 | E41: =$E$5 -> 11.5 | F41: =$F$5 -> 10 | G41: =B41-E41 -> 276.36295 | H41: =AP41-I41*$AU$7*AO41 -> 379.20486 | I41: =(I40*AP42)/AP41 -> 179.10838 | K41: 16 | L41: =B41 -> 287.86295 | M41: =N41-L41 -> 118.95973 | N41: =R41+P41 -> 406.82268 | O41: =$E$5 -> 11.5 | P41: =$F$5 -> 10 | Q41: =L41-O41 -> 276.36295 | R41: =$AP41-S41*$AU$6*AO41 -> 396.82268 | S41: =(S40*AP42)/AP41 -> 119.40559 | U41: 16 | V41: =B41 -> 287.86295 | W41: =X41-V41 -> 136.16811 | X41: =AB41+Z41 -> 424.03107 | Y41: =$E$5 -> 11.5 | Z41: =$F$5 -> 10 | AA41: =V41-Y41 -> 276.36295 | AB41: =$AP41-AC41*$AU$5*AO41 -> 414.03107 | AC41: =(AC40*AP42)/AP41 -> 59.702794 | AE41: 16 | AF41: =L41 -> 287.86295 | AG41: =AH41-AF41 -> 144.32042 | AH41: =AL41+AJ41 -> 432.18337 | AI41: =$E$5 -> 11.5 | AJ41: =$F$5 -> 10 | AK41: =AF41-AI41 -> 276.36295 | AL41: =$AP41-AM41*$AU$9*AO41 -> 422.18337 | AM41: =(AM40*AP42)/AP41 -> 29.851397 | AO41: 0.99717005 | AP41: =Mode3!H41 -> 428.16652
A42: 17 | B42: =Mode3!B42 -> 286.46959 | C42: =D42-B42 -> 101.3311 | D42: =H42+F42 -> 387.80069 | E42: =$E$5 -> 11.5 | F42: =$F$5 -> 10 | G42: =B42-E42 -> 274.96959 | H42: =AP42-I42*$AU$7*AO42 -> 377.80069 | I42: =(I41*AP43)/AP42 -> 178.17569 | K42: 17 | L42: =B42 -> 286.46959 | M42: =N42-L42 -> 118.69103 | N42: =R42+P42 -> 405.16062 | O42: =$E$5 -> 11.5 | P42: =$F$5 -> 10 | Q42: =L42-O42 -> 274.96959 | R42: =$AP42-S42*$AU$6*AO42 -> 395.16062 | S42: =(S41*AP43)/AP42 -> 118.78379 | U42: 17 | V42: =B42 -> 286.46959 | W42: =X42-V42 -> 135.64751 | X42: =AB42+Z42 -> 422.1171 | Y42: =$E$5 -> 11.5 | Z42: =$F$5 -> 10 | AA42: =V42-Y42 -> 274.96959 | AB42: =$AP42-AC42*$AU$5*AO42 -> 412.1171 | AC42: =(AC41*AP43)/AP42 -> 59.391896 | AE42: 17 | AF42: =L42 -> 286.46959 | AG42: =AH42-AF42 -> 143.68048 | AH42: =AL42+AJ42 -> 430.15007 | AI42: =$E$5 -> 11.5 | AJ42: =$F$5 -> 10 | AK42: =AF42-AI42 -> 274.96959 | AL42: =$AP42-AM42*$AU$9*AO42 -> 420.15007 | AM42: =(AM41*AP43)/AP42 -> 29.695948 | AO42: 0.98771638 | AP42: =Mode3!H42 -> 426.04563
A43: 18 | B43: =Mode3!B43 -> 285.01203 | C43: =D43-B43 -> 101.13216 | D43: =H43+F43 -> 386.14419 | E43: =$E$5 -> 11.5 | F43: =$F$5 -> 10 | G43: =B43-E43 -> 273.51203 | H43: =AP43-I43*$AU$7*AO43 -> 376.14419 | I43: =(I42*AP44)/AP43 -> 177.20162 | K43: 18 | L43: =B43 -> 285.01203 | M43: =N43-L43 -> 118.28983 | N43: =R43+P43 -> 403.30186 | O43: =$E$5 -> 11.5 | P43: =$F$5 -> 10 | Q43: =L43-O43 -> 273.51203 | R43: =$AP43-S43*$AU$6*AO43 -> 393.30186 | S43: =(S42*AP44)/AP43 -> 118.13442 | U43: 18 | V43: =B43 -> 285.01203 | W43: =X43-V43 -> 135.04875 | X43: =AB43+Z43 -> 420.06078 | Y43: =$E$5 -> 11.5 | Z43: =$F$5 -> 10 | AA43: =V43-Y43 -> 273.51203 | AB43: =$AP43-AC43*$AU$5*AO43 -> 410.06078 | AC43: =(AC42*AP44)/AP43 -> 59.067208 | AE43: 18 | AF43: =L43 -> 285.01203 | AG43: =AH43-AF43 -> 142.98812 | AH43: =AL43+AJ43 -> 428.00015 | AI43: =$E$5 -> 11.5 | AJ43: =$F$5 -> 10 | AK43: =AF43-AI43 -> 273.51203 | AL43: =$AP43-AM43*$AU$9*AO43 -> 418.00015 | AM43: =(AM42*AP44)/AP43 -> 29.533604 | AO43: 0.98157457 | AP43: =Mode3!H43 -> 423.82703
A44: 19 | B44: =Mode3!B44 -> 283.48982 | C44: =D44-B44 -> 100.90738 | D44: =H44+F44 -> 384.3972 | E44: =$E$5 -> 11.5 | F44: =$F$5 -> 10 | G44: =B44-E44 -> 271.98982 | H44: =AP44-I44*$AU$7*AO44 -> 374.3972 | I44: =(I43*AP45)/AP44 -> 176.18573 | K44: 19 | L44: =B44 -> 283.48982 | M44: =N44-L44 -> 117.85993 | N44: =R44+P44 -> 401.34975 | O44: =$E$5 -> 11.5 | P44: =$F$5 -> 10 | Q44: =L44-O44 -> 271.98982 | R44: =$AP44-S44*$AU$6*AO44 -> 391.34975 | S44: =(S43*AP45)/AP44 -> 117.45715 | U44: 19 | V44: =B44 -> 283.48982 | W44: =X44-V44 -> 134.41851 | X44: =AB44+Z44 -> 417.90833 | Y44: =$E$5 -> 11.5 | Z44: =$F$5 -> 10 | AA44: =V44-Y44 -> 271.98982 | AB44: =$AP44-AC44*$AU$5*AO44 -> 407.90833 | AC44: =(AC43*AP45)/AP44 -> 58.728575 | AE44: 19 | AF44: =L44 -> 283.48982 | AG44: =AH44-AF44 -> 142.26298 | AH44: =AL44+AJ44 -> 425.7528 | AI44: =$E$5 -> 11.5 | AJ44: =$F$5 -> 10 | AK44: =AF44-AI44 -> 271.98982 | AL44: =$AP44-AM44*$AU$9*AO44 -> 415.7528 | AM44: =(AM43*AP45)/AP44 -> 29.364288 | AO44: 0.97543276 | AP44: =Mode3!H44 -> 421.51002
A45: 20 | B45: =Mode3!B45 -> 281.90224 | C45: =D45-B45 -> 100.65632 | D45: =H45+F45 -> 382.55855 | E45: =$E$5 -> 11.5 | F45: =$F$5 -> 10 | G45: =B45-E45 -> 270.40224 | H45: =AP45-I45*$AU$7*AO45 -> 372.55855 | I45: =(I44*AP46)/AP45 -> 175.12737 | K45: 20 | L45: =B45 -> 281.90224 | M45: =N45-L45 -> 117.40094 | N45: =R45+P45 -> 399.30317 | O45: =$E$5 -> 11.5 | P45: =$F$5 -> 10 | Q45: =L45-O45 -> 270.40224 | R45: =$AP45-S45*$AU$6*AO45 -> 389.30317 | S45: =(S44*AP46)/AP45 -> 116.75158 | U45: 20 | V45: =B45 -> 281.90224 | W45: =X45-V45 -> 133.75641 | X45: =AB45+Z45 -> 415.65865 | Y45: =$E$5 -> 11.5 | Z45: =$F$5 -> 10 | AA45: =V45-Y45 -> 270.40224 | AB45: =$AP45-AC45*$AU$5*AO45 -> 405.65865 | AC45: =(AC44*AP46)/AP45 -> 58.375789 | AE45: 20 | AF45: =L45 -> 281.90224 | AG45: =AH45-AF45 -> 141.50466 | AH45: =AL45+AJ45 -> 423.4069 | AI45: =$E$5 -> 11.5 | AJ45: =$F$5 -> 10 | AK45: =AF45-AI45 -> 270.40224 | AL45: =$AP45-AM45*$AU$9*AO45 -> 413.4069 | AM45: =(AM44*AP46)/AP45 -> 29.187895 | AO45: 0.96929095 | AP45: =Mode3!H45 -> 419.0935
A46: 21 | B46: =Mode3!B46 -> 280.2483 | C46: =D46-B46 -> 100.37846 | D46: =H46+F46 -> 380.62676 | E46: =$E$5 -> 11.5 | F46: =$F$5 -> 10 | G46: =B46-E46 -> 268.7483 | H46: =AP46-I46*$AU$7*AO46 -> 370.62676 | I46: =(I45*AP47)/AP46 -> 174.02576 | K46: 21 | L46: =B46 -> 280.2483 | M46: =N46-L46 -> 116.91232 | N46: =R46+P46 -> 397.16062 | O46: =$E$5 -> 11.5 | P46: =$F$5 -> 10 | Q46: =L46-O46 -> 268.7483 | R46: =$AP46-S46*$AU$6*AO46 -> 387.16062 | S46: =(S45*AP47)/AP46 -> 116.01717 | U46: 21 | V46: =B46 -> 280.2483 | W46: =X46-V46 -> 133.06193 | X46: =AB46+Z46 -> 413.31023 | Y46: =$E$5 -> 11.5 | Z46: =$F$5 -> 10 | AA46: =V46-Y46 -> 268.7483 | AB46: =$AP46-AC46*$AU$5*AO46 -> 403.31023 | AC46: =(AC45*AP47)/AP46 -> 58.008587 | AE46: 21 | AF46: =L46 -> 280.2483 | AG46: =AH46-AF46 -> 140.71266 | AH46: =AL46+AJ46 -> 420.96095 | AI46: =$E$5 -> 11.5 | AJ46: =$F$5 -> 10 | AK46: =AF46-AI46 -> 268.7483 | AL46: =$AP46-AM46*$AU$9*AO46 -> 410.96095 | AM46: =(AM45*AP47)/AP46 -> 29.004294 | AO46: 0.96314914 | AP46: =Mode3!H46 -> 416.57598
A47: 22 | B47: =Mode3!B47 -> 278.52677 | C47: =D47-B47 -> 100.07321 | D47: =H47+F47 -> 378.59998 | E47: =$E$5 -> 11.5 | F47: =$F$5 -> 10 | G47: =B47-E47 -> 267.02677 | H47: =AP47-I47*$AU$7*AO47 -> 368.59998 | I47: =(I46*AP48)/AP47 -> 172.87996 | K47: 22 | L47: =B47 -> 278.52677 | M47: =N47-L47 -> 116.39347 | N47: =R47+P47 -> 394.92024 | O47: =$E$5 -> 11.5 | P47: =$F$5 -> 10 | Q47: =L47-O47 -> 267.02677 | R47: =$AP47-S47*$AU$6*AO47 -> 384.92024 | S47: =(S46*AP48)/AP47 -> 115.25331 | U47: 22 | V47: =B47 -> 278.52677 | W47: =X47-V47 -> 132.33444 | X47: =AB47+Z47 -> 410.86121 | Y47: =$E$5 -> 11.5 | Z47: =$F$5 -> 10 | AA47: =V47-Y47 -> 267.02677 | AB47: =$AP47-AC47*$AU$5*AO47 -> 400.86121 | AC47: =(AC46*AP48)/AP47 -> 57.626655 | AE47: 22 | AF47: =L47 -> 278.52677 | AG47: =AH47-AF47 -> 139.88633 | AH47: =AL47+AJ47 -> 418.4131 | AI47: =$E$5 -> 11.5 | AJ47: =$F$5 -> 10 | AK47: =AF47-AI47 -> 267.02677 | AL47: =$AP47-AM47*$AU$9*AO47 -> 408.4131 | AM47: =(AM46*AP48)/AP47 -> 28.813327 | AO47: 0.95700733 | AP47: =Mode3!H47 -> 413.95559
A48: 23 | B48: =Mode3!B48 -> 276.73619 | C48: =D48-B48 -> 99.739839 | D48: =H48+F48 -> 376.47603 | E48: =$E$5 -> 11.5 | F48: =$F$5 -> 10 | G48: =B48-E48 -> 265.23619 | H48: =AP48-I48*$AU$7*AO48 -> 366.47603 | I48: =(I47*AP49)/AP48 -> 171.68887 | K48: 23 | L48: =B48 -> 276.73619 | M48: =N48-L48 -> 115.84364 | N48: =R48+P48 -> 392.57983 | O48: =$E$5 -> 11.5 | P48: =$F$5 -> 10 | Q48: =L48-O48 -> 265.23619 | R48: =$AP48-S48*$AU$6*AO48 -> 382.57983 | S48: =(S47*AP49)/AP48 -> 114.45925 | U48: 23 | V48: =B48 -> 276.73619 | W48: =X48-V48 -> 131.57319 | X48: =AB48+Z48 -> 408.30938 | Y48: =$E$5 -> 11.5 | Z48: =$F$5 -> 10 | AA48: =V48-Y48 -> 265.23619 | AB48: =$AP48-AC48*$AU$5*AO48 -> 398.30938 | AC48: =(AC47*AP49)/AP48 -> 57.229624 | AE48: 23 | AF48: =L48 -> 276.73619 | AG48: =AH48-AF48 -> 139.02491 | AH48: =AL48+AJ48 -> 415.7611 | AI48: =$E$5 -> 11.5 | AJ48: =$F$5 -> 10 | AK48: =AF48-AI48 -> 265.23619 | AL48: =$AP48-AM48*$AU$9*AO48 -> 405.7611 | AM48: =(AM47*AP49)/AP48 -> 28.614812 | AO48: 0.95086552 | AP48: =Mode3!H48 -> 411.23007
A49: 24 | B49: =Mode3!B49 -> 274.87482 | C49: =D49-B49 -> 99.159806 | D49: =H49+F49 -> 374.03463 | E49: =$E$5 -> 11.5 | F49: =$F$5 -> 10 | G49: =B49-E49 -> 263.37482 | H49: =AP49-I49*$AU$7*AO49 -> 364.03463 | I49: =(I48*AP50)/AP49 -> 171.29202 | K49: 24 | L49: =B49 -> 274.87482 | M49: =N49-L49 -> 115.12261 | N49: =R49+P49 -> 389.99743 | O49: =$E$5 -> 11.5 | P49: =$F$5 -> 10 | Q49: =L49-O49 -> 263.37482 | R49: =$AP49-S49*$AU$6*AO49 -> 379.99743 | S49: =(S48*AP50)/AP49 -> 114.19468 | U49: 24 | V49: =B49 -> 274.87482 | W49: =X49-V49 -> 130.71443 | X49: =AB49+Z49 -> 405.58925 | Y49: =$E$5 -> 11.5 | Z49: =$F$5 -> 10 | AA49: =V49-Y49 -> 263.37482 | AB49: =$AP49-AC49*$AU$5*AO49 -> 395.58925 | AC49: =(AC48*AP50)/AP49 -> 57.09734 | AE49: 24 | AF49: =L49 -> 274.87482 | AG49: =AH49-AF49 -> 138.10091 | AH49: =AL49+AJ49 -> 412.97573 | AI49: =$E$5 -> 11.5 | AJ49: =$F$5 -> 10 | AK49: =AF49-AI49 -> 263.37482 | AL49: =$AP49-AM49*$AU$9*AO49 -> 402.97573 | AM49: =(AM48*AP50)/AP49 -> 28.54867 | AO49: 0.94472371 | AP49: =Mode3!H49 -> 408.39682
A50: 25 | B50: =Mode3!B50 -> 274.25464 | C50: =D50-B50 -> 99.505232 | D50: =H50+F50 -> 373.75987 | E50: =$E$5 -> 11.5 | F50: =$F$5 -> 10 | G50: =B50-E50 -> 262.75464 | H50: =AP50-I50*$AU$7*AO50 -> 363.75987 | I50: =(I49*AP51)/AP50 -> 169.8119 | K50: 25 | L50: =B50 -> 274.25464 | M50: =N50-L50 -> 115.22722 | N50: =R50+P50 -> 389.48186 | O50: =$E$5 -> 11.5 | P50: =$F$5 -> 10 | Q50: =L50-O50 -> 262.75464 | R50: =$AP50-S50*$AU$6*AO50 -> 379.48186 | S50: =(S49*AP51)/AP50 -> 113.20793 | U50: 25 | V50: =B50 -> 274.25464 | W50: =X50-V50 -> 130.58383 | X50: =AB50+Z50 -> 404.83847 | Y50: =$E$5 -> 11.5 | Z50: =$F$5 -> 10 | AA50: =V50-Y50 -> 262.75464 | AB50: =$AP50-AC50*$AU$5*AO50 -> 394.83847 | AC50: =(AC49*AP51)/AP50 -> 56.603966 | AE50: 25 | AF50: =L50 -> 274.25464 | AG50: =AH50-AF50 -> 137.85887 | AH50: =AL50+AJ50 -> 412.11352 | AI50: =$E$5 -> 11.5 | AJ50: =$F$5 -> 10 | AK50: =AF50-AI50 -> 262.75464 | AL50: =$AP50-AM50*$AU$9*AO50 -> 402.11352 | AM50: =(AM49*AP51)/AP50 -> 28.301983 | AO50: 0.9385819 | AP50: =Mode3!H50 -> 407.45282
A51: 26 | B51: =Mode3!B51 -> 271.9416 | C51: =D51-B51 -> 98.912542 | D51: =H51+F51 -> 370.85414 | E51: =$E$5 -> 11.5 | F51: =$F$5 -> 10 | G51: =B51-E51 -> 260.4416 | H51: =AP51-I51*$AU$7*AO51 -> 360.85414 | I51: =(I50*AP52)/AP51 -> 168.52436 | K51: 26 | L51: =B51 -> 271.9416 | M51: =N51-L51 -> 114.41322 | N51: =R51+P51 -> 386.35482 | O51: =$E$5 -> 11.5 | P51: =$F$5 -> 10 | Q51: =L51-O51 -> 260.4416 | R51: =$AP51-S51*$AU$6*AO51 -> 376.35482 | S51: =(S50*AP52)/AP51 -> 112.34958 | U51: 26 | V51: =B51 -> 271.9416 | W51: =X51-V51 -> 129.55367 | X51: =AB51+Z51 -> 401.49527 | Y51: =$E$5 -> 11.5 | Z51: =$F$5 -> 10 | AA51: =V51-Y51 -> 260.4416 | AB51: =$AP51-AC51*$AU$5*AO51 -> 391.49527 | AC51: =(AC50*AP52)/AP51 -> 56.174788 | AE51: 26 | AF51: =L51 -> 271.9416 | AG51: =AH51-AF51 -> 136.72631 | AH51: =AL51+AJ51 -> 408.66791 | AI51: =$E$5 -> 11.5 | AJ51: =$F$5 -> 10 | AK51: =AF51-AI51 -> 260.4416 | AL51: =$AP51-AM51*$AU$9*AO51 -> 398.66791 | AM51: =(AM50*AP52)/AP51 -> 28.087394 | AO51: 0.93244009 | AP51: =Mode3!H51 -> 403.93206
A52: 27 | B52: =Mode3!B52 -> 269.92951 | C52: =D52-B52 -> 98.485474 | D52: =H52+F52 -> 368.41499 | E52: =$E$5 -> 11.5 | F52: =$F$5 -> 10 | G52: =B52-E52 -> 258.42951 | H52: =AP52-I52*$AU$7*AO52 -> 358.41499 | I52: =(I51*AP53)/AP52 -> 167.18635 | K52: 27 | L52: =B52 -> 269.92951 | M52: =N52-L52 -> 113.7618 | N52: =R52+P52 -> 383.69131 | O52: =$E$5 -> 11.5 | P52: =$F$5 -> 10 | Q52: =L52-O52 -> 258.42951 | R52: =$AP52-S52*$AU$6*AO52 -> 373.69131 | S52: =(S51*AP53)/AP52 -> 111.45757 | U52: 27 | V52: =B52 -> 269.92951 | W52: =X52-V52 -> 128.6831 | X52: =AB52+Z52 -> 398.61261 | Y52: =$E$5 -> 11.5 | Z52: =$F$5 -> 10 | AA52: =V52-Y52 -> 258.42951 | AB52: =$AP52-AC52*$AU$5*AO52 -> 388.61261 | AC52: =(AC51*AP53)/AP52 -> 55.728783 | AE52: 27 | AF52: =L52 -> 269.92951 | AG52: =AH52-AF52 -> 135.75192 | AH52: =AL52+AJ52 -> 405.68143 | AI52: =$E$5 -> 11.5 | AJ52: =$F$5 -> 10 | AK52: =AF52-AI52 -> 258.42951 | AL52: =$AP52-AM52*$AU$9*AO52 -> 395.68143 | AM52: =(AM51*AP53)/AP52 -> 27.864391 | AO52: 0.92629828 | AP52: =Mode3!H52 -> 400.86939
... A64: 39 | B64: =Mode3!B64 -> 239.00896 | C64: =D64-B64 -> 90.503882 | D64: =H64+F64 -> 329.51284 | E64: =$E$5 -> 11.5 | F64: =$F$5 -> 10 | G64: =B64-E64 -> 227.50896 | H64: =AP64-I64*$AU$7*AO64 -> 319.51284 | I64: =(I63*AP65)/AP64 -> 146.7131 | K64: 39 | L64: =B64 -> 239.00896 | M64: =N64-L64 -> 102.84287 | N64: =R64+P64 -> 341.85183 | O64: =$E$5 -> 11.5 | P64: =$F$5 -> 10 | Q64: =L64-O64 -> 227.50896 | R64: =$AP64-S64*$AU$6*AO64 -> 331.85183 | S64: =(S63*AP65)/AP64 -> 97.808731 | U64: 39 | V64: =B64 -> 239.00896 | W64: =X64-V64 -> 114.8951 | X64: =AB64+Z64 -> 353.90406 | Y64: =$E$5 -> 11.5 | Z64: =$F$5 -> 10 | AA64: =V64-Y64 -> 227.50896 | AB64: =$AP64-AC64*$AU$5*AO64 -> 343.90406 | AC64: =(AC63*AP65)/AP64 -> 48.904366 | AE64: 39 | AF64: =L64 -> 239.00896 | AG64: =AH64-AF64 -> 120.60473 | AH64: =AL64+AJ64 -> 359.61369 | AI64: =$E$5 -> 11.5 | AJ64: =$F$5 -> 10 | AK64: =AF64-AI64 -> 227.50896 | AL64: =$AP64-AM64*$AU$9*AO64 -> 349.61369 | AM64: =(AM63*AP65)/AP64 -> 24.452183 | AO64: 0.85259657 | AP64: =Mode3!H64 -> 353.80411
